<?xml version="1.0" ?>
<!-- =================================================================================== -->
<!-- |    This document was autogenerated by xacro from /Repository/我的文件/研究生/四足项目/RL/BlindDog/rl_sar/src/robots/cyberdog_description/xacro/robot.xacro | -->
<!-- |    EDITING THIS FILE BY HAND IS NOT RECOMMENDED                                 | -->
<!-- =================================================================================== -->
<robot name="cyberdog_description">
  <!-- ros_control plugin -->
  <gazebo>
    <plugin filename="libgazebo_ros_control.so" name="gazebo_ros_control">
      <robotNamespace>/cyberdog_gazebo</robotNamespace>
      <robotSimType>gazebo_ros_control/DefaultRobotHWSim</robotSimType>
    </plugin>
  </gazebo>
  <!-- Show the trajectory of trunk center. -->
  <gazebo>
    <plugin filename="libLinkPlot3DPlugin.so" name="3dplot">
      <frequency>10</frequency>
      <plot>
        <link>base</link>
        <pose>0 0 0 0 0 0</pose>
        <material>Gazebo/Yellow</material>
      </plot>
    </plugin>
  </gazebo>
  <!-- Show the trajectory of foot. You can add another trajectory about another foot. -->
  <!-- <gazebo>
        <plugin name="3dplot" filename="libLinkPlot3DPlugin.so">
            <frequency>100</frequency>
            <plot>
                <link>FL_foot</link>
                <pose>0 0 0 0 0 0</pose>
                <material>Gazebo/Green</material>
            </plot>
        </plugin>
    </gazebo> -->
  <gazebo>
    <plugin filename="libgazebo_ros_force.so" name="gazebo_ros_force">
      <bodyName>trunk</bodyName>
      <topicName>/apply_force/trunk</topicName>
    </plugin>
  </gazebo>
  <gazebo reference="imu_link">
    <gravity>true</gravity>
    <sensor name="imu_sensor" type="imu">
      <always_on>true</always_on>
      <update_rate>1000</update_rate>
      <visualize>true</visualize>
      <topic>__default_topic__</topic>
      <plugin filename="libgazebo_ros_imu_sensor.so" name="imu_plugin">
        <topicName>trunk_imu</topicName>
        <bodyName>imu_link</bodyName>
        <updateRateHZ>1000.0</updateRateHZ>
        <gaussianNoise>0.0</gaussianNoise>
        <xyzOffset>0 0 0</xyzOffset>
        <rpyOffset>0 0 0</rpyOffset>
        <frameName>imu_link</frameName>
      </plugin>
      <pose>0 0 0 0 0 0</pose>
    </sensor>
  </gazebo>
  <!-- Foot contacts. -->
  <gazebo reference="FR_calf">
    <sensor name="FR_foot_contact" type="contact">
      <update_rate>100</update_rate>
      <plugin filename="libunitreeFootContactPlugin.so" name="contactPlugin"/>
      <contact>
        <collision>FR_calf_fixed_joint_lump__FR_foot_collision_1</collision>
      </contact>
    </sensor>
  </gazebo>
  <gazebo reference="FL_calf">
    <sensor name="FL_foot_contact" type="contact">
      <update_rate>100</update_rate>
      <plugin filename="libunitreeFootContactPlugin.so" name="contactPlugin"/>
      <contact>
        <collision>FL_calf_fixed_joint_lump__FL_foot_collision_1</collision>
      </contact>
    </sensor>
  </gazebo>
  <gazebo reference="RR_calf">
    <sensor name="RR_foot_contact" type="contact">
      <update_rate>100</update_rate>
      <plugin filename="libunitreeFootContactPlugin.so" name="contactPlugin"/>
      <contact>
        <collision>RR_calf_fixed_joint_lump__RR_foot_collision_1</collision>
      </contact>
    </sensor>
  </gazebo>
  <gazebo reference="RL_calf">
    <sensor name="RL_foot_contact" type="contact">
      <update_rate>100</update_rate>
      <plugin filename="libunitreeFootContactPlugin.so" name="contactPlugin"/>
      <contact>
        <collision>RL_calf_fixed_joint_lump__RL_foot_collision_1</collision>
      </contact>
    </sensor>
  </gazebo>
  <!-- Visualization of Foot contacts. -->
  <gazebo reference="FR_foot">
    <visual>
      <plugin filename="libunitreeDrawForcePlugin.so" name="drawForcePlugin">
        <topicName>FR_foot_contact</topicName>
      </plugin>
    </visual>
  </gazebo>
  <gazebo reference="FL_foot">
    <visual>
      <plugin filename="libunitreeDrawForcePlugin.so" name="drawForcePlugin">
        <topicName>FL_foot_contact</topicName>
      </plugin>
    </visual>
  </gazebo>
  <gazebo reference="RR_foot">
    <visual>
      <plugin filename="libunitreeDrawForcePlugin.so" name="drawForcePlugin">
        <topicName>RR_foot_contact</topicName>
      </plugin>
    </visual>
  </gazebo>
  <gazebo reference="RL_foot">
    <visual>
      <plugin filename="libunitreeDrawForcePlugin.so" name="drawForcePlugin">
        <topicName>RL_foot_contact</topicName>
      </plugin>
    </visual>
  </gazebo>
  <gazebo reference="base">
    <material>Gazebo/Green</material>
    <turnGravityOff>false</turnGravityOff>
  </gazebo>
  <gazebo reference="trunk">
    <mu1>0.2</mu1>
    <mu2>0.2</mu2>
    <kp value="1000000.0"/>
    <kd value="1.0"/>
  </gazebo>
  <gazebo reference="stick_link">
    <mu1>0.2</mu1>
    <mu2>0.2</mu2>
    <material>Gazebo/White</material>
  </gazebo>
  <gazebo reference="imu_link">
    <mu1>0.2</mu1>
    <mu2>0.2</mu2>
    <material>Gazebo/Red</material>
  </gazebo>
  <!-- FL leg -->
  <gazebo reference="FL_hip">
    <mu1>0.2</mu1>
    <mu2>0.2</mu2>
    <material>Gazebo/DarkGrey</material>
  </gazebo>
  <gazebo reference="FL_thigh">
    <mu1>0.2</mu1>
    <mu2>0.2</mu2>
    <self_collide>1</self_collide>
    <material>Gazebo/DarkGrey</material>
    <kp value="1000000.0"/>
    <kd value="1.0"/>
  </gazebo>
  <gazebo reference="FL_calf">
    <mu1>0.2</mu1>
    <mu2>0.2</mu2>
    <self_collide>1</self_collide>
  </gazebo>
  <gazebo reference="FL_foot">
    <mu1>0.6</mu1>
    <mu2>0.6</mu2>
    <self_collide>1</self_collide>
    <material>Gazebo/DarkGrey</material>
    <kp value="1000000.0"/>
    <kd value="1.0"/>
  </gazebo>
  <!-- FR leg -->
  <gazebo reference="FR_hip">
    <mu1>0.2</mu1>
    <mu2>0.2</mu2>
    <material>Gazebo/DarkGrey</material>
  </gazebo>
  <gazebo reference="FR_thigh">
    <mu1>0.2</mu1>
    <mu2>0.2</mu2>
    <self_collide>1</self_collide>
    <material>Gazebo/DarkGrey</material>
    <kp value="1000000.0"/>
    <kd value="1.0"/>
  </gazebo>
  <gazebo reference="FR_calf">
    <mu1>0.2</mu1>
    <mu2>0.2</mu2>
    <self_collide>1</self_collide>
  </gazebo>
  <gazebo reference="FR_foot">
    <mu1>0.6</mu1>
    <mu2>0.6</mu2>
    <self_collide>1</self_collide>
    <material>Gazebo/DarkGrey</material>
    <kp value="1000000.0"/>
    <kd value="1.0"/>
  </gazebo>
  <!-- RL leg -->
  <gazebo reference="RL_hip">
    <mu1>0.2</mu1>
    <mu2>0.2</mu2>
    <material>Gazebo/DarkGrey</material>
  </gazebo>
  <gazebo reference="RL_thigh">
    <mu1>0.2</mu1>
    <mu2>0.2</mu2>
    <self_collide>1</self_collide>
    <material>Gazebo/DarkGrey</material>
    <kp value="1000000.0"/>
    <kd value="1.0"/>
  </gazebo>
  <gazebo reference="RL_calf">
    <mu1>0.2</mu1>
    <mu2>0.2</mu2>
    <self_collide>1</self_collide>
  </gazebo>
  <gazebo reference="RL_foot">
    <mu1>0.6</mu1>
    <mu2>0.6</mu2>
    <self_collide>1</self_collide>
    <material>Gazebo/DarkGrey</material>
    <kp value="1000000.0"/>
    <kd value="1.0"/>
  </gazebo>
  <!-- RR leg -->
  <gazebo reference="RR_hip">
    <mu1>0.2</mu1>
    <mu2>0.2</mu2>
    <material>Gazebo/DarkGrey</material>
  </gazebo>
  <gazebo reference="RR_thigh">
    <mu1>0.2</mu1>
    <mu2>0.2</mu2>
    <self_collide>1</self_collide>
    <material>Gazebo/DarkGrey</material>
    <kp value="1000000.0"/>
    <kd value="1.0"/>
  </gazebo>
  <gazebo reference="RR_calf">
    <mu1>0.2</mu1>
    <mu2>0.2</mu2>
    <self_collide>1</self_collide>
  </gazebo>
  <gazebo reference="RR_foot">
    <mu1>0.6</mu1>
    <mu2>0.6</mu2>
    <self_collide>1</self_collide>
    <material>Gazebo/DarkGrey</material>
    <kp value="1000000.0"/>
    <kd value="1.0"/>
  </gazebo>
  <material name="black">
    <color rgba="0.0 0.0 0.0 1.0"/>
  </material>
  <material name="blue">
    <color rgba="0.0 0.0 0.8 1.0"/>
  </material>
  <material name="green">
    <color rgba="0.0 0.8 0.0 1.0"/>
  </material>
  <material name="grey">
    <color rgba="0.2 0.2 0.2 1.0"/>
  </material>
  <material name="silver">
    <color rgba="0.913725490196 0.913725490196 0.847058823529 1.0"/>
  </material>
  <material name="orange">
    <color rgba="0.12 0.15 0.2 1.0"/>
  </material>
  <material name="brown">
    <color rgba="0.870588235294 0.811764705882 0.764705882353 1.0"/>
  </material>
  <material name="red">
    <color rgba="0.8 0.0 0.0 1.0"/>
  </material>
  <material name="white">
    <color rgba="1.0 1.0 1.0 1.0"/>
  </material>
  <link name="base">
    <visual>
      <origin rpy="0 0 0" xyz="0 0 0"/>
      <geometry>
        <box size="0.001 0.001 0.001"/>
      </geometry>
    </visual>
  </link>
  <joint name="floating_base" type="fixed">
    <origin rpy="0 0 0" xyz="0 0 0"/>
    <parent link="base"/>
    <child link="trunk"/>
  </joint>
  <link name="trunk">
    <!-- <visual>
            <origin rpy="0 0 0" xyz="0 0 0" />
            <geometry>
                <mesh filename="package://cyberdog_new_description/meshes/body.dae" scale="1 1 1" />
            </geometry>
        </visual> -->
    <visual>
      <origin rpy="0 0 0" xyz="0 0 0"/>
      <geometry>
        <box size="0.36 0.23 0.15"/>
      </geometry>
      <material name="silver"/>
    </visual>
    <collision>
      <origin rpy="0 0 0" xyz="0 0 0"/>
      <geometry>
        <box size="0.36 0.23 0.15"/>
      </geometry>
    </collision>
    <inertial>
      <origin rpy="0 0 0" xyz="0.018785003 0.003291012 -0.000925646"/>
      <mass value="6.248410872"/>
      <inertia ixx="0.032143039" ixy="-0.000268204" ixz="-0.00241341" iyy="0.13578316" iyz="8.0244e-05" izz="0.14828095"/>
    </inertial>
  </link>
  <joint name="imu_joint" type="fixed">
    <parent link="trunk"/>
    <child link="imu_link"/>
    <origin rpy="0 0 0" xyz="0 0 0"/>
  </joint>
  <link name="imu_link">
    <!-- <inertial>
            <mass value="0.001" />
            <origin rpy="0 0 0" xyz="0 0 0" />
            <inertia ixx="0.0001" ixy="0" ixz="0" iyy="0.0001" iyz="0" izz="0.0001" />
        </inertial>
        <visual>
            <origin rpy="0 0 0" xyz="0 0 0" />
            <geometry>
                <box size="0.001 0.001 0.001" />
            </geometry>
        </visual>
        <collision>
            <origin rpy="0 0 0" xyz="0 0 0" />
            <geometry>
                <box size=".001 .001 .001" />
            </geometry>
        </collision> -->
  </link>
  <joint name="FR_hip_joint" type="revolute">
    <origin rpy="0 0 0" xyz="0.23035 -0.05 0"/>
    <parent link="trunk"/>
    <child link="FR_hip"/>
    <axis xyz="1 0 0"/>
    <dynamics damping="0" friction="0"/>
    <limit effort="24" lower="-0.76096355387" upper="0.76096355387" velocity="31"/>
  </joint>
  <link name="FR_hip">
    <!-- <visual>
                <xacro:if value="${(mirror_dae == True) and (front_hind_dae == True)}">
                    <origin rpy="0 0 0" xyz="0 0 0" />
                </xacro:if>
                <xacro:if value="${(mirror_dae == False) and (front_hind_dae == True)}">
                    <origin rpy="${PI} 0 0" xyz="0 0 0" />
                </xacro:if>
                <xacro:if value="${(mirror_dae == True) and (front_hind_dae == False)}">
                    <origin rpy="0 ${PI} 0" xyz="0 0 0" />
                </xacro:if>
                <xacro:if value="${(mirror_dae == False) and (front_hind_dae == False)}">
                    <origin rpy="${PI} ${PI} 0" xyz="0 0 0" />
                </xacro:if>
                <geometry>
                    <mesh filename="package://cyberdog_new_description/meshes/abad.dae" scale="1 1 1" />
                </geometry>
                <material name="orange" />
            </visual> -->
    <visual>
      <origin rpy="1.5707963267948966 0 0" xyz="0 0 0"/>
      <geometry>
        <cylinder length="0.052" radius="0.047"/>
      </geometry>
      <material name="silver"/>
    </visual>
    <collision>
      <origin rpy="1.5707963267948966 0 0" xyz="0 0 0"/>
      <geometry>
        <cylinder length="0.052" radius="0.047"/>
      </geometry>
    </collision>
    <inertial>
      <origin rpy="0 0 0" xyz="-0.001597914 -0.001680938 2.253e-06"/>
      <mass value="0.537806728"/>
      <inertia ixx="0.000403612" ixy="9.337e-06" ixz="5.36e-07" iyy="0.000600779" iyz="6.3e-08" izz="0.000417249"/>
    </inertial>
  </link>
  <joint name="FR_hip_rotor_fix" type="fixed">
    <origin rpy="0 0 0" xyz="-0.0832504 0 0"/>
    <parent link="FR_hip"/>
    <child link="FR_hip_rotor"/>
  </joint>
  <!-- this link is only for abad rotor inertial -->
  <link name="FR_hip_rotor">
    <inertial>
      <origin rpy="0 0 0" xyz="0 0 0"/>
      <mass value="0.076506382"/>
      <inertia ixx="4.5843e-05" ixy="0" ixz="0" iyy="4.5871e-05" iyz="0" izz="8.9031e-05"/>
    </inertial>
  </link>
  <joint name="FR_hip_fixed" type="fixed">
    <origin rpy="0 0 0" xyz="0 -0.053076000000000005 0"/>
    <parent link="FR_hip"/>
    <child link="FR_thigh_shoulder"/>
  </joint>
  <link name="FR_thigh_shoulder">
    <visual>
      <origin rpy="1.5707963267948966 0 0" xyz="0 0 0"/>
      <geometry>
        <cylinder length="0.052" radius="0.047"/>
      </geometry>
      <material name="silver"/>
    </visual>
    <collision>
      <origin rpy="1.5707963267948966 0 0" xyz="0 0 0"/>
      <geometry>
        <cylinder length="0.052" radius="0.047"/>
      </geometry>
    </collision>
  </link>
  <joint name="FR_thigh_joint" type="revolute">
    <origin rpy="0 0 0" xyz="0 -0.105076 0"/>
    <parent link="FR_hip"/>
    <child link="FR_thigh"/>
    <axis xyz="0 1 0"/>
    <dynamics damping="0" friction="0"/>
    <limit effort="24" lower="-1.88495559215" upper="3.76991118431" velocity="31"/>
  </joint>
  <link name="FR_thigh">
    <!-- <visual>
                <origin rpy="0 0 0" xyz="0 0 0" />
                <geometry>
                    <xacro:if value="${mirror_dae == True}">
                        <mesh filename="package://cyberdog_new_description/meshes/hip.dae"
                            scale="1 1 1" />
                    </xacro:if>
                    <xacro:if value="${mirror_dae == False}">
                        <mesh filename="package://cyberdog_new_description/meshes/hip_mirror.dae"
                            scale="1 1 1" />
                    </xacro:if>
                </geometry>
                <material name="orange" />
            </visual> -->
    <visual>
      <origin rpy="0 1.5707963267948966 0" xyz="0 0 -0.1"/>
      <geometry>
        <box size="0.2 0.035 0.05"/>
      </geometry>
      <material name="silver"/>
    </visual>
    <collision>
      <origin rpy="0 1.5707963267948966 0" xyz="0 0 -0.1"/>
      <geometry>
        <box size="0.2 0.035 0.05"/>
      </geometry>
    </collision>
    <inertial>
      <origin rpy="0 0 0" xyz="-0.003205778 0.027811623 -0.027767048"/>
      <mass value="0.950266218"/>
      <inertia ixx="0.004811898" ixy="-9.3647e-05" ixz="-0.000208709" iyy="0.004752366" iyz="-0.000813258" izz="0.001079691"/>
    </inertial>
  </link>
  <joint name="FR_thigh_rotor_fix" type="fixed">
    <origin rpy="0 0 0" xyz="0 0.107226 0"/>
    <parent link="FR_thigh"/>
    <child link="FR_thigh_rotor"/>
  </joint>
  <!-- this link is only for hip rotor inertial -->
  <link name="FR_thigh_rotor">
    <inertial>
      <origin rpy="0 0 0" xyz="0 0 0"/>
      <mass value="0.076506382"/>
      <inertia ixx="4.5843e-05" ixy="0" ixz="0" iyy="4.5871e-05" iyz="0" izz="8.9031e-05"/>
    </inertial>
  </link>
  <joint name="FR_calf_rotor_fix" type="fixed">
    <origin rpy="0 0 0" xyz="0 0.0426259 0"/>
    <parent link="FR_thigh"/>
    <child link="FR_calf_rotor"/>
  </joint>
  <!-- this link is only for knee rotor inertial -->
  <link name="FR_calf_rotor">
    <inertial>
      <origin rpy="0 0 0" xyz="0 0 0"/>
      <mass value="0.076506382"/>
      <inertia ixx="4.5843e-05" ixy="0" ixz="0" iyy="4.5871e-05" iyz="0" izz="8.9031e-05"/>
    </inertial>
  </link>
  <joint name="FR_calf_joint" type="revolute">
    <origin rpy="0 0 0" xyz="0 0 -0.2"/>
    <parent link="FR_thigh"/>
    <child link="FR_calf"/>
    <axis xyz="0 1 0"/>
    <dynamics damping="0" friction="0"/>
    <limit effort="24" lower="-2.49582083035" upper="-0.717155789644" velocity="31"/>
  </joint>
  <link name="FR_calf">
    <!-- <visual>
                <origin rpy="0 0 0" xyz="0 0 0" />
                <geometry>
                    <mesh filename="package://cyberdog_new_description/meshes/knee.dae" scale="1 1 1" />
                </geometry>
                <material name="orange" />
            </visual> -->
    <visual>
      <origin rpy="0 3.141592653589793 0" xyz="0 0 -0.1045"/>
      <geometry>
        <box size="0.016 0.016 0.209"/>
      </geometry>
      <material name="silver"/>
    </visual>
    <visual name="FR_calf_rubber">
      <origin rpy="0 3.141592653589793 0" xyz="-0.0125 0 -0.007"/>
      <geometry>
        <sphere radius="0.016"/>
      </geometry>
    </visual>
    <collision>
      <origin rpy="0 3.141592653589793 0" xyz="0 0 -0.1045"/>
      <geometry>
        <box size="0.016 0.016 0.209"/>
      </geometry>
    </collision>
    <collision name="FR_calf_rubber">
      <origin rpy="0 3.141592653589793 0" xyz="-0.0125 0 -0.007"/>
      <geometry>
        <sphere radius="0.016"/>
      </geometry>
      <surface>
        <contact>
          <ode>
            <max_vel>0.00001</max_vel>
            <min_depth>0.0</min_depth>
          </ode>
        </contact>
      </surface>
    </collision>
    <inertial>
      <origin rpy="0 0 0" xyz="0.007372358 0.000122423 -0.10769301"/>
      <mass value="0.1135916"/>
      <inertia ixx="0.000667971" ixy="-1e-09" ixz="5.356e-06" iyy="0.000674399" iyz="-1.5e-08" izz="1.4181e-05"/>
    </inertial>
  </link>
  <joint dont_collapse="true" name="FR_foot_fixed" type="fixed">
    <origin rpy="0 0 0" xyz="0 0 -0.19999999999999998"/>
    <parent link="FR_calf"/>
    <child link="FR_foot"/>
  </joint>
  <link name="FR_foot">
    <visual>
      <origin rpy="0 0 0" xyz="0 0 0"/>
      <geometry>
        <sphere radius="0.018"/>
      </geometry>
      <material name="silver"/>
    </visual>
    <collision>
      <origin rpy="0 0 0" xyz="0 0 0"/>
      <geometry>
        <sphere radius="0.018"/>
      </geometry>
      <surface>
        <contact>
          <ode>
            <max_vel>0.001</max_vel>
            <min_depth>0.0</min_depth>
          </ode>
        </contact>
      </surface>
    </collision>
  </link>
  <transmission name="FR_hip_tran">
    <type>transmission_interface/SimpleTransmission</type>
    <joint name="FR_hip_joint">
      <hardwareInterface>hardware_interface/EffortJointInterface</hardwareInterface>
    </joint>
    <actuator name="FR_hip_motor">
      <hardwareInterface>hardware_interface/EffortJointInterface</hardwareInterface>
      <mechanicalReduction>&quot;1&quot;</mechanicalReduction>
    </actuator>
  </transmission>
  <transmission name="FR_thigh_tran">
    <type>transmission_interface/SimpleTransmission</type>
    <joint name="FR_thigh_joint">
      <hardwareInterface>hardware_interface/EffortJointInterface</hardwareInterface>
    </joint>
    <actuator name="FR_thigh_motor">
      <hardwareInterface>hardware_interface/EffortJointInterface</hardwareInterface>
      <mechanicalReduction>&quot;1&quot;</mechanicalReduction>
    </actuator>
  </transmission>
  <transmission name="FR_calf_tran">
    <type>transmission_interface/SimpleTransmission</type>
    <joint name="FR_calf_joint">
      <hardwareInterface>hardware_interface/EffortJointInterface</hardwareInterface>
    </joint>
    <actuator name="FR_calf_motor">
      <hardwareInterface>hardware_interface/EffortJointInterface</hardwareInterface>
      <mechanicalReduction>&quot;1&quot;</mechanicalReduction>
    </actuator>
  </transmission>
  <joint name="FL_hip_joint" type="revolute">
    <origin rpy="0 0 0" xyz="0.23035 0.05 0"/>
    <parent link="trunk"/>
    <child link="FL_hip"/>
    <axis xyz="1 0 0"/>
    <dynamics damping="0" friction="0"/>
    <limit effort="24" lower="-0.76096355387" upper="0.76096355387" velocity="31"/>
  </joint>
  <link name="FL_hip">
    <!-- <visual>
                <xacro:if value="${(mirror_dae == True) and (front_hind_dae == True)}">
                    <origin rpy="0 0 0" xyz="0 0 0" />
                </xacro:if>
                <xacro:if value="${(mirror_dae == False) and (front_hind_dae == True)}">
                    <origin rpy="${PI} 0 0" xyz="0 0 0" />
                </xacro:if>
                <xacro:if value="${(mirror_dae == True) and (front_hind_dae == False)}">
                    <origin rpy="0 ${PI} 0" xyz="0 0 0" />
                </xacro:if>
                <xacro:if value="${(mirror_dae == False) and (front_hind_dae == False)}">
                    <origin rpy="${PI} ${PI} 0" xyz="0 0 0" />
                </xacro:if>
                <geometry>
                    <mesh filename="package://cyberdog_new_description/meshes/abad.dae" scale="1 1 1" />
                </geometry>
                <material name="orange" />
            </visual> -->
    <visual>
      <origin rpy="1.5707963267948966 0 0" xyz="0 0 0"/>
      <geometry>
        <cylinder length="0.052" radius="0.047"/>
      </geometry>
      <material name="silver"/>
    </visual>
    <collision>
      <origin rpy="1.5707963267948966 0 0" xyz="0 0 0"/>
      <geometry>
        <cylinder length="0.052" radius="0.047"/>
      </geometry>
    </collision>
    <inertial>
      <origin rpy="0 0 0" xyz="-0.001597914 0.001680938 2.253e-06"/>
      <mass value="0.537806728"/>
      <inertia ixx="0.000403612" ixy="-9.337e-06" ixz="5.36e-07" iyy="0.000600779" iyz="-6.3e-08" izz="0.000417249"/>
    </inertial>
  </link>
  <joint name="FL_hip_rotor_fix" type="fixed">
    <origin rpy="0 0 0" xyz="-0.0832504 0 0"/>
    <parent link="FL_hip"/>
    <child link="FL_hip_rotor"/>
  </joint>
  <!-- this link is only for abad rotor inertial -->
  <link name="FL_hip_rotor">
    <inertial>
      <origin rpy="0 0 0" xyz="0 0 0"/>
      <mass value="0.076506382"/>
      <inertia ixx="4.5843e-05" ixy="0" ixz="0" iyy="4.5871e-05" iyz="0" izz="8.9031e-05"/>
    </inertial>
  </link>
  <joint name="FL_hip_fixed" type="fixed">
    <origin rpy="0 0 0" xyz="0 0.053076000000000005 0"/>
    <parent link="FL_hip"/>
    <child link="FL_thigh_shoulder"/>
  </joint>
  <link name="FL_thigh_shoulder">
    <visual>
      <origin rpy="1.5707963267948966 0 0" xyz="0 0 0"/>
      <geometry>
        <cylinder length="0.052" radius="0.047"/>
      </geometry>
      <material name="silver"/>
    </visual>
    <collision>
      <origin rpy="1.5707963267948966 0 0" xyz="0 0 0"/>
      <geometry>
        <cylinder length="0.052" radius="0.047"/>
      </geometry>
    </collision>
  </link>
  <joint name="FL_thigh_joint" type="revolute">
    <origin rpy="0 0 0" xyz="0 0.105076 0"/>
    <parent link="FL_hip"/>
    <child link="FL_thigh"/>
    <axis xyz="0 1 0"/>
    <dynamics damping="0" friction="0"/>
    <limit effort="24" lower="-1.88495559215" upper="3.76991118431" velocity="31"/>
  </joint>
  <link name="FL_thigh">
    <!-- <visual>
                <origin rpy="0 0 0" xyz="0 0 0" />
                <geometry>
                    <xacro:if value="${mirror_dae == True}">
                        <mesh filename="package://cyberdog_new_description/meshes/hip.dae"
                            scale="1 1 1" />
                    </xacro:if>
                    <xacro:if value="${mirror_dae == False}">
                        <mesh filename="package://cyberdog_new_description/meshes/hip_mirror.dae"
                            scale="1 1 1" />
                    </xacro:if>
                </geometry>
                <material name="orange" />
            </visual> -->
    <visual>
      <origin rpy="0 1.5707963267948966 0" xyz="0 0 -0.1"/>
      <geometry>
        <box size="0.2 0.035 0.05"/>
      </geometry>
      <material name="silver"/>
    </visual>
    <collision>
      <origin rpy="0 1.5707963267948966 0" xyz="0 0 -0.1"/>
      <geometry>
        <box size="0.2 0.035 0.05"/>
      </geometry>
    </collision>
    <inertial>
      <origin rpy="0 0 0" xyz="-0.003205778 -0.027811623 -0.027767048"/>
      <mass value="0.950266218"/>
      <inertia ixx="0.004811898" ixy="9.3647e-05" ixz="-0.000208709" iyy="0.004752366" iyz="0.000813258" izz="0.001079691"/>
    </inertial>
  </link>
  <joint name="FL_thigh_rotor_fix" type="fixed">
    <origin rpy="0 0 0" xyz="0 -0.107226 0"/>
    <parent link="FL_thigh"/>
    <child link="FL_thigh_rotor"/>
  </joint>
  <!-- this link is only for hip rotor inertial -->
  <link name="FL_thigh_rotor">
    <inertial>
      <origin rpy="0 0 0" xyz="0 0 0"/>
      <mass value="0.076506382"/>
      <inertia ixx="4.5843e-05" ixy="0" ixz="0" iyy="4.5871e-05" iyz="0" izz="8.9031e-05"/>
    </inertial>
  </link>
  <joint name="FL_calf_rotor_fix" type="fixed">
    <origin rpy="0 0 0" xyz="0 -0.0426259 0"/>
    <parent link="FL_thigh"/>
    <child link="FL_calf_rotor"/>
  </joint>
  <!-- this link is only for knee rotor inertial -->
  <link name="FL_calf_rotor">
    <inertial>
      <origin rpy="0 0 0" xyz="0 0 0"/>
      <mass value="0.076506382"/>
      <inertia ixx="4.5843e-05" ixy="0" ixz="0" iyy="4.5871e-05" iyz="0" izz="8.9031e-05"/>
    </inertial>
  </link>
  <joint name="FL_calf_joint" type="revolute">
    <origin rpy="0 0 0" xyz="0 0 -0.2"/>
    <parent link="FL_thigh"/>
    <child link="FL_calf"/>
    <axis xyz="0 1 0"/>
    <dynamics damping="0" friction="0"/>
    <limit effort="24" lower="-2.49582083035" upper="-0.717155789644" velocity="31"/>
  </joint>
  <link name="FL_calf">
    <!-- <visual>
                <origin rpy="0 0 0" xyz="0 0 0" />
                <geometry>
                    <mesh filename="package://cyberdog_new_description/meshes/knee.dae" scale="1 1 1" />
                </geometry>
                <material name="orange" />
            </visual> -->
    <visual>
      <origin rpy="0 3.141592653589793 0" xyz="0 0 -0.1045"/>
      <geometry>
        <box size="0.016 0.016 0.209"/>
      </geometry>
      <material name="silver"/>
    </visual>
    <visual name="FL_calf_rubber">
      <origin rpy="0 3.141592653589793 0" xyz="-0.0125 0 -0.007"/>
      <geometry>
        <sphere radius="0.016"/>
      </geometry>
    </visual>
    <collision>
      <origin rpy="0 3.141592653589793 0" xyz="0 0 -0.1045"/>
      <geometry>
        <box size="0.016 0.016 0.209"/>
      </geometry>
    </collision>
    <collision name="FL_calf_rubber">
      <origin rpy="0 3.141592653589793 0" xyz="-0.0125 0 -0.007"/>
      <geometry>
        <sphere radius="0.016"/>
      </geometry>
      <surface>
        <contact>
          <ode>
            <max_vel>0.00001</max_vel>
            <min_depth>0.0</min_depth>
          </ode>
        </contact>
      </surface>
    </collision>
    <inertial>
      <origin rpy="0 0 0" xyz="0.007372358 0.000122423 -0.10769301"/>
      <mass value="0.1135916"/>
      <inertia ixx="0.000667971" ixy="-1e-09" ixz="5.356e-06" iyy="0.000674399" iyz="-1.5e-08" izz="1.4181e-05"/>
    </inertial>
  </link>
  <joint dont_collapse="true" name="FL_foot_fixed" type="fixed">
    <origin rpy="0 0 0" xyz="0 0 -0.19999999999999998"/>
    <parent link="FL_calf"/>
    <child link="FL_foot"/>
  </joint>
  <link name="FL_foot">
    <visual>
      <origin rpy="0 0 0" xyz="0 0 0"/>
      <geometry>
        <sphere radius="0.018"/>
      </geometry>
      <material name="silver"/>
    </visual>
    <collision>
      <origin rpy="0 0 0" xyz="0 0 0"/>
      <geometry>
        <sphere radius="0.018"/>
      </geometry>
      <surface>
        <contact>
          <ode>
            <max_vel>0.001</max_vel>
            <min_depth>0.0</min_depth>
          </ode>
        </contact>
      </surface>
    </collision>
  </link>
  <transmission name="FL_hip_tran">
    <type>transmission_interface/SimpleTransmission</type>
    <joint name="FL_hip_joint">
      <hardwareInterface>hardware_interface/EffortJointInterface</hardwareInterface>
    </joint>
    <actuator name="FL_hip_motor">
      <hardwareInterface>hardware_interface/EffortJointInterface</hardwareInterface>
      <mechanicalReduction>&quot;1&quot;</mechanicalReduction>
    </actuator>
  </transmission>
  <transmission name="FL_thigh_tran">
    <type>transmission_interface/SimpleTransmission</type>
    <joint name="FL_thigh_joint">
      <hardwareInterface>hardware_interface/EffortJointInterface</hardwareInterface>
    </joint>
    <actuator name="FL_thigh_motor">
      <hardwareInterface>hardware_interface/EffortJointInterface</hardwareInterface>
      <mechanicalReduction>&quot;1&quot;</mechanicalReduction>
    </actuator>
  </transmission>
  <transmission name="FL_calf_tran">
    <type>transmission_interface/SimpleTransmission</type>
    <joint name="FL_calf_joint">
      <hardwareInterface>hardware_interface/EffortJointInterface</hardwareInterface>
    </joint>
    <actuator name="FL_calf_motor">
      <hardwareInterface>hardware_interface/EffortJointInterface</hardwareInterface>
      <mechanicalReduction>&quot;1&quot;</mechanicalReduction>
    </actuator>
  </transmission>
  <joint name="RR_hip_joint" type="revolute">
    <origin rpy="0 0 0" xyz="-0.23035 -0.05 0"/>
    <parent link="trunk"/>
    <child link="RR_hip"/>
    <axis xyz="1 0 0"/>
    <dynamics damping="0" friction="0"/>
    <limit effort="24" lower="-0.76096355387" upper="0.76096355387" velocity="31"/>
  </joint>
  <link name="RR_hip">
    <!-- <visual>
                <xacro:if value="${(mirror_dae == True) and (front_hind_dae == True)}">
                    <origin rpy="0 0 0" xyz="0 0 0" />
                </xacro:if>
                <xacro:if value="${(mirror_dae == False) and (front_hind_dae == True)}">
                    <origin rpy="${PI} 0 0" xyz="0 0 0" />
                </xacro:if>
                <xacro:if value="${(mirror_dae == True) and (front_hind_dae == False)}">
                    <origin rpy="0 ${PI} 0" xyz="0 0 0" />
                </xacro:if>
                <xacro:if value="${(mirror_dae == False) and (front_hind_dae == False)}">
                    <origin rpy="${PI} ${PI} 0" xyz="0 0 0" />
                </xacro:if>
                <geometry>
                    <mesh filename="package://cyberdog_new_description/meshes/abad.dae" scale="1 1 1" />
                </geometry>
                <material name="orange" />
            </visual> -->
    <visual>
      <origin rpy="1.5707963267948966 0 0" xyz="0 0 0"/>
      <geometry>
        <cylinder length="0.052" radius="0.047"/>
      </geometry>
      <material name="silver"/>
    </visual>
    <collision>
      <origin rpy="1.5707963267948966 0 0" xyz="0 0 0"/>
      <geometry>
        <cylinder length="0.052" radius="0.047"/>
      </geometry>
    </collision>
    <inertial>
      <origin rpy="0 0 0" xyz="0.001597914 -0.001680938 2.253e-06"/>
      <mass value="0.537806728"/>
      <inertia ixx="0.000403612" ixy="-9.337e-06" ixz="-5.36e-07" iyy="0.000600779" iyz="6.3e-08" izz="0.000417249"/>
    </inertial>
  </link>
  <joint name="RR_hip_rotor_fix" type="fixed">
    <origin rpy="0 0 0" xyz="0.0832504 0 0"/>
    <parent link="RR_hip"/>
    <child link="RR_hip_rotor"/>
  </joint>
  <!-- this link is only for abad rotor inertial -->
  <link name="RR_hip_rotor">
    <inertial>
      <origin rpy="0 0 0" xyz="0 0 0"/>
      <mass value="0.076506382"/>
      <inertia ixx="4.5843e-05" ixy="0" ixz="0" iyy="4.5871e-05" iyz="0" izz="8.9031e-05"/>
    </inertial>
  </link>
  <joint name="RR_hip_fixed" type="fixed">
    <origin rpy="0 0 0" xyz="0 -0.053076000000000005 0"/>
    <parent link="RR_hip"/>
    <child link="RR_thigh_shoulder"/>
  </joint>
  <link name="RR_thigh_shoulder">
    <visual>
      <origin rpy="1.5707963267948966 0 0" xyz="0 0 0"/>
      <geometry>
        <cylinder length="0.052" radius="0.047"/>
      </geometry>
      <material name="silver"/>
    </visual>
    <collision>
      <origin rpy="1.5707963267948966 0 0" xyz="0 0 0"/>
      <geometry>
        <cylinder length="0.052" radius="0.047"/>
      </geometry>
    </collision>
  </link>
  <joint name="RR_thigh_joint" type="revolute">
    <origin rpy="0 0 0" xyz="0 -0.105076 0"/>
    <parent link="RR_hip"/>
    <child link="RR_thigh"/>
    <axis xyz="0 1 0"/>
    <dynamics damping="0" friction="0"/>
    <limit effort="24" lower="-1.88495559215" upper="3.76991118431" velocity="31"/>
  </joint>
  <link name="RR_thigh">
    <!-- <visual>
                <origin rpy="0 0 0" xyz="0 0 0" />
                <geometry>
                    <xacro:if value="${mirror_dae == True}">
                        <mesh filename="package://cyberdog_new_description/meshes/hip.dae"
                            scale="1 1 1" />
                    </xacro:if>
                    <xacro:if value="${mirror_dae == False}">
                        <mesh filename="package://cyberdog_new_description/meshes/hip_mirror.dae"
                            scale="1 1 1" />
                    </xacro:if>
                </geometry>
                <material name="orange" />
            </visual> -->
    <visual>
      <origin rpy="0 1.5707963267948966 0" xyz="0 0 -0.1"/>
      <geometry>
        <box size="0.2 0.035 0.05"/>
      </geometry>
      <material name="silver"/>
    </visual>
    <collision>
      <origin rpy="0 1.5707963267948966 0" xyz="0 0 -0.1"/>
      <geometry>
        <box size="0.2 0.035 0.05"/>
      </geometry>
    </collision>
    <inertial>
      <origin rpy="0 0 0" xyz="-0.003205778 0.027811623 -0.027767048"/>
      <mass value="0.950266218"/>
      <inertia ixx="0.004811898" ixy="-9.3647e-05" ixz="-0.000208709" iyy="0.004752366" iyz="-0.000813258" izz="0.001079691"/>
    </inertial>
  </link>
  <joint name="RR_thigh_rotor_fix" type="fixed">
    <origin rpy="0 0 0" xyz="0 0.107226 0"/>
    <parent link="RR_thigh"/>
    <child link="RR_thigh_rotor"/>
  </joint>
  <!-- this link is only for hip rotor inertial -->
  <link name="RR_thigh_rotor">
    <inertial>
      <origin rpy="0 0 0" xyz="0 0 0"/>
      <mass value="0.076506382"/>
      <inertia ixx="4.5843e-05" ixy="0" ixz="0" iyy="4.5871e-05" iyz="0" izz="8.9031e-05"/>
    </inertial>
  </link>
  <joint name="RR_calf_rotor_fix" type="fixed">
    <origin rpy="0 0 0" xyz="0 0.0426259 0"/>
    <parent link="RR_thigh"/>
    <child link="RR_calf_rotor"/>
  </joint>
  <!-- this link is only for knee rotor inertial -->
  <link name="RR_calf_rotor">
    <inertial>
      <origin rpy="0 0 0" xyz="0 0 0"/>
      <mass value="0.076506382"/>
      <inertia ixx="4.5843e-05" ixy="0" ixz="0" iyy="4.5871e-05" iyz="0" izz="8.9031e-05"/>
    </inertial>
  </link>
  <joint name="RR_calf_joint" type="revolute">
    <origin rpy="0 0 0" xyz="0 0 -0.2"/>
    <parent link="RR_thigh"/>
    <child link="RR_calf"/>
    <axis xyz="0 1 0"/>
    <dynamics damping="0" friction="0"/>
    <limit effort="24" lower="-2.49582083035" upper="-0.717155789644" velocity="31"/>
  </joint>
  <link name="RR_calf">
    <!-- <visual>
                <origin rpy="0 0 0" xyz="0 0 0" />
                <geometry>
                    <mesh filename="package://cyberdog_new_description/meshes/knee.dae" scale="1 1 1" />
                </geometry>
                <material name="orange" />
            </visual> -->
    <visual>
      <origin rpy="0 3.141592653589793 0" xyz="0 0 -0.1045"/>
      <geometry>
        <box size="0.016 0.016 0.209"/>
      </geometry>
      <material name="silver"/>
    </visual>
    <visual name="RR_calf_rubber">
      <origin rpy="0 3.141592653589793 0" xyz="-0.0125 0 -0.007"/>
      <geometry>
        <sphere radius="0.016"/>
      </geometry>
    </visual>
    <collision>
      <origin rpy="0 3.141592653589793 0" xyz="0 0 -0.1045"/>
      <geometry>
        <box size="0.016 0.016 0.209"/>
      </geometry>
    </collision>
    <collision name="RR_calf_rubber">
      <origin rpy="0 3.141592653589793 0" xyz="-0.0125 0 -0.007"/>
      <geometry>
        <sphere radius="0.016"/>
      </geometry>
      <surface>
        <contact>
          <ode>
            <max_vel>0.00001</max_vel>
            <min_depth>0.0</min_depth>
          </ode>
        </contact>
      </surface>
    </collision>
    <inertial>
      <origin rpy="0 0 0" xyz="0.007372358 0.000122423 -0.10769301"/>
      <mass value="0.1135916"/>
      <inertia ixx="0.000667971" ixy="-1e-09" ixz="5.356e-06" iyy="0.000674399" iyz="-1.5e-08" izz="1.4181e-05"/>
    </inertial>
  </link>
  <joint dont_collapse="true" name="RR_foot_fixed" type="fixed">
    <origin rpy="0 0 0" xyz="0 0 -0.19999999999999998"/>
    <parent link="RR_calf"/>
    <child link="RR_foot"/>
  </joint>
  <link name="RR_foot">
    <visual>
      <origin rpy="0 0 0" xyz="0 0 0"/>
      <geometry>
        <sphere radius="0.018"/>
      </geometry>
      <material name="silver"/>
    </visual>
    <collision>
      <origin rpy="0 0 0" xyz="0 0 0"/>
      <geometry>
        <sphere radius="0.018"/>
      </geometry>
      <surface>
        <contact>
          <ode>
            <max_vel>0.001</max_vel>
            <min_depth>0.0</min_depth>
          </ode>
        </contact>
      </surface>
    </collision>
  </link>
  <transmission name="RR_hip_tran">
    <type>transmission_interface/SimpleTransmission</type>
    <joint name="RR_hip_joint">
      <hardwareInterface>hardware_interface/EffortJointInterface</hardwareInterface>
    </joint>
    <actuator name="RR_hip_motor">
      <hardwareInterface>hardware_interface/EffortJointInterface</hardwareInterface>
      <mechanicalReduction>&quot;1&quot;</mechanicalReduction>
    </actuator>
  </transmission>
  <transmission name="RR_thigh_tran">
    <type>transmission_interface/SimpleTransmission</type>
    <joint name="RR_thigh_joint">
      <hardwareInterface>hardware_interface/EffortJointInterface</hardwareInterface>
    </joint>
    <actuator name="RR_thigh_motor">
      <hardwareInterface>hardware_interface/EffortJointInterface</hardwareInterface>
      <mechanicalReduction>&quot;1&quot;</mechanicalReduction>
    </actuator>
  </transmission>
  <transmission name="RR_calf_tran">
    <type>transmission_interface/SimpleTransmission</type>
    <joint name="RR_calf_joint">
      <hardwareInterface>hardware_interface/EffortJointInterface</hardwareInterface>
    </joint>
    <actuator name="RR_calf_motor">
      <hardwareInterface>hardware_interface/EffortJointInterface</hardwareInterface>
      <mechanicalReduction>&quot;1&quot;</mechanicalReduction>
    </actuator>
  </transmission>
  <joint name="RL_hip_joint" type="revolute">
    <origin rpy="0 0 0" xyz="-0.23035 0.05 0"/>
    <parent link="trunk"/>
    <child link="RL_hip"/>
    <axis xyz="1 0 0"/>
    <dynamics damping="0" friction="0"/>
    <limit effort="24" lower="-0.76096355387" upper="0.76096355387" velocity="31"/>
  </joint>
  <link name="RL_hip">
    <!-- <visual>
                <xacro:if value="${(mirror_dae == True) and (front_hind_dae == True)}">
                    <origin rpy="0 0 0" xyz="0 0 0" />
                </xacro:if>
                <xacro:if value="${(mirror_dae == False) and (front_hind_dae == True)}">
                    <origin rpy="${PI} 0 0" xyz="0 0 0" />
                </xacro:if>
                <xacro:if value="${(mirror_dae == True) and (front_hind_dae == False)}">
                    <origin rpy="0 ${PI} 0" xyz="0 0 0" />
                </xacro:if>
                <xacro:if value="${(mirror_dae == False) and (front_hind_dae == False)}">
                    <origin rpy="${PI} ${PI} 0" xyz="0 0 0" />
                </xacro:if>
                <geometry>
                    <mesh filename="package://cyberdog_new_description/meshes/abad.dae" scale="1 1 1" />
                </geometry>
                <material name="orange" />
            </visual> -->
    <visual>
      <origin rpy="1.5707963267948966 0 0" xyz="0 0 0"/>
      <geometry>
        <cylinder length="0.052" radius="0.047"/>
      </geometry>
      <material name="silver"/>
    </visual>
    <collision>
      <origin rpy="1.5707963267948966 0 0" xyz="0 0 0"/>
      <geometry>
        <cylinder length="0.052" radius="0.047"/>
      </geometry>
    </collision>
    <inertial>
      <origin rpy="0 0 0" xyz="0.001597914 0.001680938 2.253e-06"/>
      <mass value="0.537806728"/>
      <inertia ixx="0.000403612" ixy="9.337e-06" ixz="-5.36e-07" iyy="0.000600779" iyz="-6.3e-08" izz="0.000417249"/>
    </inertial>
  </link>
  <joint name="RL_hip_rotor_fix" type="fixed">
    <origin rpy="0 0 0" xyz="0.0832504 0 0"/>
    <parent link="RL_hip"/>
    <child link="RL_hip_rotor"/>
  </joint>
  <!-- this link is only for abad rotor inertial -->
  <link name="RL_hip_rotor">
    <inertial>
      <origin rpy="0 0 0" xyz="0 0 0"/>
      <mass value="0.076506382"/>
      <inertia ixx="4.5843e-05" ixy="0" ixz="0" iyy="4.5871e-05" iyz="0" izz="8.9031e-05"/>
    </inertial>
  </link>
  <joint name="RL_hip_fixed" type="fixed">
    <origin rpy="0 0 0" xyz="0 0.053076000000000005 0"/>
    <parent link="RL_hip"/>
    <child link="RL_thigh_shoulder"/>
  </joint>
  <link name="RL_thigh_shoulder">
    <visual>
      <origin rpy="1.5707963267948966 0 0" xyz="0 0 0"/>
      <geometry>
        <cylinder length="0.052" radius="0.047"/>
      </geometry>
      <material name="silver"/>
    </visual>
    <collision>
      <origin rpy="1.5707963267948966 0 0" xyz="0 0 0"/>
      <geometry>
        <cylinder length="0.052" radius="0.047"/>
      </geometry>
    </collision>
  </link>
  <joint name="RL_thigh_joint" type="revolute">
    <origin rpy="0 0 0" xyz="0 0.105076 0"/>
    <parent link="RL_hip"/>
    <child link="RL_thigh"/>
    <axis xyz="0 1 0"/>
    <dynamics damping="0" friction="0"/>
    <limit effort="24" lower="-1.88495559215" upper="3.76991118431" velocity="31"/>
  </joint>
  <link name="RL_thigh">
    <!-- <visual>
                <origin rpy="0 0 0" xyz="0 0 0" />
                <geometry>
                    <xacro:if value="${mirror_dae == True}">
                        <mesh filename="package://cyberdog_new_description/meshes/hip.dae"
                            scale="1 1 1" />
                    </xacro:if>
                    <xacro:if value="${mirror_dae == False}">
                        <mesh filename="package://cyberdog_new_description/meshes/hip_mirror.dae"
                            scale="1 1 1" />
                    </xacro:if>
                </geometry>
                <material name="orange" />
            </visual> -->
    <visual>
      <origin rpy="0 1.5707963267948966 0" xyz="0 0 -0.1"/>
      <geometry>
        <box size="0.2 0.035 0.05"/>
      </geometry>
      <material name="silver"/>
    </visual>
    <collision>
      <origin rpy="0 1.5707963267948966 0" xyz="0 0 -0.1"/>
      <geometry>
        <box size="0.2 0.035 0.05"/>
      </geometry>
    </collision>
    <inertial>
      <origin rpy="0 0 0" xyz="-0.003205778 -0.027811623 -0.027767048"/>
      <mass value="0.950266218"/>
      <inertia ixx="0.004811898" ixy="9.3647e-05" ixz="-0.000208709" iyy="0.004752366" iyz="0.000813258" izz="0.001079691"/>
    </inertial>
  </link>
  <joint name="RL_thigh_rotor_fix" type="fixed">
    <origin rpy="0 0 0" xyz="0 -0.107226 0"/>
    <parent link="RL_thigh"/>
    <child link="RL_thigh_rotor"/>
  </joint>
  <!-- this link is only for hip rotor inertial -->
  <link name="RL_thigh_rotor">
    <inertial>
      <origin rpy="0 0 0" xyz="0 0 0"/>
      <mass value="0.076506382"/>
      <inertia ixx="4.5843e-05" ixy="0" ixz="0" iyy="4.5871e-05" iyz="0" izz="8.9031e-05"/>
    </inertial>
  </link>
  <joint name="RL_calf_rotor_fix" type="fixed">
    <origin rpy="0 0 0" xyz="0 -0.0426259 0"/>
    <parent link="RL_thigh"/>
    <child link="RL_calf_rotor"/>
  </joint>
  <!-- this link is only for knee rotor inertial -->
  <link name="RL_calf_rotor">
    <inertial>
      <origin rpy="0 0 0" xyz="0 0 0"/>
      <mass value="0.076506382"/>
      <inertia ixx="4.5843e-05" ixy="0" ixz="0" iyy="4.5871e-05" iyz="0" izz="8.9031e-05"/>
    </inertial>
  </link>
  <joint name="RL_calf_joint" type="revolute">
    <origin rpy="0 0 0" xyz="0 0 -0.2"/>
    <parent link="RL_thigh"/>
    <child link="RL_calf"/>
    <axis xyz="0 1 0"/>
    <dynamics damping="0" friction="0"/>
    <limit effort="24" lower="-2.49582083035" upper="-0.717155789644" velocity="31"/>
  </joint>
  <link name="RL_calf">
    <!-- <visual>
                <origin rpy="0 0 0" xyz="0 0 0" />
                <geometry>
                    <mesh filename="package://cyberdog_new_description/meshes/knee.dae" scale="1 1 1" />
                </geometry>
                <material name="orange" />
            </visual> -->
    <visual>
      <origin rpy="0 3.141592653589793 0" xyz="0 0 -0.1045"/>
      <geometry>
        <box size="0.016 0.016 0.209"/>
      </geometry>
      <material name="silver"/>
    </visual>
    <visual name="RL_calf_rubber">
      <origin rpy="0 3.141592653589793 0" xyz="-0.0125 0 -0.007"/>
      <geometry>
        <sphere radius="0.016"/>
      </geometry>
    </visual>
    <collision>
      <origin rpy="0 3.141592653589793 0" xyz="0 0 -0.1045"/>
      <geometry>
        <box size="0.016 0.016 0.209"/>
      </geometry>
    </collision>
    <collision name="RL_calf_rubber">
      <origin rpy="0 3.141592653589793 0" xyz="-0.0125 0 -0.007"/>
      <geometry>
        <sphere radius="0.016"/>
      </geometry>
      <surface>
        <contact>
          <ode>
            <max_vel>0.00001</max_vel>
            <min_depth>0.0</min_depth>
          </ode>
        </contact>
      </surface>
    </collision>
    <inertial>
      <origin rpy="0 0 0" xyz="0.007372358 0.000122423 -0.10769301"/>
      <mass value="0.1135916"/>
      <inertia ixx="0.000667971" ixy="-1e-09" ixz="5.356e-06" iyy="0.000674399" iyz="-1.5e-08" izz="1.4181e-05"/>
    </inertial>
  </link>
  <joint dont_collapse="true" name="RL_foot_fixed" type="fixed">
    <origin rpy="0 0 0" xyz="0 0 -0.19999999999999998"/>
    <parent link="RL_calf"/>
    <child link="RL_foot"/>
  </joint>
  <link name="RL_foot">
    <visual>
      <origin rpy="0 0 0" xyz="0 0 0"/>
      <geometry>
        <sphere radius="0.018"/>
      </geometry>
      <material name="silver"/>
    </visual>
    <collision>
      <origin rpy="0 0 0" xyz="0 0 0"/>
      <geometry>
        <sphere radius="0.018"/>
      </geometry>
      <surface>
        <contact>
          <ode>
            <max_vel>0.001</max_vel>
            <min_depth>0.0</min_depth>
          </ode>
        </contact>
      </surface>
    </collision>
  </link>
  <transmission name="RL_hip_tran">
    <type>transmission_interface/SimpleTransmission</type>
    <joint name="RL_hip_joint">
      <hardwareInterface>hardware_interface/EffortJointInterface</hardwareInterface>
    </joint>
    <actuator name="RL_hip_motor">
      <hardwareInterface>hardware_interface/EffortJointInterface</hardwareInterface>
      <mechanicalReduction>&quot;1&quot;</mechanicalReduction>
    </actuator>
  </transmission>
  <transmission name="RL_thigh_tran">
    <type>transmission_interface/SimpleTransmission</type>
    <joint name="RL_thigh_joint">
      <hardwareInterface>hardware_interface/EffortJointInterface</hardwareInterface>
    </joint>
    <actuator name="RL_thigh_motor">
      <hardwareInterface>hardware_interface/EffortJointInterface</hardwareInterface>
      <mechanicalReduction>&quot;1&quot;</mechanicalReduction>
    </actuator>
  </transmission>
  <transmission name="RL_calf_tran">
    <type>transmission_interface/SimpleTransmission</type>
    <joint name="RL_calf_joint">
      <hardwareInterface>hardware_interface/EffortJointInterface</hardwareInterface>
    </joint>
    <actuator name="RL_calf_motor">
      <hardwareInterface>hardware_interface/EffortJointInterface</hardwareInterface>
      <mechanicalReduction>&quot;1&quot;</mechanicalReduction>
    </actuator>
  </transmission>
</robot>

