<?xml version="1.0" ?>
<!-- =================================================================================== -->
<!-- |    This document was autogenerated by xacro from tita.urdf.xacro                | -->
<!-- |    EDITING THIS FILE BY HAND IS NOT RECOMMENDED                                 | -->
<!-- =================================================================================== -->
<robot name="tita">
  <material name="black">
    <color rgba="0.19607843137254902 0.19607843137254902 0.19607843137254902 1.0"/>
  </material>
  <material name="blue">
    <color rgba="0.0 0.0 0.8 1.0"/>
  </material>
  <material name="green">
    <color rgba="0.0 0.8 0.0 1.0"/>
  </material>
  <material name="grey">
    <color rgba="0.2 0.2 0.2 1.0"/>
  </material>
  <material name="silver">
    <color rgba="0.9137254901960784 0.9137254901960784 0.8470588235294118 1.0"/>
  </material>
  <material name="orange">
    <color rgba="1.0 0.4235294117647059 0.0392156862745098 1.0"/>
  </material>
  <material name="brown">
    <color rgba="0.8705882352941177 0.8117647058823529 0.7647058823529411 1.0"/>
  </material>
  <material name="red">
    <color rgba="0.8 0.0 0.0 1.0"/>
  </material>
  <material name="white">
    <color rgba="1.0 1.0 1.0 1.0"/>
  </material>

  <link name="base">
    <visual>
        <origin rpy="0 0 0" xyz="0 0 0"/>
        <geometry>
            <box size="0.001 0.001 0.001"/> <!-- 很小的虚拟几何体 -->
        </geometry>
    </visual>
</link>

<joint name="floating_base" type="fixed">
    <origin rpy="0 0 0" xyz="0 0 0"/>
    <parent link="base"/>
    <child link="trunk"/>
</joint>


  <link name="trunk">
    <inertial>
      <origin rpy="0 0 0" xyz="0.020452 3.5457E-06 0.01871"/>
      <mass value="13.2"/>
      <inertia ixx="0.061855" ixy="-2.6029E-05" ixz="0.00081082" iyy="0.036934" iyz="-1.7269E-05" izz="0.071232"/>
    </inertial>
    <visual>
      <origin rpy="0 0 0" xyz="0 0 0"/>
      <geometry>
        <mesh filename="package://tita_description/meshes/base_link.STL"/>
      </geometry>
      <material name="black"/>
    </visual>
    <collision>
      <origin rpy="0 0 0" xyz="0 0 0.017"/>
      <geometry>
        <box size="0.47 0.3 0.19"/>
      </geometry>
    </collision>
  </link>
  <link name="spad_link">
    </link>
  <joint name="spad_joint" type="fixed">
    <origin rpy="2.199 0 1.5708" xyz="0.24052 -0.0019 0.064455"/>
    <parent link="trunk"/>
    <child link="spad_link"/>
    <axis xyz="0 0 0"/>
  </joint>
  <link name="spad1_link">
    </link>
  <joint name="spad1_joint" type="fixed">
    <origin rpy="2.632 0 1.5708" xyz="0.21953 -0.0019 -0.030142"/>
    <parent link="trunk"/>
    <child link="spad1_link"/>
    <axis xyz="0 0 0"/>
  </joint>
  <link name="left_camera_link">
    </link>
  <joint name="left_camera_joint" type="fixed">
    <origin rpy="1.5708 0 1.5708" xyz="0.23416 0.075 0.04036"/>
    <parent link="trunk"/>
    <child link="left_camera_link"/>
    <axis xyz="0 0 0"/>
  </joint>
  <link name="ch201_link">
    </link>
  <joint name="ch201_joint" type="fixed">
    <origin rpy="1.1693 0 1.5708" xyz="0.23782 0 0.018636"/>
    <parent link="trunk"/>
    <child link="ch201_link"/>
    <axis xyz="0 0 0"/>
  </joint>
  <link name="right_camara_link">
    </link>
  <joint name="right_camera_joint" type="fixed">
    <origin rpy="1.5708 0 1.5708" xyz="0.23416 -0.075001 0.04036"/>
    <parent link="trunk"/>
    <child link="right_camara_link"/>
    <axis xyz="0 0 0"/>
  </joint>
  <joint name="imu_joint" type="fixed">
    <parent link="trunk"/>
    <child link="imu_link"/>
    <origin rpy="0 0 0" xyz="0 0 0"/>
  </joint>
  <link name="imu_link">
    <inertial>
      <mass value="0.001"/>
      <origin rpy="0 0 0" xyz="0 0 0"/>
      <inertia ixx="0.0001" ixy="0" ixz="0" iyy="0.0001" iyz="0" izz="0.0001"/>
    </inertial>
    <visual>
      <origin rpy="0 0 0" xyz="0 0 0"/>
      <geometry>
        <box size="0.001 0.001 0.001"/>
      </geometry>
      <material name="red"/>
    </visual>
    <collision>
      <origin rpy="0 0 0" xyz="0 0 0"/>
      <geometry>
        <box size=".001 .001 .001"/>
      </geometry>
    </collision>
  </link>
  <link name="left_leg_1">
    <inertial>
      <origin rpy="0 0 0" xyz="0.0016025 5.0253E-05 0.000638"/>
      <mass value="2.064"/>
      <inertia ixx="0.0043044" ixy="-1.3538E-07" ixz="8.054E-05" iyy="0.0029982" iyz="-1.5446E-06" izz="0.0022703"/>
    </inertial>
    <visual>
      <origin rpy="0 0 0" xyz="0 0 0"/>
      <geometry>
        <mesh filename="package://tita_description/meshes/left_leg_1.STL"/>
      </geometry>
      <material name="black"/>
    </visual>
  </link>
  <joint name="joint_left_leg_1" type="revolute">
    <origin rpy="1.5708 0 1.5708" xyz="0 0.0895 0"/>
    <parent link="trunk"/>
    <child link="left_leg_1"/>
    <axis xyz="0 0 1"/>
    <limit effort="60" lower="-0.785398" upper="0.785398" velocity="100"/>
  </joint>
  <link name="left_leg_2">
    <inertial>
      <origin rpy="0 0 0" xyz="0.021763 0.0019069 -0.027868"/>
      <mass value="3.0984"/>
      <inertia ixx="0.0029784" ixy="-9.6332E-05" ixz="7.878E-05" iyy="0.0064836" iyz="4.3691E-06" izz="0.0088353"/>
    </inertial>
    <visual>
      <origin rpy="0 0 0" xyz="0 0 0"/>
      <geometry>
        <mesh filename="package://tita_description/meshes/left_leg_2.STL"/>
      </geometry>
      <material name="black"/>
    </visual>
  </link>
  <joint name="joint_left_leg_2" type="revolute">
    <origin rpy="-1.5708 0 -1.5708" xyz="0.1426 0 0"/>
    <parent link="left_leg_1"/>
    <child link="left_leg_2"/>
    <axis xyz="0 0 1"/>
    <limit effort="60" lower="-1.919862" upper="3.490659" velocity="100"/>
  </joint>
  <link name="left_leg_3">
    <inertial>
      <origin rpy="0 0 0" xyz="0.095348 0.011698 0.001838"/>
      <mass value="0.57244"/>
      <inertia ixx="0.00030595" ixy="0.00035537" ixz="-0.00011764" iyy="0.0032009" iyz="1.129E-05" izz="0.0034209"/>
    </inertial>
    <visual>
      <origin rpy="0 0 0" xyz="0 0 0"/>
      <geometry>
        <mesh filename="package://tita_description/meshes/left_leg_3.STL"/>
      </geometry>
      <material name="black"/>
    </visual>
    <collision>
      <origin rpy="0 0 -0.131" xyz="0.1 0.021 -0.002"/>
      <geometry>
        <box size="0.2 0.07 0.05"/>
      </geometry>
    </collision>
  </link>
  <joint name="joint_left_leg_3" type="revolute">
    <origin rpy="0 0 0" xyz="0.2 0 0"/>
    <parent link="left_leg_2"/>
    <child link="left_leg_3"/>
    <axis xyz="0 0 1"/>
    <limit effort="60" lower="-2.670354" upper="-0.698132" velocity="100"/>
  </joint>
  <link name="left_leg_4">
    <inertial>
      <origin rpy="0 0 0" xyz="-2.267E-06 -1.6471E-06 -0.00095616"/>
      <mass value="1.5094"/>
      <inertia ixx="0.0035466" ixy="6.9816E-06" ixz="-2.3224E-07" iyy="0.0035053" iyz="-1.7712E-08" izz="0.0069049"/>
    </inertial>
    <visual>
      <origin rpy="0 0 0" xyz="0 0 0"/>
      <geometry>
        <mesh filename="package://tita_description/meshes/left_leg_4.STL"/>
      </geometry>
      <material name="black"/>
    </visual>
    <collision>
      <origin rpy="0 0 0" xyz="0 0 0"/>
      <geometry>
        <cylinder length="0.034" radius="0.0925"/>
      </geometry>
    </collision>
  </link>
  <joint name="joint_left_leg_4" type="revolute">
    <origin rpy="0 0 0" xyz="0.2 0 0.0514"/>
    <parent link="left_leg_3"/>
    <child link="left_leg_4"/>
    <axis xyz="0 0 1"/>
    <limit effort="15" lower="-6.283185e4" upper="6.283185e4" velocity="100"/>
  </joint>
  <link name="right_leg_1">
    <inertial>
      <origin rpy="0 0 0" xyz="-0.0016025 5.0253E-05 0.00063801"/>
      <mass value="2.064"/>
      <inertia ixx="0.0043044" ixy="1.3538E-07" ixz="-8.054E-05" iyy="0.0029982" iyz="-1.5359E-06" izz="0.0022703"/>
    </inertial>
    <visual>
      <origin rpy="0 0 0" xyz="0 0 0"/>
      <geometry>
        <mesh filename="package://tita_description/meshes/right_leg_1.STL"/>
      </geometry>
      <material name="black"/>
    </visual>
  </link>
  <joint name="joint_right_leg_1" type="revolute">
    <origin rpy="1.5708 0 1.5708" xyz="0 -0.0895 0"/>
    <parent link="trunk"/>
    <child link="right_leg_1"/>
    <axis xyz="0 0 1"/>
    <limit effort="60" lower="-0.785398" upper="0.785398" velocity="100"/>
  </joint>
  <link name="right_leg_2">
    <inertial>
      <origin rpy="0 0 0" xyz="0.021763 0.0019065 0.027873"/>
      <mass value="3.0987"/>
      <inertia ixx="0.0029784" ixy="-9.6347E-05" ixz="-7.8776E-05" iyy="0.0064836" iyz="-4.3711E-06" izz="0.0088353"/>
    </inertial>
    <visual>
      <origin rpy="0 0 0" xyz="0 0 0"/>
      <geometry>
        <mesh filename="package://tita_description/meshes/right_leg_2.STL"/>
      </geometry>
      <material name="black"/>
    </visual>
  </link>
  <joint name="joint_right_leg_2" type="revolute">
    <origin rpy="-1.5708 0 -1.5708" xyz="-0.1426 0 0"/>
    <parent link="right_leg_1"/>
    <child link="right_leg_2"/>
    <axis xyz="0 0 1"/>
    <limit effort="60" lower="-1.919862" upper="3.490659" velocity="100"/>
  </joint>
  <link name="right_leg_3">
    <inertial>
      <origin rpy="0 0 0" xyz="0.095348 0.011698 -0.001838"/>
      <mass value="0.57244"/>
      <inertia ixx="0.00030595" ixy="0.00035537" ixz="0.00011764" iyy="0.0032009" iyz="-1.129E-05" izz="0.0034209"/>
    </inertial>
    <visual>
      <origin rpy="0 0 0" xyz="0 0 0"/>
      <geometry>
        <mesh filename="package://tita_description/meshes/right_leg_3.STL"/>
      </geometry>
      <material name="black"/>
    </visual>
    <collision>
      <origin rpy="0 0 -0.131" xyz="0.1 0.021 -0.002"/>
      <geometry>
        <box size="0.2 0.07 0.05"/>
      </geometry>
    </collision>
  </link>
  <joint name="joint_right_leg_3" type="revolute">
    <origin rpy="0 0 0" xyz="0.2 0 0"/>
    <parent link="right_leg_2"/>
    <child link="right_leg_3"/>
    <axis xyz="0 0 1"/>
    <limit effort="60" lower="-2.670354" upper="-0.698132" velocity="100"/>
  </joint>
  <link name="right_leg_4">
    <inertial>
      <origin rpy="0 0 0" xyz="-2.3798E-06 -1.5854E-06 0.00095595"/>
      <mass value="1.5094"/>
      <inertia ixx="0.0035465" ixy="7.0548E-06" ixz="2.3146E-07" iyy="0.0035052" iyz="1.9287E-08" izz="0.0069047"/>
    </inertial>
    <visual>
      <origin rpy="0 0 0" xyz="0 0 0"/>
      <geometry>
        <mesh filename="package://tita_description/meshes/right_leg_4.STL"/>
      </geometry>
      <material name="black"/>
    </visual>
    <collision>
      <origin rpy="0 0 0" xyz="0 0 0"/>
      <geometry>
        <cylinder length="0.034" radius="0.0925"/>
      </geometry>
    </collision>
  </link>
  <joint name="joint_right_leg_4" type="revolute">
    <origin rpy="0 0 0" xyz="0.2 0 -0.0514"/>
    <parent link="right_leg_3"/>
    <child link="right_leg_4"/>
    <axis xyz="0 0 1"/>
    <limit effort="15" lower="-6.283185e4" upper="6.283185e4" velocity="20"/>
  </joint>



  <transmission name="L_hip_tran">
    <type>transmission_interface/SimpleTransmission</type>
    <joint name="joint_left_leg_1">
      <hardwareInterface>hardware_interface/EffortJointInterface</hardwareInterface>
    </joint>
    <actuator name="L_hip_motor">
      <hardwareInterface>hardware_interface/EffortJointInterface</hardwareInterface>
      <mechanicalReduction>1</mechanicalReduction>
    </actuator>
  </transmission>

  <transmission name="L_thigh_tran">
    <type>transmission_interface/SimpleTransmission</type>
    <joint name="joint_left_leg_2">
      <hardwareInterface>hardware_interface/EffortJointInterface</hardwareInterface>
    </joint>
    <actuator name="L_thigh_motor">
      <hardwareInterface>hardware_interface/EffortJointInterface</hardwareInterface>
      <mechanicalReduction>1</mechanicalReduction>
    </actuator>
  </transmission>


  <transmission name="L_calf_tran">
    <type>transmission_interface/SimpleTransmission</type>
    <joint name="joint_left_leg_3">
      <hardwareInterface>hardware_interface/EffortJointInterface</hardwareInterface>
    </joint>
    <actuator name="L_calf_motor">
      <hardwareInterface>hardware_interface/EffortJointInterface</hardwareInterface>
      <mechanicalReduction>1</mechanicalReduction>
    </actuator>
  </transmission>

  <transmission name="L_foot_tran">
    <type>transmission_interface/SimpleTransmission</type>
    <joint name="joint_left_leg_4">
      <hardwareInterface>hardware_interface/EffortJointInterface</hardwareInterface>
    </joint>
    <actuator name="L_foot_motor">
      <hardwareInterface>hardware_interface/EffortJointInterface</hardwareInterface>
      <mechanicalReduction>1</mechanicalReduction>
    </actuator>
  </transmission>

  <transmission name="R_hip_tran">
    <type>transmission_interface/SimpleTransmission</type>
    <joint name="joint_right_leg_1">
      <hardwareInterface>hardware_interface/EffortJointInterface</hardwareInterface>
    </joint>
    <actuator name="R_hip_motor">
      <hardwareInterface>hardware_interface/EffortJointInterface</hardwareInterface>
      <mechanicalReduction>1</mechanicalReduction>
    </actuator>
  </transmission>

  <transmission name="R_thigh_tran">
    <type>transmission_interface/SimpleTransmission</type>
    <joint name="joint_right_leg_2">
      <hardwareInterface>hardware_interface/EffortJointInterface</hardwareInterface>
    </joint>
    <actuator name="R_thigh_motor">
      <hardwareInterface>hardware_interface/EffortJointInterface</hardwareInterface>
      <mechanicalReduction>1</mechanicalReduction>
    </actuator>
  </transmission>

  <transmission name="R_calf_tran">
    <type>transmission_interface/SimpleTransmission</type>
    <joint name="joint_right_leg_3">
      <hardwareInterface>hardware_interface/EffortJointInterface</hardwareInterface>
    </joint>
    <actuator name="R_calf_motor">
      <hardwareInterface>hardware_interface/EffortJointInterface</hardwareInterface>
      <mechanicalReduction>1</mechanicalReduction>
    </actuator>
  </transmission>
  <transmission name="R_foot_tran">
    <type>transmission_interface/SimpleTransmission</type>
    <joint name="joint_right_leg_4">
      <hardwareInterface>hardware_interface/EffortJointInterface</hardwareInterface>
    </joint>
    <actuator name="R_foot_motor">
      <hardwareInterface>hardware_interface/EffortJointInterface</hardwareInterface>
      <mechanicalReduction>1</mechanicalReduction>
    </actuator>
  </transmission>

</robot>
