<?xml version="1.0" encoding="utf-8"?>
<!-- This URDF was automatically created by SolidWorks to URDF Exporter! Originally created by Stephen Brawner (brawner@gmail.com)
     Commit Version: 1.6.0-4-g7f85cfe  Build Version: 1.6.7995.38578
     For more information, please see http://wiki.ros.org/sw_urdf_exporter -->
<robot name="l4w4">
  <material name="black">
    <color rgba="0.0 0.0 0.0 1.0"/>
  </material>
  <material name="blue">
    <color rgba="0.0 0.0 0.8 1.0"/>
  </material>
  <material name="green">
    <color rgba="0.0 0.8 0.0 1.0"/>
  </material>
  <material name="grey">
    <color rgba="0.2 0.2 0.2 1.0"/>
  </material>
  <material name="silver">
    <color rgba="0.913725490196 0.913725490196 0.847058823529 1.0"/>
  </material>
  <material name="orange">
    <color rgba="1.0 0.423529411765 0.0392156862745 1.0"/>
  </material>
  <material name="brown">
    <color rgba="0.870588235294 0.811764705882 0.764705882353 1.0"/>
  </material>
  <material name="red">
    <color rgba="0.8 0.0 0.0 1.0"/>
  </material>
  <material name="white">
    <color rgba="1.0 1.0 1.0 1.0"/>
  </material>

  <link name="base">
    <visual>
      <origin rpy="0 0 0" xyz="0 0 0"/>
      <geometry>
        <box size="0.001 0.001 0.001"/>
      </geometry>
    </visual>
  </link>
  <joint name="floating_base" type="fixed">
    <origin rpy="0 0 0" xyz="0 0 0"/>
    <parent link="base"/>
    <child link="trunk"/>
  </joint>

  <link name="trunk">
    <inertial>
      <origin xyz="-0.0107 -0.00135 0.005" rpy="0 0 0" />
      <mass value="18.057" />
      <inertia ixx="0.12015" ixy="-0.00086" ixz="-0.00124" iyy="0.36210" iyz="-0.00004" izz="0.40829" />
    </inertial>
    <visual>
      <origin xyz="0 0 0" rpy="0 0 0" />
      <geometry>
        <mesh filename="package://l4w4_description/meshes/trunk.STL" />
      </geometry>
      <material name="">
        <color rgba="0.25 0.25 0.25 1" />
      </material>
    </visual>
    <collision>
      <origin xyz="0 0 0" rpy="0 0 0" />
      <geometry>
        <box size="0.688 0.18 0.18" />
      </geometry>
    </collision>
  </link>


  <link name="FR_hip">
    <inertial>
      <origin xyz="-0.004726 -0.001176 0.000044" rpy="0 0 0" />
      <mass value="2" />
      <inertia ixx="0.003012" ixy="0.000018" ixz="0.000006" iyy="0.005188" iyz="-0.000004" izz="0.003993" />
    </inertial>
    <visual>
      <origin xyz="0 0 0" rpy="0 0 0" />
      <geometry>
        <mesh filename="package://l4w4_description/meshes/shoulder_R.STL" />
      </geometry>
      <material name="">
        <color rgba="1 0.7765 0.0314 1" />
      </material>
    </visual>
    <collision>
      <origin xyz="0 0 0" rpy="0 0 0" />
      <geometry>
        <cylinder length="0" radius="0" />
      </geometry>
    </collision>
  </link>
  <joint name="FR_hip_joint" type="revolute">
    <origin xyz="0.249 -0.065 0" rpy="0 0 0" />
    <parent link="trunk" />
    <child link="FR_hip" />
    <axis xyz="1 0 0" />
    <limit lower="-0.5236" upper="0.5236" effort="110" velocity="11.5" />
  </joint>

  <link name="FR_thigh">
    <inertial>
      <origin xyz="-0.007013 -0.09103 -0.06380" rpy="0 0 0" />
      <mass value="3.396" />
      <inertia ixx="0.043751" ixy="0.000606" ixz="0.002054" iyy="0.043937" iyz="0.005154" izz="0.006846" />
    </inertial>
    <visual>
      <origin xyz="0 0 0" rpy="0 0 0" />
      <geometry>
        <mesh filename="package://l4w4_description/meshes/thigh_R.STL" scale = "1 1 1"/>
      </geometry>
      <material name="">
        <color rgba="1 1 1 1" />
      </material>
    </visual>
    <collision>
      <origin xyz="0 -0.1145 -0.100" rpy="0 0 0" />
      <geometry>
        <box size="0.122 0.044 0.32" />
      </geometry>
    </collision>
  </link>
  <joint name="FR_thigh_joint" type="revolute">
    <origin xyz="0 0 0" rpy="0 0 0" />
    <parent link="FR_hip" />
    <child link="FR_thigh" />
    <axis xyz="0 1 0" />
    <limit lower="-1.4" upper="3.14" effort="110" velocity="12.56" />
  </joint>

  <link name="FR_calf">
    <inertial>
      <origin xyz="-0.001448 0.001637 -0.130288" rpy="0 0 0" />
      <mass value="0.829" />
      <inertia ixx="0.012593" ixy="0.000001" ixz="-0.000510" iyy="0.012842" iyz="-0.000137" izz="0.000514" />
    </inertial>
    <visual>
      <origin xyz="0 0 0" rpy="0 0 0" />
      <geometry>
        <mesh filename="package://l4w4_description/meshes/shank_R.STL" scale = "1 1 1"/>
      </geometry>
      <material name="">
        <color rgba="1 0.8 0.8 1" />
      </material>
    </visual>
    <collision>
      <origin xyz="0 0 -0.2" rpy="0 0 0" />
      <geometry>
        <box size="0.06 0.03 0.1"/>
      </geometry>
    </collision>
  </link>
  <joint name="FR_calf_joint" type="revolute">
    <origin xyz="0 -0.1145 -0.3" rpy="0 0 0" />
    <parent link="FR_thigh" />
    <child link="FR_calf" />
    <axis xyz="0 1 0" />
    <limit lower="-2.7" upper="-0.17" effort="135" velocity="12.56" />
  </joint>

  <link name="FR_foot">
    <inertial>
      <origin xyz="0 -0.0559 0" rpy="0 0 0" />
      <mass value="2.6" />
      <inertia ixx="0.003934" ixy="0.0" ixz="0.000004" iyy="0.007113" iyz="-0.000004" izz="0.00395" />
    </inertial>
    <visual>
      <origin xyz="0 0 0" rpy="0 0 0" />
      <geometry>
        <mesh filename="package://l4w4_description/meshes/wheel_R.STL" scale = "1 1 1"/>
      </geometry>
      <material name="">
        <color rgba="0.25 0.25 0.25 1" />
      </material>
    </visual>
    <collision>
      <origin xyz="0 -0.0559 0" rpy="1.570796327 0 0" />
      <geometry>
        <cylinder length="0.040" radius="0.105"/>
      </geometry>
    </collision>
  </link>
  <joint name="FR_foot_joint" type="revolute">
    <origin xyz="0 0 -0.3" rpy="0 0 0" />
    <parent link="FR_calf" />
    <child link="FR_foot" />
    <axis xyz="0 1 0" />
    <limit lower="-1000000" upper="1000000" effort="32" velocity="12.0" />
  </joint>

  <transmission name="FR_hip_tran">
    <type>transmission_interface/SimpleTransmission</type>
    <joint name="FR_hip_joint">
      <hardwareInterface>hardware_interface/EffortJointInterface</hardwareInterface>
    </joint>
    <actuator name="FR_hip_motor">
      <hardwareInterface>hardware_interface/EffortJointInterface</hardwareInterface>
      <mechanicalReduction>1</mechanicalReduction>
    </actuator>
  </transmission>
  <transmission name="FR_thigh_tran">
    <type>transmission_interface/SimpleTransmission</type>
    <joint name="FR_thigh_joint">
      <hardwareInterface>hardware_interface/EffortJointInterface</hardwareInterface>
    </joint>
    <actuator name="FR_thigh_motor">
      <hardwareInterface>hardware_interface/EffortJointInterface</hardwareInterface>
      <mechanicalReduction>1</mechanicalReduction>
    </actuator>
  </transmission>
  <transmission name="FR_calf_tran">
    <type>transmission_interface/SimpleTransmission</type>
    <joint name="FR_calf_joint">
      <hardwareInterface>hardware_interface/EffortJointInterface</hardwareInterface>
    </joint>
    <actuator name="FR_calf_motor">
      <hardwareInterface>hardware_interface/EffortJointInterface</hardwareInterface>
      <mechanicalReduction>1</mechanicalReduction>
    </actuator>
  </transmission>
  <transmission name="FR_foot_tran">
    <type>transmission_interface/SimpleTransmission</type>
    <joint name="FR_foot_joint">
      <hardwareInterface>hardware_interface/EffortJointInterface</hardwareInterface>
    </joint>
    <actuator name="FR_foot_motor">
      <hardwareInterface>hardware_interface/EffortJointInterface</hardwareInterface>
      <mechanicalReduction>1</mechanicalReduction>
    </actuator>
  </transmission>

  <link name="FL_hip">
    <inertial>
      <origin xyz="-0.004726 0.001176 0.000044" rpy="0 0 0" />
      <mass value="2" />
      <inertia ixx="0.003012" ixy="-0.000018" ixz="0.000006" iyy="0.005188" iyz="0.000004" izz="0.003993" />
    </inertial>
    <visual>
      <origin xyz="0 0 0" rpy="0 0 0" />
      <geometry>
        <mesh filename="package://l4w4_description/meshes/shoulder_R.STL" scale = "1 -1 1"/>
      </geometry>
      <material name="">
        <color rgba="1 0.7765 0.0314 1" />
      </material>
    </visual>
    <collision>
      <origin xyz="0 0 0" rpy="0 0 0" />
      <geometry>
        <cylinder length="0" radius="0" />
      </geometry>
    </collision>
  </link>
  <joint name="FL_hip_joint" type="revolute">
    <origin xyz="0.249 0.065 0" rpy="0 0 0" />
    <parent link="trunk" />
    <child link="FL_hip" />
    <axis xyz="1 0 0" />
    <limit lower="-0.5236" upper="0.5236" effort="110" velocity="11.5" />
  </joint>

  <link name="FL_thigh">
    <inertial>
      <origin xyz="-0.007013 0.09103 -0.06380" rpy="0 0 0" />
      <mass value="3.396" />
      <inertia ixx="0.043751" ixy="-0.000606" ixz="0.002054" iyy="0.043937" iyz="-0.005154" izz="0.006846" />
    </inertial>
    <visual>
      <origin xyz="0 0 0" rpy="0 0 0" />
      <geometry>
        <mesh filename="package://l4w4_description/meshes/thigh_R.STL" scale = "1 -1 1"/>
      </geometry>
      <material name="">
        <color rgba="1 1 1 1" />
      </material>
    </visual>
    <collision>
      <origin xyz="0 0.1145 -0.100" rpy="0 0 0" />
      <geometry>
        <box size="0.122 0.044 0.32" />
      </geometry>
    </collision>
  </link>
  <joint name="FL_thigh_joint" type="revolute">
    <origin xyz="0 0 0" rpy="0 0 0" />
    <parent link="FL_hip" />
    <child link="FL_thigh" />
    <axis xyz="0 1 0" />
    <limit lower="-1.4" upper="3.14" effort="110" velocity="12.56" />
  </joint>

  <link name="FL_calf">
    <inertial>
      <origin xyz="-0.001448 -0.001637 -0.130288" rpy="0 0 0" />
      <mass value="0.829" />
      <inertia ixx="0.012593" ixy="-0.000001" ixz="-0.000510" iyy="0.012842" iyz="0.000137" izz="0.000514" />
    </inertial>
    <visual>
      <origin xyz="0 0 0" rpy="0 0 0" />
      <geometry>
        <mesh filename="package://l4w4_description/meshes/shank_R.STL" scale = "1 -1 1"/>
      </geometry>
      <material name="">
        <color rgba="1 0.8 0.8 1" />
      </material>
    </visual>
    <collision>
      <origin xyz="0 0 -0.2" rpy="0 0 0" />
      <geometry>
        <box size="0.06 0.03 0.1"/>
      </geometry>
    </collision>
  </link>
  <joint name="FL_calf_joint" type="revolute">
    <origin xyz="0 0.1145 -0.3" rpy="0 0 0" />
    <parent link="FL_thigh" />
    <child link="FL_calf" />
    <axis xyz="0 1 0" />
    <limit lower="-2.7" upper="-0.17" effort="135" velocity="12.56" />
  </joint>

  <link name="FL_foot">
    <inertial>
      <origin xyz="0 0.0559 0" rpy="0 0 0" />
      <mass value="2.6" />
      <inertia ixx="0.003934" ixy="0.0" ixz="0.000004" iyy="0.007113" iyz="0.000004" izz="0.00395" />
    </inertial>
    <visual>
      <origin xyz="0 0 0" rpy="0 0 0" />
      <geometry>
        <mesh filename="package://l4w4_description/meshes/wheel_R.STL" scale = "1 -1 1"/>
      </geometry>
      <material name="">
        <color rgba="0.25 0.25 0.25 1" />
      </material>
    </visual>
    <collision>
      <origin xyz="0 0.0559 0" rpy="1.570796327 0 0" />
      <geometry>
        <cylinder length="0.040" radius="0.105"/>
      </geometry>
    </collision>
  </link>
  <joint name="FL_foot_joint" type="revolute">
    <origin xyz="0 0 -0.3" rpy="0 0 0" />
    <parent link="FL_calf" />
    <child link="FL_foot" />
    <axis xyz="0 1 0" />
    <limit lower="-1000000" upper="1000000" effort="32" velocity="12.0" />
  </joint>

  <transmission name="FL_hip_tran">
    <type>transmission_interface/SimpleTransmission</type>
    <joint name="FL_hip_joint">
      <hardwareInterface>hardware_interface/EffortJointInterface</hardwareInterface>
    </joint>
    <actuator name="FL_hip_motor">
      <hardwareInterface>hardware_interface/EffortJointInterface</hardwareInterface>
      <mechanicalReduction>1</mechanicalReduction>
    </actuator>
  </transmission>
  <transmission name="FL_thigh_tran">
    <type>transmission_interface/SimpleTransmission</type>
    <joint name="FL_thigh_joint">
      <hardwareInterface>hardware_interface/EffortJointInterface</hardwareInterface>
    </joint>
    <actuator name="FL_thigh_motor">
      <hardwareInterface>hardware_interface/EffortJointInterface</hardwareInterface>
      <mechanicalReduction>1</mechanicalReduction>
    </actuator>
  </transmission>
  <transmission name="FL_calf_tran">
    <type>transmission_interface/SimpleTransmission</type>
    <joint name="FL_calf_joint">
      <hardwareInterface>hardware_interface/EffortJointInterface</hardwareInterface>
    </joint>
    <actuator name="FL_calf_motor">
      <hardwareInterface>hardware_interface/EffortJointInterface</hardwareInterface>
      <mechanicalReduction>1</mechanicalReduction>
    </actuator>
  </transmission>
  <transmission name="FL_foot_tran">
    <type>transmission_interface/SimpleTransmission</type>
    <joint name="FL_foot_joint">
      <hardwareInterface>hardware_interface/EffortJointInterface</hardwareInterface>
    </joint>
    <actuator name="FL_foot_motor">
      <hardwareInterface>hardware_interface/EffortJointInterface</hardwareInterface>
      <mechanicalReduction>1</mechanicalReduction>
    </actuator>
  </transmission>

  <link name="RR_hip">
    <inertial>
      <origin xyz="0.004726 -0.001176 0.000044" rpy="0 0 0" />
      <mass value="2" />
      <inertia ixx="0.003012" ixy="-0.000018" ixz="-0.000006" iyy="0.005188" iyz="-0.000004" izz="0.003993" />
    </inertial>
    <visual>
      <origin xyz="0 0 0" rpy="0 0 0" />
      <geometry>
        <mesh filename="package://l4w4_description/meshes/shoulder_R.STL" scale="-1 1 1"/>
      </geometry>
      <material name="">
        <color rgba="1 0.7765 0.0314 1" />
      </material>
    </visual>
    <collision>
      <origin xyz="0 0 0" rpy="0 0 0" />
      <geometry>
        <cylinder length="0" radius="0" />
      </geometry>
    </collision>
  </link>
  <joint name="RR_hip_joint" type="revolute">
    <origin xyz="-0.249 -0.065 0" rpy="0 0 0" />
    <parent link="trunk" />
    <child link="RR_hip" />
    <axis xyz="1 0 0" />
    <limit lower="-0.5236" upper="0.5236" effort="110" velocity="11.5" />
  </joint>

  <link name="RR_thigh">
    <inertial>
      <origin xyz="-0.007013 -0.09103 -0.06380" rpy="0 0 0" />
      <mass value="3.396" />
      <inertia ixx="0.043751" ixy="0.000606" ixz="0.002054" iyy="0.043937" iyz="0.005154" izz="0.006846" />
    </inertial>
    <visual>
      <origin xyz="0 0 0" rpy="0 0 0" />
      <geometry>
        <mesh filename="package://l4w4_description/meshes/thigh_R.STL" scale = "1 1 1"/>
      </geometry>
      <material name="">
        <color rgba="1 0.7765 0.0314 1" />
      </material>
    </visual>
    <collision>
      <origin xyz="0 -0.1145 -0.100" rpy="0 0 0" />
      <geometry>
        <box size="0.122 0.044 0.32" />
      </geometry>
    </collision>
  </link>
  <joint name="RR_thigh_joint" type="revolute">
    <origin xyz="0 0 0" rpy="0 0 0" />
    <parent link="RR_hip" />
    <child link="RR_thigh" />
    <axis xyz="0 1 0" />
    <limit lower="-1.4" upper="3.14" effort="110" velocity="12.56" />
  </joint>

  <link name="RR_calf">
    <inertial>
      <origin xyz="-0.001448 0.001637 -0.130288" rpy="0 0 0" />
      <mass value="0.829" />
      <inertia ixx="0.012593" ixy="0.000001" ixz="-0.000510" iyy="0.012842" iyz="-0.000137" izz="0.000514" />
    </inertial>
    <visual>
      <origin xyz="0 0 0" rpy="0 0 0" />
      <geometry>
        <mesh filename="package://l4w4_description/meshes/shank_R.STL" scale = "1 1 1"/>
      </geometry>
      <material name="">
        <color rgba="1 0.8 0.8 1" />
      </material>
    </visual>
    <collision>
      <origin xyz="0 0 -0.2" rpy="0 0 0" />
      <geometry>
        <box size="0.06 0.03 0.1"/>
      </geometry>
    </collision>
  </link>
  <joint name="RR_calf_joint" type="revolute">
    <origin xyz="0 -0.1145 -0.3" rpy="0 0 0" />
    <parent link="RR_thigh" />
    <child link="RR_calf" />
    <axis xyz="0 1 0" />
    <limit lower="-2.7" upper="-0.17" effort="135" velocity="12.56" />
  </joint>

  <link name="RR_foot">
    <inertial>
      <origin xyz="0 -0.0559 0" rpy="0 0 0" />
      <mass value="2.6" />
      <inertia ixx="0.003934" ixy="0.0" ixz="0.000004" iyy="0.007113" iyz="-0.000004" izz="0.00395" />
    </inertial>
    <visual>
      <origin xyz="0 0 0" rpy="0 0 0" />
      <geometry>
        <mesh filename="package://l4w4_description/meshes/wheel_R.STL" scale = "1 1 1"/>
      </geometry>
      <material name="">
        <color rgba="0.25 0.25 0.25 1" />
      </material>
    </visual>
    <collision>
      <origin xyz="0 -0.0559 0" rpy="1.570796327 0 0" />
      <geometry>
        <cylinder length="0.040" radius="0.105"/>
      </geometry>
    </collision>
  </link>
  <joint name="RR_foot_joint" type="revolute">
    <origin xyz="0 0 -0.3" rpy="0 0 0" />
    <parent link="RR_calf" />
    <child link="RR_foot" />
    <axis xyz="0 1 0" />
    <limit lower="-1000000" upper="1000000" effort="32" velocity="12.0" />
  </joint>

  <link name="RL_hip">
    <inertial>
      <origin xyz="0.004726 0.001176 0.000044" rpy="0 0 0" />
      <mass value="2" />
      <inertia ixx="0.003012" ixy="0.000018" ixz="-0.000006" iyy="0.005188" iyz="0.000004" izz="0.003993" />
    </inertial>
    <visual>
      <origin xyz="0 0 0" rpy="0 0 0" />
      <geometry>
        <mesh filename="package://l4w4_description/meshes/shoulder_R.STL" scale = "-1 -1 1"/>
      </geometry>
      <material name="">
        <color rgba="1 0.7765 0.0314 1" />
      </material>
    </visual>
    <collision>
      <origin xyz="0 0 0" rpy="0 0 0" />
      <geometry>
        <cylinder length="0" radius="0" />
      </geometry>
    </collision>
  </link>
  <joint name="RL_hip_joint" type="revolute">
    <origin xyz="-0.249 0.065 0" rpy="0 0 0" />
    <parent link="trunk" />
    <child link="RL_hip" />
    <axis xyz="1 0 0" />
    <limit lower="-0.5236" upper="0.5236" effort="110" velocity="11.5" />
  </joint>

  <transmission name="RL_hip_tran">
    <type>transmission_interface/SimpleTransmission</type>
    <joint name="RL_hip_joint">
      <hardwareInterface>hardware_interface/EffortJointInterface</hardwareInterface>
    </joint>
    <actuator name="RL_hip_motor">
      <hardwareInterface>hardware_interface/EffortJointInterface</hardwareInterface>
      <mechanicalReduction>1</mechanicalReduction>
    </actuator>
  </transmission>
  <transmission name="RL_thigh_tran">
    <type>transmission_interface/SimpleTransmission</type>
    <joint name="RL_thigh_joint">
      <hardwareInterface>hardware_interface/EffortJointInterface</hardwareInterface>
    </joint>
    <actuator name="RL_thigh_motor">
      <hardwareInterface>hardware_interface/EffortJointInterface</hardwareInterface>
      <mechanicalReduction>1</mechanicalReduction>
    </actuator>
  </transmission>
  <transmission name="RL_calf_tran">
    <type>transmission_interface/SimpleTransmission</type>
    <joint name="RL_calf_joint">
      <hardwareInterface>hardware_interface/EffortJointInterface</hardwareInterface>
    </joint>
    <actuator name="RL_calf_motor">
      <hardwareInterface>hardware_interface/EffortJointInterface</hardwareInterface>
      <mechanicalReduction>1</mechanicalReduction>
    </actuator>
  </transmission>
  <transmission name="RL_foot_tran">
    <type>transmission_interface/SimpleTransmission</type>
    <joint name="RL_foot_joint">
      <hardwareInterface>hardware_interface/EffortJointInterface</hardwareInterface>
    </joint>
    <actuator name="RL_foot_motor">
      <hardwareInterface>hardware_interface/EffortJointInterface</hardwareInterface>
      <mechanicalReduction>1</mechanicalReduction>
    </actuator>
  </transmission>

  <link name="RL_thigh">
    <inertial>
      <origin xyz="-0.007013 0.09103 -0.06380" rpy="0 0 0" />
      <mass value="3.396" />
      <inertia ixx="0.043751" ixy="-0.000606" ixz="0.002054" iyy="0.043937" iyz="-0.005154" izz="0.006846" />
    </inertial>
    <visual>
      <origin xyz="0 0 0" rpy="0 0 0" />
      <geometry>
        <mesh filename="package://l4w4_description/meshes/thigh_R.STL" scale = "1 -1 1"/>
      </geometry>
      <material name="">
        <color rgba="1 0.7765 0.0314 1" />
      </material>
    </visual>
    <collision>
      <origin xyz="0 0.1145 -0.100" rpy="0 0 0" />
      <geometry>
        <box size="0.122 0.044 0.32" />
      </geometry>
    </collision>
  </link>
  <joint name="RL_thigh_joint" type="revolute">
    <origin xyz="0 0 0" rpy="0 0 0" />
    <parent link="RL_hip" />
    <child link="RL_thigh" />
    <axis xyz="0 1 0" />
    <limit lower="-1.4" upper="3.14" effort="110" velocity="12.56" />
  </joint>

  <link name="RL_calf">
    <inertial>
      <origin xyz="-0.001448 -0.001637 -0.130288" rpy="0 0 0" />
      <mass value="0.829" />
      <inertia ixx="0.012593" ixy="-0.000001" ixz="-0.000510" iyy="0.012842" iyz="0.000137" izz="0.000514" />
    </inertial>
    <visual>
      <origin xyz="0 0 0" rpy="0 0 0" />
      <geometry>
        <mesh filename="package://l4w4_description/meshes/shank_R.STL" scale = "1 -1 1"/>
      </geometry>
      <material name="">
        <color rgba="1 0.8 0.8 1" />
      </material>
    </visual>
    <collision>
      <origin xyz="0 0 -0.2" rpy="0 0 0" />
      <geometry>
        <box size="0.06 0.03 0.1"/>
      </geometry>
    </collision>
  </link>
  <joint name="RL_calf_joint" type="revolute">
    <origin xyz="0 0.1145 -0.3" rpy="0 0 0" />
    <parent link="RL_thigh" />
    <child link="RL_calf" />
    <axis xyz="0 1 0" />
    <limit lower="-2.7" upper="-0.17" effort="135" velocity="12.56" />
  </joint>

  <link name="RL_foot">
    <inertial>
      <origin xyz="0 0.0559 0" rpy="0 0 0" />
      <mass value="2.6" />
      <inertia ixx="0.003934" ixy="0.0" ixz="0.000004" iyy="0.007113" iyz="0.000004" izz="0.00395" />
    </inertial>
    <visual>
      <origin xyz="0 0 0" rpy="0 0 0" />
      <geometry>
        <mesh filename="package://l4w4_description/meshes/wheel_R.STL" scale = "1 -1 1"/>
      </geometry>
      <material name="">
        <color rgba="0.25 0.25 0.25 1" />
      </material>
    </visual>
    <collision>
      <origin xyz="0 0.0559 0" rpy="1.570796327 0 0" />
      <geometry>
        <cylinder length="0.040" radius="0.105"/>
      </geometry>
    </collision>
  </link>
  <joint name="RL_foot_joint" type="revolute">
    <origin xyz="0 0 -0.3" rpy="0 0 0" />
    <parent link="RL_calf" />
    <child link="RL_foot" />
    <axis xyz="0 1 0" />
    <limit lower="-1000000" upper="1000000" effort="32" velocity="12.0" />
  </joint>

  <transmission name="RR_hip_tran">
    <type>transmission_interface/SimpleTransmission</type>
    <joint name="RR_hip_joint">
      <hardwareInterface>hardware_interface/EffortJointInterface</hardwareInterface>
    </joint>
    <actuator name="RR_hip_motor">
      <hardwareInterface>hardware_interface/EffortJointInterface</hardwareInterface>
      <mechanicalReduction>1</mechanicalReduction>
    </actuator>
  </transmission>
  <transmission name="RR_thigh_tran">
    <type>transmission_interface/SimpleTransmission</type>
    <joint name="RR_thigh_joint">
      <hardwareInterface>hardware_interface/EffortJointInterface</hardwareInterface>
    </joint>
    <actuator name="RR_thigh_motor">
      <hardwareInterface>hardware_interface/EffortJointInterface</hardwareInterface>
      <mechanicalReduction>1</mechanicalReduction>
    </actuator>
  </transmission>
  <transmission name="RR_calf_tran">
    <type>transmission_interface/SimpleTransmission</type>
    <joint name="RR_calf_joint">
      <hardwareInterface>hardware_interface/EffortJointInterface</hardwareInterface>
    </joint>
    <actuator name="RR_calf_motor">
      <hardwareInterface>hardware_interface/EffortJointInterface</hardwareInterface>
      <mechanicalReduction>1</mechanicalReduction>
    </actuator>
  </transmission>
  <transmission name="RR_foot_tran">
    <type>transmission_interface/SimpleTransmission</type>
    <joint name="RR_foot_joint">
      <hardwareInterface>hardware_interface/EffortJointInterface</hardwareInterface>
    </joint>
    <actuator name="RR_foot_motor">
      <hardwareInterface>hardware_interface/EffortJointInterface</hardwareInterface>
      <mechanicalReduction>1</mechanicalReduction>
    </actuator>
  </transmission>

  <link name="imu_link">
    <inertial>
      <origin xyz="0 0 0" rpy="0 0 0" />
      <mass value="0" />
      <inertia ixx="0" ixy="0" ixz="0" iyy="0" iyz="0" izz="0" />
    </inertial>
  </link>
  <joint name="imu_joint" type="fixed">
    <origin xyz="0 0 0" rpy="0 0 0" />
    <parent link="trunk" />
    <child link="imu_link" />
  </joint>

</robot>
