<?xml version="1.0" encoding="utf-8"?>
<!-- This URDF was automatically created by SolidWorks to URDF Exporter! Originally created by Stephen Brawner (brawner@gmail.com) 
     Commit Version: 1.6.0-4-g7f85cfe  Build Version: 1.6.7995.38578
     For more information, please see http://wiki.ros.org/sw_urdf_exporter -->
<robot name="Lite3">
    <!-- <mujoco>
        <compiler meshdir="package://lite3_description/meshes/" balanceinertia="false" discardvisual="false"/>
    </mujoco> -->
    <link name="TORSO">
        <inertial>
            <origin xyz="0 0 0" rpy="0 0 0"/>
            <mass value="5.6056"/>
            <inertia ixx="0.02456" ixy="0" ixz="0" iyy="0.05518" iyz="0" izz="0.07016"/>
        </inertial>
        <visual>
            <origin xyz="0 0 0" rpy="0 0 0"/>
            <geometry>
                <mesh filename="package://lite3_description/meshes/torso.STL"/>
            </geometry>
            <material name="">
                <color rgba="1 1 1 1"/>
            </material>
        </visual>
        <collision>
            <origin xyz="0 0 0.01" rpy="0 0 0"/>
            <geometry>
                <box size="0.5 0.1 0.12"/>
            </geometry>
        </collision>
        <collision>
            <origin xyz="0 0 0.01" rpy="0 0 0"/>
            <geometry>
                <box size="0.25 0.2 0.12"/>
            </geometry>
        </collision>
    </link>

    <!--!!!!!!!!!!!! Front Left Leg !!!!!!!!!!!!!!!!!!!!!!!!!!!!!!!!!!!!-->

    <link name="FL_HIP">
        <inertial>
            <origin xyz="-0.00601 -0.0066532 0.00034295" rpy="0 0 0"/>
            <mass value="0.550"/>
            <inertia ixx="0.0003949" ixy="0" ixz="0" iyy="0.0004028" iyz="0" izz="0.0004472"/>
        </inertial>
        <visual>
            <origin xyz="0 0 0" rpy="0 0 0"/>
            <geometry>
                <mesh filename="package://lite3_description/meshes/fl_hip.STL"/>
            </geometry>
            <material name="">
                <color rgba="1 1 1 1"/>
            </material>
        </visual>
        <collision>
            <origin xyz="0 0.05 0" rpy="1.57079632 0 0"/>
            <geometry>
                <cylinder length="0.15" radius="0.04"/>
            </geometry>
        </collision>
    </link>
    <joint name="FL_HipX_joint" type="revolute">
        <origin xyz="0.1745 0.062 0" rpy="0 0 0"/>
        <parent link="TORSO"/>
        <child link="FL_HIP"/>
        <axis xyz="-1 0 0"/>
        <limit lower="-0.523" upper="0.523" effort="24" velocity="26.2"/>
    </joint>
    <link name="FL_THIGH">
        <inertial>
            <origin xyz="-0.0052817 -0.014632 -0.042672" rpy="0 0 0"/>
            <mass value="0.86"/>
            <inertia ixx="0.005736" ixy="0" ixz="0" iyy="0.004960" iyz="0" izz="0.001436"/>
        </inertial>
        <visual>
            <origin xyz="0 0 0" rpy="0 0 0"/>
            <geometry>
                <mesh filename="package://lite3_description/meshes/fl_thigh.STL"/>
            </geometry>
            <material name="">
                <color rgba="1 1 1 1"/>
            </material>
        </visual>
        <collision>
            <origin xyz="-0.015 0 -0.08" rpy="0 0. 0"/>
            <geometry>
                <box size="0.04 0.045 0.2"/>
            </geometry>
        </collision>
    </link>
    <joint name="FL_HipY_joint" type="revolute">
        <origin xyz="0 0.09735 0" rpy="0 0 0"/>
        <parent link="FL_HIP"/>
        <child link="FL_THIGH"/>
        <axis xyz="0 -1 0"/>
        <limit lower="-2.67" upper="0.314" effort="24" velocity="26.2"/>
    </joint>
    <link name="FL_SHANK">
        <inertial>
            <origin xyz="0.0064794 -1.4535E-06 -0.12157" rpy="0 0 0"/>
            <mass value="0.153"/>
            <inertia ixx="0.00089039" ixy="0" ixz="0" iyy="0.00090672" iyz="0" izz="3.1266E-05"/>
        </inertial>
        <visual>
            <origin xyz="0 0 0" rpy="0 0 0"/>
            <geometry>
                <mesh filename="package://lite3_description/meshes/fl_shank_collision.STL"/>
            </geometry>
            <material name="">
                <color rgba="1 1 1 1"/>
            </material>
        </visual>
        <collision>
            <origin xyz="0.005 0 -0.03" rpy="0 -0.2 0"/>
            <geometry>
                <cylinder length="0.12" radius="0.015"/>
            </geometry>
        </collision>
        <collision>
            <origin xyz="0.01 0 -0.14" rpy="0 0.15 0"/>
            <geometry>
                <cylinder length="0.10" radius="0.015"/>
            </geometry>
        </collision>
    </link>
    <joint name="FL_Knee_joint" type="revolute">
        <origin xyz="0 0 -0.20" rpy="0 0 0"/>
        <parent link="FL_THIGH"/>
        <child link="FL_SHANK"/>
        <axis xyz="0 -1 0"/>
        <limit lower="0.524" upper="2.792" effort="36" velocity="17.3"/>
    </joint>

    <link name="FL_FOOT">
        <contact>
            <friction_anchor/>
            <stiffness value="30000.0"/>
            <damping value="1000.0"/>
            <spinning_friction value="0.3"/>
            <lateral_friction value="1.0"/>
        </contact>
        <collision>
            <origin rpy="1.57079632679 0 0" xyz="0 0 0"/>
            <geometry>
                <sphere radius="0.022"/>
            </geometry>
        </collision>
        <visual>
            <origin xyz="0 0 0" rpy="0 0 0"/>
            <geometry>
                <sphere radius="0.022"/>
            </geometry>
            <material name="">
                <color rgba="1 1 1 1"/>
            </material>
        </visual>
        <inertial>
            <mass value="0.02"/>
            <inertia ixx="0" ixy="0" ixz="0" iyy="0" iyz="0" izz="0"/>
        </inertial>
    </link>

    <joint name="FL_Ankle" type="fixed" dont_collapse="true">
        <parent link="FL_SHANK"/>
        <child link="FL_FOOT"/>
        <origin xyz="0 0 -0.21012"/>

    </joint>

    <!--!!!!!!!!!!!! Front Right Leg !!!!!!!!!!!!!!!!!!!!!!!!!!!!!!!!!!!!-->
    <link name="FR_HIP">
        <inertial>
            <origin xyz="-0.010579 0.011358 0.00048546" rpy="0 0 0"/>
            <mass value="0.550"/>
            <inertia ixx="0.0004472" ixy="0" ixz="0" iyy="0.0004028" iyz="0" izz="0.0003949"/>
        </inertial>
        <visual>
            <origin xyz="0 0 0" rpy="0 0 0"/>
            <geometry>
                <mesh filename="package://lite3_description/meshes/fr_hip.STL"/>
            </geometry>
            <material name="">
                <color rgba="1 1 1 1"/>
            </material>
        </visual>
        <collision>
            <origin xyz="0 -0.05 0" rpy="1.57079632 0 0"/>
            <geometry>
                <cylinder length="0.15" radius="0.04"/>
            </geometry>
        </collision>
    </link>
    <joint name="FR_HipX_joint"
           type="revolute">
        <origin xyz="0.1745 -0.062 0" rpy="0 0 0"/>
        <parent link="TORSO"/>
        <child link="FR_HIP"/>
        <axis xyz="-1 0 0"/>
        <limit lower="-0.523" upper="0.523" effort="24" velocity="26.2"/>
    </joint>
    <link name="FR_THIGH">
        <inertial>
            <origin xyz="-0.0039245 0.025256 -0.025146" rpy="0 0 0"/>
            <mass value="0.86"/>
            <!-- inertia ixx="0.00433" ixy="0.00001" ixz="0.00034" iyy="0.00403"  iyz="-0.0000186" izz="0.00143" -->
            <inertia ixx="0.005736" ixy="0" ixz="0" iyy="0.004960" iyz="0" izz="0.001436"/>
        </inertial>
        <visual>
            <origin xyz="0 0 0" rpy="0 0 0"/>
            <geometry>
                <mesh filename="package://lite3_description/meshes/fr_thigh.STL"/>
            </geometry>
            <material name="">
                <color rgba="1 1 1 1"/>
            </material>
        </visual>
        <collision>
            <origin xyz="-0.015 0 -0.08" rpy="0 0. 0"/>
            <geometry>
                <box size="0.04 0.045 0.2"/>
            </geometry>
        </collision>
    </link>
    <joint name="FR_HipY_joint" type="revolute">
        <origin xyz="0 -0.09735 0" rpy="0 0 0"/>
        <parent link="FR_HIP"/>
        <child link="FR_THIGH"/>
        <axis xyz="0 -1 0"/>
        <limit lower="-2.67" upper="0.314" effort="24" velocity="26.2"/>
    </joint>
    <link name="FR_SHANK">
        <inertial>
            <origin xyz="0.0064794 -1.4552E-06 -0.12157" rpy="0 0 0"/>
            <mass value="0.153"/>
            <inertia ixx="0.00089039" ixy="0" ixz="0" iyy="0.00090672" iyz="0" izz="3.1266E-05"/>
        </inertial>
        <visual>
            <origin xyz="0 0 0" rpy="0 0 0"/>
            <geometry>
                <mesh filename="package://lite3_description/meshes/fr_shank_collision.STL"/>
            </geometry>
            <material name="">
                <color rgba="1 1 1 1"/>
            </material>
        </visual>
        <collision>
            <origin xyz="0.005 0 -0.03" rpy="0 -0.2 0"/>
            <geometry>
                <cylinder length="0.12" radius="0.015"/>
            </geometry>
        </collision>
        <collision>
            <origin xyz="0.01 0 -0.14" rpy="0 0.15 0"/>
            <geometry>
                <cylinder length="0.10" radius="0.015"/>
            </geometry>
        </collision>
    </link>
    <joint name="FR_Knee_joint" type="revolute">
        <origin xyz="0 0 -0.20" rpy="0 0 0"/>
        <parent link="FR_THIGH"/>
        <child link="FR_SHANK"/>
        <axis xyz="0 -1 0"/>
        <limit lower="0.524" upper="2.792" effort="36" velocity="17.3"/>
    </joint>

    <link name="FR_FOOT">
        <contact>
            <friction_anchor/>
            <stiffness value="30000.0"/>
            <damping value="1000.0"/>
            <spinning_friction value="0.3"/>
            <lateral_friction value="1.0"/>
        </contact>
        <collision>
            <origin rpy="1.57079632679 0 0" xyz="0 0 0"/>
            <geometry>
                <sphere radius="0.022"/>
            </geometry>
        </collision>
        <visual>
            <origin xyz="0 0 0" rpy="0 0 0"/>
            <geometry>
                <sphere radius="0.022"/>
            </geometry>
            <material name="">
                <color rgba="1 1 1 1"/>
            </material>
        </visual>
        <inertial>
            <mass value="0.02"/>
            <inertia ixx="0" ixy="0" ixz="0" iyy="0" iyz="0" izz="0"/>
        </inertial>
    </link>

    <joint name="FR_Ankle" type="fixed" dont_collapse="true">
        <parent link="FR_SHANK"/>
        <child link="FR_FOOT"/>
        <origin xyz="0 0 -0.21012"/>

    </joint>

    <!--!!!!!!!!!!!! Back Left Leg !!!!!!!!!!!!!!!!!!!!!!!!!!!!!!!!!!!!-->
    <link name="HL_HIP">
        <inertial>
            <origin xyz="0.010905 -0.012636 0.001051" rpy="0 0 0"/>
            <mass value="0.550"/>
            <inertia ixx="0.0003949" ixy="0" ixz="0" iyy="0.0004028" iyz="0" izz="0.0004472"/>
        </inertial>
        <visual>
            <origin xyz="0 0 0" rpy="0 0 0"/>
            <geometry>
                <mesh filename="package://lite3_description/meshes/hl_hip.STL"/>
            </geometry>
            <material name="">
                <color rgba="1 1 1 1"/>
            </material>
        </visual>
        <collision>
            <origin xyz="0 0.05 0" rpy="1.57079632 0 0"/>
            <geometry>
                <cylinder length="0.15" radius="0.04"/>
            </geometry>
        </collision>
    </link>
    <joint name="HL_HipX_joint" type="revolute">
        <origin xyz="-0.1745 0.062 0" rpy="0 0 0"/>
        <parent link="TORSO"/>
        <child link="HL_HIP"/>
        <axis xyz="-1 0 0"/>
        <limit lower="-0.523" upper="0.523" effort="24" velocity="26.2"/>
    </joint>
    <link name="HL_THIGH">
        <inertial>
            <origin xyz="-0.0057137 -0.014631 -0.042453" rpy="0 0 0"/>
            <mass value="0.86"/>
            <inertia ixx="0.005736" ixy="0" ixz="0" iyy="0.004960" iyz="0" izz="0.001436"/>
        </inertial>
        <visual>
            <origin xyz="0 0 0" rpy="0 0 0"/>
            <geometry>
                <mesh filename="package://lite3_description/meshes/hl_thigh.STL"/>
            </geometry>
            <material name="">
                <color rgba="1 1 1 1"/>
            </material>
        </visual>
        <collision>
            <origin xyz="-0.015 0 -0.08" rpy="0 0. 0"/>
            <geometry>
                <box size="0.04 0.045 0.2"/>
            </geometry>
        </collision>
    </link>
    <joint name="HL_HipY_joint" type="revolute">
        <origin xyz="0 0.09735 0" rpy="0 0 0"/>
        <parent link="HL_HIP"/>
        <child link="HL_THIGH"/>
        <axis xyz="0 -1 0"/>
        <limit lower="-2.67" upper="0.314" effort="24" velocity="26.2"/>
    </joint>
    <link name="HL_SHANK">
        <inertial>
            <origin xyz="0.0064794 -1.4558E-06 -0.12157" rpy="0 0 0"/>
            <mass value="0.153"/>
            <inertia ixx="0.00089039" ixy="0" ixz="0" iyy="0.00090672" iyz="0" izz="3.1266E-05"/>
        </inertial>
        <visual>
            <origin xyz="0 0 0" rpy="0 0 0"/>
            <geometry>
                <mesh filename="package://lite3_description/meshes/hl_shank_collision.STL"/>
            </geometry>
            <material name="">
                <color rgba="1 1 1 1"/>
            </material>
        </visual>
        <collision>
            <origin xyz="0.005 0 -0.03" rpy="0 -0.2 0"/>
            <geometry>
                <cylinder length="0.12" radius="0.015"/>
            </geometry>
        </collision>
        <collision>
            <origin xyz="0.01 0 -0.14" rpy="0 0.15 0"/>
            <geometry>
                <cylinder length="0.10" radius="0.015"/>
            </geometry>
        </collision>
    </link>
    <joint name="HL_Knee_joint" type="revolute">
        <origin xyz="0 0 -0.20" rpy="0 0 0"/>
        <parent link="HL_THIGH"/>
        <child link="HL_SHANK"/>
        <axis xyz="0 -1 0"/>
        <limit lower="0.524" upper="2.792" effort="36" velocity="17.3"/>
    </joint>

    <link name="HL_FOOT">
        <contact>
            <friction_anchor/>
            <stiffness value="30000.0"/>
            <damping value="1000.0"/>
            <spinning_friction value="0.3"/>
            <lateral_friction value="1.0"/>
        </contact>
        <collision>
            <origin rpy="1.57079632679 0 0" xyz="0 0 0"/>
            <geometry>
                <sphere radius="0.022"/>
            </geometry>
        </collision>
        <visual>
            <origin xyz="0 0 0" rpy="0 0 0"/>
            <geometry>
                <sphere radius="0.022"/>
            </geometry>
            <material name="">
                <color rgba="1 1 1 1"/>
            </material>
        </visual>
        <inertial>
            <mass value="0.02"/>
            <inertia ixx="0" ixy="0" ixz="0" iyy="0" iyz="0" izz="0"/>
        </inertial>
    </link>

    <joint name="HL_Ankle" type="fixed" dont_collapse="true">
        <parent link="HL_SHANK"/>
        <child link="HL_FOOT"/>
        <origin xyz="0 0 -0.21012"/>

    </joint>
    <!--!!!!!!!!!!!! Back Right Leg !!!!!!!!!!!!!!!!!!!!!!!!!!!!!!!!!!!!-->

    <link name="HR_HIP">
        <inertial>
            <origin xyz="0.010354 0.011423 0.00049498" rpy="0 0 0"/>
            <mass value="0.550"/>
            <inertia ixx="0.0004472" ixy="0" ixz="0" iyy="0.0004028" iyz="0" izz="0.0003949"/>
        </inertial>
        <visual>
            <origin xyz="0 0 0" rpy="0 0 0"/>
            <geometry>
                <mesh filename="package://lite3_description/meshes/hr_hip.STL"/>
            </geometry>
            <material name="">
                <color rgba="1 1 1 1"/>
            </material>
        </visual>
        <collision>
            <origin xyz="0 -0.05 0" rpy="1.57079632 0 0"/>
            <geometry>
                <cylinder length="0.15" radius="0.04"/>
            </geometry>
        </collision>
    </link>
    <joint name="HR_HipX_joint" type="revolute">
        <origin xyz="-0.1745 -0.062 0" rpy="0 0 0"/>
        <parent link="TORSO"/>
        <child link="HR_HIP"/>
        <axis xyz="-1 0 0"/>
        <limit lower="-0.523" upper="0.523" effort="24" velocity="26.2"/>
    </joint>
    <link name="HR_THIGH">
        <inertial>
            <origin xyz="-0.0031903 0.02526 -0.025617" rpy="0 0 0"/>
            <mass value="0.86"/>
            <inertia ixx="0.005736" ixy="0" ixz="0" iyy="0.004960" iyz="0" izz="0.001436"/>
        </inertial>
        <visual>
            <origin xyz="0 0 0" rpy="0 0 0"/>
            <geometry>
                <mesh filename="package://lite3_description/meshes/hr_thigh.STL"/>
            </geometry>
            <material name="">
                <color rgba="1 1 1 1"/>
            </material>
        </visual>
        <collision>
            <origin xyz="-0.015 0 -0.08" rpy="0 0. 0"/>
            <geometry>
                <box size="0.04 0.045 0.2"/>
            </geometry>
        </collision>
    </link>
    <joint name="HR_HipY_joint" type="revolute">
        <origin xyz="0 -0.09735 0" rpy="0 0 0"/>
        <parent link="HR_HIP"/>
        <child link="HR_THIGH"/>
        <axis xyz="0 -1 0"/>
        <limit lower="-2.67" upper="0.314" effort="24" velocity="26.2"/>
    </joint>
    <link name="HR_SHANK">
        <inertial>
            <origin xyz="0.0064794 -1.4529E-06 -0.12157" rpy="0 0 0"/>
            <mass value="0.153"/>
            <inertia ixx="0.00089039" ixy="0" ixz="0" iyy="0.00090672" iyz="0" izz="3.1266E-05"/>
        </inertial>
        <visual>
            <origin xyz="0 0 0" rpy="0 0 0"/>
            <geometry>
                <mesh filename="package://lite3_description/meshes/hr_shank_collision.STL"/>
            </geometry>
            <material name="">
                <color rgba="1 1 1 1"/>
            </material>
        </visual>
        <collision>
            <origin xyz="0.005 0 -0.03" rpy="0 -0.2 0"/>
            <geometry>
                <cylinder length="0.12" radius="0.015"/>
            </geometry>
        </collision>
        <collision>
            <origin xyz="0.01 0 -0.14" rpy="0 0.15 0"/>
            <geometry>
                <cylinder length="0.10" radius="0.015"/>
            </geometry>
        </collision>
    </link>
    <joint name="HR_Knee_joint" type="revolute">
        <origin xyz="0 0 -0.20" rpy="0 0 0"/>
        <parent link="HR_THIGH"/>
        <child link="HR_SHANK"/>
        <axis xyz="0 -1 0"/>
        <limit lower="0.524" upper="2.792" effort="36" velocity="17.3"/>
    </joint>

    <link name="HR_FOOT">
        <contact>
            <friction_anchor/>
            <stiffness value="30000.0"/>
            <damping value="1000.0"/>
            <spinning_friction value="0.3"/>
            <lateral_friction value="1.0"/>
        </contact>
        <collision>
            <origin rpy="1.57079632679 0 0" xyz="0 0 0"/>
            <geometry>
                <sphere radius="0.022"/>
            </geometry>
        </collision>
        <visual>
            <origin xyz="0 0 0" rpy="0 0 0"/>
            <geometry>
                <sphere radius="0.022"/>
            </geometry>
            <material name="">
                <color rgba="1 1 1 1"/>
            </material>
        </visual>
        <inertial>
            <mass value="0.02"/>
            <inertia ixx="0" ixy="0" ixz="0" iyy="0" iyz="0" izz="0"/>
        </inertial>
    </link>

    <joint name="HR_Ankle" type="fixed" dont_collapse="true">
        <parent link="HR_SHANK"/>
        <child link="HR_FOOT"/>
        <origin xyz="0 0 -0.21012"/>

    </joint>

    <link name="imu_link">
      <inertial>
        <origin xyz="0 0 0" rpy="0 0 0" />
        <mass value="0" />
        <inertia ixx="0" ixy="0" ixz="0" iyy="0" iyz="0" izz="0" />
      </inertial>
    </link>
    <joint name="imu_joint" type="fixed">
      <origin xyz="-0.02557 0 0.04232" rpy="0 0 0" />
      <parent link="TORSO" />
      <child link="imu_link" />
      <axis xyz="0 0 0" />
    </joint>


  <transmission name="FL_HipX_tran">
    <type>transmission_interface/SimpleTransmission</type>
    <joint name="FL_HipX_joint">
      <hardwareInterface>hardware_interface/EffortJointInterface</hardwareInterface>
    </joint>
    <actuator name="FL_HipX_motor">
      <hardwareInterface>hardware_interface/EffortJointInterface</hardwareInterface>
      <mechanicalReduction>1</mechanicalReduction>
    </actuator>
  </transmission>
  <transmission name="FL_HipY_tran">
    <type>transmission_interface/SimpleTransmission</type>
    <joint name="FL_HipY_joint">
      <hardwareInterface>hardware_interface/EffortJointInterface</hardwareInterface>
    </joint>
    <actuator name="FL_HipY_motor">
      <hardwareInterface>hardware_interface/EffortJointInterface</hardwareInterface>
      <mechanicalReduction>1</mechanicalReduction>
    </actuator>
  </transmission>
  <transmission name="FL_Knee_tran">
    <type>transmission_interface/SimpleTransmission</type>
    <joint name="FL_Knee_joint">
      <hardwareInterface>hardware_interface/EffortJointInterface</hardwareInterface>
    </joint>
    <actuator name="FL_Knee_motor">
      <hardwareInterface>hardware_interface/EffortJointInterface</hardwareInterface>
      <mechanicalReduction>1</mechanicalReduction>
    </actuator>
  </transmission>

  <transmission name="FR_HipX_tran">
    <type>transmission_interface/SimpleTransmission</type>
    <joint name="FR_HipX_joint">
      <hardwareInterface>hardware_interface/EffortJointInterface</hardwareInterface>
    </joint>
    <actuator name="FR_HipX_motor">
      <hardwareInterface>hardware_interface/EffortJointInterface</hardwareInterface>
      <mechanicalReduction>1</mechanicalReduction>
    </actuator>
  </transmission>
  <transmission name="FR_HipY_tran">
    <type>transmission_interface/SimpleTransmission</type>
    <joint name="FR_HipY_joint">
      <hardwareInterface>hardware_interface/EffortJointInterface</hardwareInterface>
    </joint>
    <actuator name="FR_HipY_motor">
      <hardwareInterface>hardware_interface/EffortJointInterface</hardwareInterface>
      <mechanicalReduction>1</mechanicalReduction>
    </actuator>
  </transmission>
  <transmission name="FR_Knee_tran">
    <type>transmission_interface/SimpleTransmission</type>
    <joint name="FR_Knee_joint">
      <hardwareInterface>hardware_interface/EffortJointInterface</hardwareInterface>
    </joint>
    <actuator name="FR_Knee_motor">
      <hardwareInterface>hardware_interface/EffortJointInterface</hardwareInterface>
      <mechanicalReduction>1</mechanicalReduction>
    </actuator>
  </transmission>

  <transmission name="HL_HipX_tran">
    <type>transmission_interface/SimpleTransmission</type>
    <joint name="HL_HipX_joint">
      <hardwareInterface>hardware_interface/EffortJointInterface</hardwareInterface>
    </joint>
    <actuator name="HL_HipX_motor">
      <hardwareInterface>hardware_interface/EffortJointInterface</hardwareInterface>
      <mechanicalReduction>1</mechanicalReduction>
    </actuator>
  </transmission>
  <transmission name="HL_HipY_tran">
    <type>transmission_interface/SimpleTransmission</type>
    <joint name="HL_HipY_joint">
      <hardwareInterface>hardware_interface/EffortJointInterface</hardwareInterface>
    </joint>
    <actuator name="HL_HipY_motor">
      <hardwareInterface>hardware_interface/EffortJointInterface</hardwareInterface>
      <mechanicalReduction>1</mechanicalReduction>
    </actuator>
  </transmission>
  <transmission name="HL_Knee_tran">
    <type>transmission_interface/SimpleTransmission</type>
    <joint name="HL_Knee_joint">
      <hardwareInterface>hardware_interface/EffortJointInterface</hardwareInterface>
    </joint>
    <actuator name="HL_Knee_motor">
      <hardwareInterface>hardware_interface/EffortJointInterface</hardwareInterface>
      <mechanicalReduction>1</mechanicalReduction>
    </actuator>
  </transmission>

  <transmission name="HR_HipX_tran">
    <type>transmission_interface/SimpleTransmission</type>
    <joint name="HR_HipX_joint">
      <hardwareInterface>hardware_interface/EffortJointInterface</hardwareInterface>
    </joint>
    <actuator name="HR_HipX_motor">
      <hardwareInterface>hardware_interface/EffortJointInterface</hardwareInterface>
      <mechanicalReduction>1</mechanicalReduction>
    </actuator>
  </transmission>
  <transmission name="HR_HipY_tran">
    <type>transmission_interface/SimpleTransmission</type>
    <joint name="HR_HipY_joint">
      <hardwareInterface>hardware_interface/EffortJointInterface</hardwareInterface>
    </joint>
    <actuator name="HR_HipY_motor">
      <hardwareInterface>hardware_interface/EffortJointInterface</hardwareInterface>
      <mechanicalReduction>1</mechanicalReduction>
    </actuator>
  </transmission>
  <transmission name="HR_Knee_tran">
    <type>transmission_interface/SimpleTransmission</type>
    <joint name="HR_Knee_joint">
      <hardwareInterface>hardware_interface/EffortJointInterface</hardwareInterface>
    </joint>
    <actuator name="HR_Knee_motor">
      <hardwareInterface>hardware_interface/EffortJointInterface</hardwareInterface>
      <mechanicalReduction>1</mechanicalReduction>
    </actuator>
  </transmission>

</robot>