<?xml version="1.0" encoding="utf-8"?>
<!-- This URDF was automatically created by SolidWorks to URDF Exporter! Originally created by Stephen Brawner (brawner@gmail.com) 
     Commit Version: 1.6.0-4-g7f85cfe  Build Version: 1.6.7995.38578
     For more information, please see http://wiki.ros.org/sw_urdf_exporter -->
<robot
  name="OpenLoog">
     
  <!-- <mujoco>
    <compiler 
    meshdir="" 
    balanceinertia="true" 
    discardvisual="false" />
  </mujoco> -->

  <!-- ros_control plugin -->
  <gazebo>
    <plugin filename="libgazebo_ros_control.so" name="gazebo_ros_control">
      <robotNamespace>/openloong_gazebo</robotNamespace>
      <robotSimType>gazebo_ros_control/DefaultRobotHWSim</robotSimType>
    </plugin>
  </gazebo>

    <gazebo>
    <plugin filename="libgazebo_ros_force.so" name="gazebo_ros_force">
      <bodyName>base_link</bodyName>
      <topicName>/apply_force/base_link</topicName>
    </plugin>
  </gazebo>

  <gazebo reference="imu_link">
    <gravity>true</gravity>
    <sensor name="imu_sensor" type="imu">
      <always_on>true</always_on>
      <update_rate>1000</update_rate>
      <visualize>true</visualize>
      <topic>__default_topic__</topic>
      <plugin filename="libgazebo_ros_imu_sensor.so" name="imu_plugin">
        <topicName>base_link_imu</topicName>
        <bodyName>imu_link</bodyName>
        <updateRateHZ>1000.0</updateRateHZ>
        <gaussianNoise>0.0</gaussianNoise>
        <xyzOffset>0 0 0</xyzOffset>
        <rpyOffset>0 0 0</rpyOffset>
        <frameName>imu_link</frameName>
      </plugin>
      <pose>0 0 0 0 0 0</pose>
    </sensor>
  </gazebo>

  <gazebo reference="base">
    <material>Gazebo/DarkGrey</material>
    <turnGravityOff>false</turnGravityOff>
  </gazebo>
  <gazebo reference="base_link">
    <mu1>0.2</mu1>
    <mu2>0.2</mu2>
    <kp value="1000000.0"/>
    <kd value="1.0"/>
  </gazebo>
  <gazebo reference="imu_link">
    <mu1>0.2</mu1>
    <mu2>0.2</mu2>
    <material>Gazebo/Red</material>
  </gazebo>
  <!-- left leg -->
  <gazebo reference="Link_hip_l_roll">
    <mu1>0.2</mu1>
    <mu2>0.2</mu2>
    <self_collide>1</self_collide>
    <material>Gazebo/DarkGrey</material>
  </gazebo>
  <gazebo reference="Link_hip_l_yaw">
    <mu1>0.2</mu1>
    <mu2>0.2</mu2>
    <self_collide>1</self_collide>
    <material>Gazebo/DarkGrey</material>
  </gazebo>
  <gazebo reference="Link_hip_l_pitch">
    <mu1>0.2</mu1>
    <mu2>0.2</mu2>
    <self_collide>1</self_collide>
    <material>Gazebo/DarkGrey</material>
  </gazebo>
  <gazebo reference="Link_knee_l_pitch">
    <mu1>0.2</mu1>
    <mu2>0.2</mu2>
    <self_collide>1</self_collide>
    <material>Gazebo/DarkGrey</material>
  </gazebo>
  <gazebo reference="Link_l_ankle_pitch">
    <mu1>1.0</mu1>
    <mu2>1.0</mu2>
    <self_collide>1</self_collide>
    <kp value="1000000.0"/>
    <kd value="1.0"/>
    <material>Gazebo/DarkGrey</material>
  </gazebo>
  <gazebo reference="Link_l_ankle_roll">
    <mu1>1.0</mu1>
    <mu2>1.0</mu2>
    <self_collide>1</self_collide>
    <kp value="1000000.0"/>
    <kd value="1.0"/>
    <material>Gazebo/DarkGrey</material>
  </gazebo>

  <!-- right leg -->
  <gazebo reference="Link_hip_r_roll">
    <mu1>0.2</mu1>
    <mu2>0.2</mu2>
    <self_collide>1</self_collide>
    <material>Gazebo/DarkGrey</material>
  </gazebo>
  <gazebo reference="Link_hip_r_yaw">
    <mu1>0.2</mu1>
    <mu2>0.2</mu2>
    <self_collide>1</self_collide>
    <material>Gazebo/DarkGrey</material>
  </gazebo>
  <gazebo reference="Link_hip_r_pitch">
    <mu1>0.2</mu1>
    <mu2>0.2</mu2>
    <self_collide>1</self_collide>
    <material>Gazebo/DarkGrey</material>
  </gazebo>
  <gazebo reference="Link_knee_r_pitch">
    <mu1>0.2</mu1>
    <mu2>0.2</mu2>
    <self_collide>1</self_collide>
    <material>Gazebo/DarkGrey</material>
  </gazebo>
  <gazebo reference="Link_r_ankle_pitch">
    <mu1>1.0</mu1>
    <mu2>1.0</mu2>
    <self_collide>1</self_collide>
    <kp value="1000000.0"/>
    <kd value="1.0"/>
    <material>Gazebo/DarkGrey</material>
  </gazebo>
  <gazebo reference="Link_r_ankle_roll">
    <mu1>1.0</mu1>
    <mu2>1.0</mu2>
    <self_collide>1</self_collide>
    <kp value="1000000.0"/>
    <kd value="1.0"/>
    <material>Gazebo/DarkGrey</material>
  </gazebo>

  <material name="black">
    <color rgba="0.0 0.0 0.0 1.0"/>
  </material>
  <material name="blue">
    <color rgba="0.0 0.0 0.8 1.0"/>
  </material>
  <material name="green">
    <color rgba="0.0 0.8 0.0 1.0"/>
  </material>
  <material name="grey">
    <color rgba="0.2 0.2 0.2 1.0"/>
  </material>
  <material name="silver">
    <color rgba="0.913725490196 0.913725490196 0.847058823529 1.0"/>
  </material>
  <material name="orange">
    <color rgba="0.12 0.15 0.2 1.0"/>
  </material>
  <material name="brown">
    <color rgba="0.870588235294 0.811764705882 0.764705882353 1.0"/>
  </material>
  <material name="red">
    <color rgba="0.8 0.0 0.0 1.0"/>
  </material>
  <material name="white">
    <color rgba="1.0 1.0 1.0 1.0"/>
  </material>
  <!-- [CAUTION] uncomment when convert to mujoco
  <link name="world"></link>
  <joint name="floating_base_joint" type="floating">
    <parent link="world" />
    <child link="base_link" />
  </joint> -->

  <link name="base">
    <visual>
      <origin rpy="0 0 0" xyz="0 0 0"/>
      <geometry>
        <box size="0.001 0.001 0.001"/>
      </geometry>
    </visual>
  </link>
  <joint name="floating_base" type="fixed">
    <origin rpy="0 0 0" xyz="0 0 0"/>
    <parent link="base"/>
    <child link="base_link"/>
  </joint>

  <link
    name="base_link">
    <inertial>
      <origin
        xyz="-0.0056641 -0.0013367 0.23829"
        rpy="0 0 0" />
      <mass
        value="22.447" />
      <inertia
        ixx="0.3742"
        ixy="0.0009471"
        ixz="0.004646"
        iyy="0.27691"
        iyz="0.0040142"
        izz="0.22104" />
    </inertial>
    <visual>
      <origin
        xyz="0 0 0"
        rpy="0 0 0" />
      <geometry>
        <mesh
          filename="package://openloong_description/meshes/base_link.STL" />
      </geometry>
      <material
        name="">
        <color
          rgba="0.75294 0.75294 0.75294 1" />
      </material>
    </visual>
     <collision>
      <origin xyz="0 0 0.16" rpy="0 0 0" />
      <geometry>
        <box size="0.35 0.25 0.35"/>
      </geometry>
    </collision>
    <!-- <collision>
      <origin
        xyz="0 0 0"
        rpy="0 0 0" />
      <geometry>
        <mesh
          filename="package://openloong_description/meshes/base_link.STL" />
      </geometry>
    </collision> -->
  </link>
  <link
    name="Link_head_yaw">
    <inertial>
      <origin
        xyz="4.6974E-12 -0.0020814 0.044801"
        rpy="0 0 0" />
      <mass
        value="0.84249" />
      <inertia
        ixx="0.000629"
        ixy="1.2848E-14"
        ixz="-1.5461E-10"
        iyy="0.0007003"
        iyz="-6.5E-06"
        izz="0.0005541" />
    </inertial>
    <visual>
      <origin
        xyz="0 0 0"
        rpy="0 0 0" />
      <geometry>
        <mesh
          filename="package://openloong_description/meshes/Link_head_yaw.STL" />
      </geometry>
      <material
        name="">
        <color
          rgba="0.89804 0.91765 0.92941 1" />
      </material>
    </visual>
    <collision>
      <origin
        xyz="0 0 0"
        rpy="0 0 0" />
      <geometry>
        <mesh
          filename="package://openloong_description/meshes/Link_head_yaw.STL" />
      </geometry>
    </collision>
  </link>
  <joint
    name="J_head_yaw"
    type="fixed">
    <origin
      xyz="0.009 0 0.4064"
      rpy="0 0 0" />
    <parent
      link="base_link" />
    <child
      link="Link_head_yaw" />
    <axis
      xyz="0 0 1" />
    <limit
      lower="-1.5708"
      upper="1.5708"
      effort="26"
      velocity="109.8" />
  </joint>
  <link
    name="Link_head_pitch">
    <inertial>
      <origin
        xyz="0.020569 0.033004 0.125"
        rpy="0 0 0" />
      <mass
        value="1.3943" />
      <inertia
        ixx="0.0060059"
        ixy="9.4E-06"
        ixz="-0.0007564"
        iyy="0.00629"
        iyz="1.03E-05"
        izz="0.0048569" />
    </inertial>
    <visual>
      <origin
        xyz="0 0 0"
        rpy="0 0 0" />
      <geometry>
        <mesh
          filename="package://openloong_description/meshes/Link_head_pitch.STL" />
      </geometry>
      <material
        name="">
        <color
          rgba="0.69804 0.69804 0.69804 1" />
      </material>
    </visual>
    <collision>
      <origin
        xyz="0 0 0"
        rpy="0 0 0" />
      <geometry>
        <mesh
          filename="package://openloong_description/meshes/Link_head_pitch.STL" />
      </geometry>
    </collision>
  </link>
  <joint
    name="J_head_pitch"
    type="fixed">
    <origin
      xyz="0 -0.0345999999999997 0.0484999999999999"
      rpy="0 0 0" />
    <parent
      link="Link_head_yaw" />
    <child
      link="Link_head_pitch" />
    <axis
      xyz="0 -1 0" />
    <limit
      lower="-0.7854"
      upper="0.7854"
      effort="26"
      velocity="109.8" />
  </joint>
  <link
    name="Link_arm_r_01">
    <inertial>
      <origin
        xyz="0.0044946 -0.038294 -1.8744E-06"
        rpy="0 0 0" />
      <mass
        value="0.75641" />
      <inertia
        ixx="0.00058712"
        ixy="-2.9803E-07"
        ixz="-5.8378E-09"
        iyy="0.00080305"
        iyz="3.6648E-08"
        izz="0.00084299" />
    </inertial>
    <visual>
      <origin
        xyz="0 0 0"
        rpy="0 0 0" />
      <geometry>
        <mesh
          filename="package://openloong_description/meshes/Link_arm_r_01.STL" />
      </geometry>
      <material
        name="">
        <color
          rgba="0.69804 0.69804 0.69804 1" />
      </material>
    </visual>
    <collision>
      <origin
        xyz="0 0 0"
        rpy="0 0 0" />
      <geometry>
        <mesh
          filename="package://openloong_description/meshes/Link_arm_r_01.STL" />
      </geometry>
    </collision>
  </link>
  <joint
    name="r_arm_01"
    type="fixed">
    <origin
      xyz="0.004 -0.1616 0.3922"
      rpy="0 3.14 0" />
    <parent
      link="base_link" />
    <child
      link="Link_arm_r_01" />
    <axis
      xyz="0 -1 0" />
    <limit
      lower="-2.96706"
      upper="2.96706"
      effort="80"
      velocity="3.14" />
  </joint>
  <link
    name="Link_arm_r_02">
    <inertial>
      <origin
        xyz="0.042 -0.0674307499121858 -6.93889390390723E-18"
        rpy="0 0 0" />
      <mass
        value="0.984999996273518" />
      <inertia
        ixx="0.0017309882399251"
        ixy="9.79515256436727E-20"
        ixz="3.63988309726277E-19"
        iyy="0.00115401958000568"
        iyz="-4.42134220053852E-19"
        izz="0.00226269324370836" />
    </inertial>
    <visual>
      <origin
        xyz="0 0 0"
        rpy="0 0 0" />
      <geometry>
        <mesh
          filename="package://openloong_description/meshes/Link_arm_r_02.STL" />
      </geometry>
      <material
        name="">
        <color
          rgba="0.698039215686274 0.698039215686274 0.698039215686274 1" />
      </material>
    </visual>
    <collision>
      <origin
        xyz="0 0 0"
        rpy="0 0 0" />
      <geometry>
        <mesh
          filename="package://openloong_description/meshes/Link_arm_r_02.STL" />
      </geometry>
    </collision>
  </link>
  <joint
    name="r_arm_02"
    type="fixed">
    <origin
      xyz="-0.042 -0.041 0"
      rpy="-1.3 0 0" />
    <parent
      link="Link_arm_r_01" />
    <child
      link="Link_arm_r_02" />
    <axis
      xyz="-1 0 0" />
    <limit
      lower="-1.83260"
      upper="1.83260"
      effort="80"
      velocity="3.14" />
  </joint>
  <link
    name="Link_arm_r_03">
    <inertial>
      <origin
        xyz="-0.00141357502419955 -0.164662742175383 0.0207578924800774"
        rpy="0 0 0" />
      <mass
        value="0.958999855228924" />
      <inertia
        ixx="0.00206438134078715"
        ixy="-1.82014067823509E-05"
        ixz="5.1283136963991E-06"
        iyy="0.00080535412926664"
        iyz="0.000255265992194607"
        izz="0.00205099914609259" />
    </inertial>
    <visual>
      <origin
        xyz="0 0 0"
        rpy="0 0 0" />
      <geometry>
        <mesh
          filename="package://openloong_description/meshes/Link_arm_r_03.STL" />
      </geometry>
      <material
        name="">
        <color
          rgba="0.698039215686274 0.698039215686274 0.698039215686274 1" />
      </material>
    </visual>
    <collision>
      <origin
        xyz="0 0 0"
        rpy="0 0 0" />
      <geometry>
        <mesh
          filename="package://openloong_description/meshes/Link_arm_r_03.STL" />
      </geometry>
    </collision>
  </link>
  <joint
    name="r_arm_03"
    type="fixed">
    <origin
      xyz="0.042 -0.1226 0"
      rpy="0 0 0" />
    <parent
      link="Link_arm_r_02" />
    <child
      link="Link_arm_r_03" />
    <axis
      xyz="0 -1 0" />
    <limit
      lower="-2.96706"
      upper="2.96706"
      effort="48"
      velocity="3.14" />
  </joint>
  <link
    name="Link_arm_r_04">
    <inertial>
      <origin
        xyz="-0.038727 -0.060767 -0.021003"
        rpy="0 0 0" />
      <mass
        value="0.6" />
      <inertia
        ixx="0.00070398"
        ixy="2.023E-05"
        ixz="1.1263E-05"
        iyy="0.00068085"
        iyz="-0.00010585"
        izz="0.0010653" />
    </inertial>
    <visual>
      <origin
        xyz="0 0 0"
        rpy="0 0 0" />
      <geometry>
        <mesh
          filename="package://openloong_description/meshes/Link_arm_r_04.STL" />
      </geometry>
      <material
        name="">
        <color
          rgba="0.69804 0.69804 0.69804 1" />
      </material>
    </visual>
    <collision>
      <origin
        xyz="0 0 0"
        rpy="0 0 0" />
      <geometry>
        <mesh
          filename="package://openloong_description/meshes/Link_arm_r_04.STL" />
      </geometry>
    </collision>
  </link>
  <joint
    name="r_arm_04"
    type="fixed">
    <origin
      xyz="0.0353 -0.1774 0.024"
      rpy="0 0 0" />
    <parent
      link="Link_arm_r_03" />
    <child
      link="Link_arm_r_04" />
    <axis
      xyz="-1 0 0" />
    <limit
      lower="0"
      upper="2.96706"
      effort="48"
      velocity="3.14" />
  </joint>
  <link
    name="Link_arm_r_05">
    <inertial>
      <origin
        xyz="3.2712E-05 -0.068658 -0.00011178"
        rpy="0 0 0" />
      <mass
        value="0.68976" />
      <inertia
        ixx="0.0025225"
        ixy="-4E-07"
        ixz="8E-07"
        iyy="0.0004487"
        iyz="3.1E-06"
        izz="0.0024111" />
    </inertial>
    <visual>
      <origin
        xyz="0 0 0"
        rpy="0 0 0" />
      <geometry>
        <mesh
          filename="package://openloong_description/meshes/Link_arm_r_05.STL" />
      </geometry>
      <material
        name="">
        <color
          rgba="0.69804 0.69804 0.69804 1" />
      </material>
    </visual>
    <collision>
      <origin
        xyz="0 0 0"
        rpy="0 0 0" />
      <geometry>
        <mesh
          filename="package://openloong_description/meshes/Link_arm_r_05.STL" />
      </geometry>
    </collision>
  </link>
  <joint
    name="r_arm_05"
    type="fixed">
    <origin
      xyz="-0.0353 -0.1035 -0.024"
      rpy="0 0 0" />
    <parent
      link="Link_arm_r_04" />
    <child
      link="Link_arm_r_05" />
    <axis
      xyz="0 -1 0" />
    <limit
      lower="-2.96706"
      upper="2.96706"
      effort="12.4"
      velocity="6.28" />
  </joint>
  <link
    name="Link_arm_r_06">
    <inertial>
      <origin
        xyz="0.026078 -8.9588E-07 0.0016637"
        rpy="0 0 0" />
      <mass
        value="0.28" />
      <inertia
        ixx="0.0001456"
        ixy="-7.7026E-10"
        ixz="-2.1456E-07"
        iyy="0.00015693"
        iyz="-2.4102E-09"
        izz="0.00010498" />
    </inertial>
    <visual>
      <origin
        xyz="0 0 0"
        rpy="0 0 0" />
      <geometry>
        <mesh
          filename="package://openloong_description/meshes/Link_arm_r_06.STL" />
      </geometry>
      <material
        name="">
        <color
          rgba="0.69804 0.69804 0.69804 1" />
      </material>
    </visual>
    <collision>
      <origin
        xyz="0 0 0"
        rpy="0 0 0" />
      <geometry>
        <mesh
          filename="package://openloong_description/meshes/Link_arm_r_06.STL" />
      </geometry>
    </collision>
  </link>
  <joint
    name="r_arm_06"
    type="fixed">
    <origin
      xyz="-0.0265 -0.1965 0"
      rpy="0 0 0" />
    <parent
      link="Link_arm_r_05" />
    <child
      link="Link_arm_r_06" />
    <axis
      xyz="1 0 0" />
    <limit
      lower="-1.8326"
      upper="1.8326"
      effort="12.4"
      velocity="6.28" />
  </joint>
  <link
    name="Link_arm_r_07">
    <inertial>
      <origin
        xyz="-0.007859 -0.15817 -0.027736"
        rpy="0 0 0" />
      <mass
        value="0.61354" />
      <inertia
        ixx="0.0025969"
        ixy="4.65E-05"
        ixz="-0.0001089"
        iyy="0.0007306"
        iyz="-1.47E-05"
        izz="0.0030104" />
    </inertial>
    <visual>
      <origin
        xyz="0 0 0"
        rpy="0 0 0" />
      <geometry>
        <mesh
          filename="package://openloong_description/meshes/Link_arm_r_07.STL" />
      </geometry>
      <material
        name="">
        <color
          rgba="0.77647 0.75686 0.73725 1" />
      </material>
    </visual>
    <collision>
      <origin
        xyz="0 0 0"
        rpy="0 0 0" />
      <geometry>
        <mesh
          filename="package://openloong_description/meshes/Link_arm_r_07.STL" />
      </geometry>
    </collision>
  </link>
  <joint
    name="r_arm_07"
    type="fixed">
    <origin
      xyz="0.0265 0 0.0318"
      rpy="0 0 0" />
    <parent
      link="Link_arm_r_06" />
    <child
      link="Link_arm_r_07" />
    <axis
      xyz="0 0 1" />
    <limit
      lower="-1.04720"
      upper="1.04720"
      effort="12.4"
      velocity="6.28" />
  </joint>
  <link
    name="Link_arm_l_01">
    <inertial>
      <origin
        xyz="-0.00449464987882542 0.0382942125981936 -1.874402432607E-06"
        rpy="0 0 0" />
      <mass
        value="0.756406339732892" />
      <inertia
        ixx="0.000587115683146372"
        ixy="-2.98026052651538E-07"
        ixz="5.83781087215966E-09"
        iyy="0.000803052813361661"
        iyz="-3.66476835396106E-08"
        izz="0.000842985653484675" />
    </inertial>
    <visual>
      <origin
        xyz="0 0 0"
        rpy="0 0 0" />
      <geometry>
        <mesh
          filename="package://openloong_description/meshes/Link_arm_l_01.STL" />
      </geometry>
      <material
        name="">
        <color
          rgba="0.698039215686274 0.698039215686274 0.698039215686274 1" />
      </material>
    </visual>
    <collision>
      <origin
        xyz="0 0 0"
        rpy="0 0 0" />
      <geometry>
        <mesh
          filename="package://openloong_description/meshes/Link_arm_l_01.STL" />
      </geometry>
    </collision>
  </link>
  <joint
    name="l_arm_01"
    type="fixed">
    <origin
      xyz="0.004 0.1616 0.3922"
      rpy="0 3.14 0" />
    <parent
      link="base_link" />
    <child
      link="Link_arm_l_01" />
    <axis
      xyz="0 1 0" />
    <limit
      lower="-2.96706"
      upper="2.96706"
      effort="80"
      velocity="3.14" />
  </joint>
  <link
    name="Link_arm_l_02">
    <inertial>
      <origin
        xyz="-0.042 0.0674307499121858 1.38777878078145E-17"
        rpy="0 0 0" />
      <mass
        value="0.984999996273518" />
      <inertia
        ixx="0.0017309882399251"
        ixy="1.48322871384691E-19"
        ixz="1.94588987195478E-19"
        iyy="0.00115401958000568"
        iyz="6.15989345249147E-19"
        izz="0.00226269324370836" />
    </inertial>
    <visual>
      <origin
        xyz="0 0 0"
        rpy="0 0 0" />
      <geometry>
        <mesh
          filename="package://openloong_description/meshes/Link_arm_l_02.STL" />
      </geometry>
      <material
        name="">
        <color
          rgba="0.698039215686274 0.698039215686274 0.698039215686274 1" />
      </material>
    </visual>
    <collision>
      <origin
        xyz="0 0 0"
        rpy="0 0 0" />
      <geometry>
        <mesh
          filename="package://openloong_description/meshes/Link_arm_l_02.STL" />
      </geometry>
    </collision>
  </link>
  <joint
    name="l_arm_02"
    type="fixed">
    <origin
      xyz="0.042 0.041 0"
      rpy="1.3 0 0" />
    <parent
      link="Link_arm_l_01" />
    <child
      link="Link_arm_l_02" />
    <axis
      xyz="-1 0 0" />
    <limit
      lower="-1.83260"
      upper="1.83260"
      effort="80"
      velocity="3.14" />
  </joint>
  <link
    name="Link_arm_l_03">
    <inertial>
      <origin
        xyz="0.00141357502419956 0.164662742175383 0.0207578924800774"
        rpy="0 0 0" />
      <mass
        value="0.958999855228925" />
      <inertia
        ixx="0.00206438134078715"
        ixy="-1.82014067823508E-05"
        ixz="-5.12831369639908E-06"
        iyy="0.000805354129266641"
        iyz="-0.000255265992194607"
        izz="0.00205099914609259" />
    </inertial>
    <visual>
      <origin
        xyz="0 0 0"
        rpy="0 0 0" />
      <geometry>
        <mesh
          filename="package://openloong_description/meshes/Link_arm_l_03.STL" />
      </geometry>
      <material
        name="">
        <color
          rgba="0.698039215686274 0.698039215686274 0.698039215686274 1" />
      </material>
    </visual>
    <collision>
      <origin
        xyz="0 0 0"
        rpy="0 0 0" />
      <geometry>
        <mesh
          filename="package://openloong_description/meshes/Link_arm_l_03.STL" />
      </geometry>
    </collision>
  </link>
  <joint
    name="l_arm_03"
    type="fixed">
    <origin
      xyz="-0.042 0.1226 0"
      rpy="0 0 0" />
    <parent
      link="Link_arm_l_02" />
    <child
      link="Link_arm_l_03" />
    <axis
      xyz="0 1 0" />
    <limit
      lower="-2.96706"
      upper="2.96706"
      effort="48"
      velocity="3.14" />
  </joint>
  <link
    name="Link_arm_l_04">
    <inertial>
      <origin
        xyz="0.038726985904266 0.0607672244593032 -0.0210032450980798"
        rpy="0 0 0" />
      <mass
        value="0.60000012303258" />
      <inertia
        ixx="0.000703976141425558"
        ixy="2.02301178076816E-05"
        ixz="-1.12633779930363E-05"
        iyy="0.000680850033983237"
        iyz="0.000105852227353173"
        izz="0.00106526266740194" />
    </inertial>
    <visual>
      <origin
        xyz="0 0 0"
        rpy="0 0 0" />
      <geometry>
        <mesh
          filename="package://openloong_description/meshes/Link_arm_l_04.STL" />
      </geometry>
      <material
        name="">
        <color
          rgba="0.698039215686274 0.698039215686274 0.698039215686274 1" />
      </material>
    </visual>
    <collision>
      <origin
        xyz="0 0 0"
        rpy="0 0 0" />
      <geometry>
        <mesh
          filename="package://openloong_description/meshes/Link_arm_l_04.STL" />
      </geometry>
    </collision>
  </link>
  <joint
    name="l_arm_04"
    type="fixed">
    <origin
      xyz="-0.0353 0.1774 0.024"
      rpy="0 0 0" />
    <parent
      link="Link_arm_l_03" />
    <child
      link="Link_arm_l_04" />
    <axis
      xyz="1 0 0" />
    <limit
      lower="0"
      upper="2.96706"
      effort="48"
      velocity="3.14" />
  </joint>
  <link
    name="Link_arm_l_05">
    <inertial>
      <origin
        xyz="-3.2712E-05 0.068658 -0.00011178"
        rpy="0 0 0" />
      <mass
        value="0.68976" />
      <inertia
        ixx="0.0025225"
        ixy="-4E-07"
        ixz="-8E-07"
        iyy="0.0004487"
        iyz="-3.1E-06"
        izz="0.0024111" />
    </inertial>
    <visual>
      <origin
        xyz="0 0 0"
        rpy="0 0 0" />
      <geometry>
        <mesh
          filename="package://openloong_description/meshes/Link_arm_l_05.STL" />
      </geometry>
      <material
        name="">
        <color
          rgba="0.69804 0.69804 0.69804 1" />
      </material>
    </visual>
    <collision>
      <origin
        xyz="0 0 0"
        rpy="0 0 0" />
      <geometry>
        <mesh
          filename="package://openloong_description/meshes/Link_arm_l_05.STL" />
      </geometry>
    </collision>
  </link>
  <joint
    name="l_arm_05"
    type="fixed">
    <origin
      xyz="0.0353 0.1035 -0.024"
      rpy="0 0 0" />
    <parent
      link="Link_arm_l_04" />
    <child
      link="Link_arm_l_05" />
    <axis
      xyz="0 1 0" />
    <limit
      lower="-2.96706"
      upper="2.96706"
      effort="12.4"
      velocity="6.28" />
  </joint>
  <link
    name="Link_arm_l_06">
    <inertial>
      <origin
        xyz="-0.0260776548825596 8.95877202866657E-07 0.00166373234012217"
        rpy="0 0 0" />
      <mass
        value="0.280000012776158" />
      <inertia
        ixx="0.000145596926990102"
        ixy="-7.70263046256849E-10"
        ixz="2.14557176368931E-07"
        iyy="0.000156926535065694"
        iyz="2.41022657678511E-09"
        izz="0.000104981940665913" />
    </inertial>
    <visual>
      <origin
        xyz="0 0 0"
        rpy="0 0 0" />
      <geometry>
        <mesh
          filename="package://openloong_description/meshes/Link_arm_l_06.STL" />
      </geometry>
      <material
        name="">
        <color
          rgba="0.698039215686274 0.698039215686274 0.698039215686274 1" />
      </material>
    </visual>
    <collision>
      <origin
        xyz="0 0 0"
        rpy="0 0 0" />
      <geometry>
        <mesh
          filename="package://openloong_description/meshes/Link_arm_l_06.STL" />
      </geometry>
    </collision>
  </link>
  <joint
    name="l_arm_06"
    type="fixed">
    <origin
      xyz="0.0265 0.1965 0"
      rpy="0 0 0" />
    <parent
      link="Link_arm_l_05" />
    <child
      link="Link_arm_l_06" />
    <axis
      xyz="-1 0 0" />
    <limit
      lower="-1.8326"
      upper="1.8326"
      effort="12.4"
      velocity="6.28" />
  </joint>
  <link
    name="Link_arm_l_07">
    <inertial>
      <origin
        xyz="-0.0077872 0.15705 -0.027733"
        rpy="0 0 0" />
      <mass
        value="0.61354" />
      <inertia
        ixx="0.0025964"
        ixy="-4.66E-05"
        ixz="-0.0001089"
        iyy="0.0007306"
        iyz="1.47E-05"
        izz="0.00301" />
    </inertial>
    <visual>
      <origin
        xyz="0 0 0"
        rpy="0 0 0" />
      <geometry>
        <mesh
          filename="package://openloong_description/meshes/Link_arm_l_07.STL" />
      </geometry>
      <material
        name="">
        <color
          rgba="0.77647 0.75686 0.73725 1" />
      </material>
    </visual>
    <collision>
      <origin
        xyz="0 0 0"
        rpy="0 0 0" />
      <geometry>
        <mesh
          filename="package://openloong_description/meshes/Link_arm_l_07.STL" />
      </geometry>
    </collision>
  </link>
  <joint
    name="l_arm_07"
    type="fixed">
    <origin
      xyz="-0.0265 0 0.0318"
      rpy="0 0 0" />
    <parent
      link="Link_arm_l_06" />
    <child
      link="Link_arm_l_07" />
    <axis
      xyz="0 0 1" />
    <limit
      lower="-1.04720"
      upper="1.04720"
      effort="12.4"
      velocity="6.28" />
  </joint>
  <link
    name="Link_waist_pitch">
    <inertial>
      <origin
        xyz="-0.00073496 0.049925 -2.9695E-05"
        rpy="0 0 0" />
      <mass
        value="2.6964" />
      <inertia
        ixx="0.0051971"
        ixy="-4.37E-05"
        ixz="3E-07"
        iyy="0.0047413"
        iyz="6E-06"
        izz="0.0061906" />
    </inertial>
    <visual>
      <origin
        xyz="0 0 0"
        rpy="0 0 0" />
      <geometry>
        <mesh
          filename="package://openloong_description/meshes/Link_waist_pitch.STL" />
      </geometry>
      <material
        name="">
        <color
          rgba="0.69804 0.69804 0.69804 1" />
      </material>
    </visual>
    <!-- <collision>
      <origin
        xyz="0 0 0"
        rpy="0 0 0" />
      <geometry>
        <mesh
          filename="package://openloong_description/meshes/Link_waist_pitch.STL" />
      </geometry>
    </collision> -->
  </link>
  <joint
    name="J_waist_pitch"
    type="fixed">
    <origin
      xyz="0 -0.06525 0"
      rpy="0 0 0" />
    <parent
      link="base_link" />
    <child
      link="Link_waist_pitch" />
    <axis
      xyz="0 -1 0" />
    <limit
      lower="-0.29671"
      upper="0.78540"
      effort="315"
      velocity="3.72" />
  </joint>
  <link
    name="Link_waist_roll">
    <inertial>
      <origin
        xyz="-0.0037424 -0.001 -0.016856"
        rpy="0 0 0" />
      <mass
        value="2.9806" />
      <inertia
        ixx="0.0071327"
        ixy="0"
        ixz="-0.00358"
        iyy="0.018825"
        iyz="0"
        izz="0.016056" />
    </inertial>
    <visual>
      <origin
        xyz="0 0 0"
        rpy="0 0 0" />
      <geometry>
        <mesh
          filename="package://openloong_description/meshes/Link_waist_roll.STL" />
      </geometry>
      <material
        name="">
        <color
          rgba="0.8902 0.8902 0.91373 1" />
      </material>
    </visual>
    <!-- <collision>
      <origin
        xyz="0 0 0"
        rpy="0 0 0" />
      <geometry>
        <mesh
          filename="package://openloong_description/meshes/Link_waist_roll.STL" />
      </geometry>
    </collision> -->
  </link>
  <joint
    name="J_waist_roll"
    type="fixed">
    <origin
      xyz="-0.064 0.0655 0"
      rpy="0 0 0" />
    <parent
      link="Link_waist_pitch" />
    <child
      link="Link_waist_roll" />
    <axis
      xyz="1 0 0" />
    <limit
      lower="-0.69813"
      upper="0.69813"
      effort="315"
      velocity="3.72" />
  </joint>
  <link
    name="Link_waist_yaw">
    <inertial>
      <origin
        xyz="-0.096172 -0.001 -0.057836"
        rpy="0 0 0" />
      <mass
        value="7.3588" />
      <inertia
        ixx="0.091635"
        ixy="0"
        ixz="0.0058036"
        iyy="0.032766"
        iyz="0"
        izz="0.10764" />
    </inertial>
    <visual>
      <origin
        xyz="0 0 0"
        rpy="0 0 0" />
      <geometry>
        <mesh
          filename="package://openloong_description/meshes/Link_waist_yaw.STL" />
      </geometry>
      <material
        name="">
        <color
          rgba="0.8902 0.8902 0.91373 1" />
      </material>
    </visual>
    <!-- <collision>
      <origin
        xyz="0 0 0"
        rpy="0 0 0" />
      <geometry>
        <mesh
          filename="package://openloong_description/meshes/Link_waist_yaw.STL" />
      </geometry>
    </collision> -->
  </link>
  <joint
    name="J_waist_yaw"
    type="fixed">
    <origin
      xyz="0.0675 0 -0.098"
      rpy="0 0 0" />
    <parent
      link="Link_waist_roll" />
    <child
      link="Link_waist_yaw" />
    <axis
      xyz="0 0 1" />
    <limit
      lower="-0.78540"
      upper="0.78540"
      effort="121"
      velocity="5.92" />
  </joint>
  <link
    name="Link_hip_r_roll">
    <inertial>
      <origin
        xyz="0.075725 -0.0010616 0.016591"
        rpy="0 0 0" />
      <mass
        value="2.4334" />
      <inertia
        ixx="0.0036961"
        ixy="-9E-07"
        ixz="0.0001644"
        iyy="0.0045067"
        iyz="6.3E-06"
        izz="0.0039063" />
    </inertial>
    <visual>
      <origin
        xyz="0 0 0"
        rpy="0 0 0" />
      <geometry>
        <mesh
          filename="package://openloong_description/meshes/Link_hip_r_roll.STL" />
      </geometry>
      <material
        name="">
        <color
          rgba="0.89804 0.91765 0.92941 1" />
      </material>
    </visual>
    <!-- <collision>
      <origin
        xyz="0 0 0"
        rpy="0 0 0" />
      <geometry>
        <mesh
          filename="package://openloong_description/meshes/Link_hip_r_roll.STL" />
      </geometry>
    </collision> -->
  </link>
  <joint
    name="r_hip_roll"
    type="revolute">
    <origin
      xyz="-0.0875 -0.12 -0.069"
      rpy="0 0 0" />
    <parent
      link="Link_waist_yaw" />
    <child
      link="Link_hip_r_roll" />
    <axis
      xyz="1 0 0" />
    <limit
      lower="-0.17453"
      upper="0.43633"
      effort="320"
      velocity="20.94" />
  </joint>
  <link
    name="Link_hip_r_yaw">
    <inertial>
      <origin
        xyz="-3.0911E-08 -0.0071356 -0.10063"
        rpy="0 0 0" />
      <mass
        value="3.4303" />
      <inertia
        ixx="0.0077365"
        ixy="0"
        ixz="0"
        iyy="0.0080807"
        iyz="0.0001167"
        izz="0.006641" />
    </inertial>
    <visual>
      <origin
        xyz="0 0 0"
        rpy="0 0 0" />
      <geometry>
        <mesh
          filename="package://openloong_description/meshes/Link_hip_r_yaw.STL" />
      </geometry>
      <material
        name="">
        <color
          rgba="0.89804 0.91765 0.92941 1" />
      </material>
    </visual>
    <!-- <collision>
      <origin
        xyz="0 0 0"
        rpy="0 0 0" />
      <geometry>
        <mesh
          filename="package://openloong_description/meshes/Link_hip_r_yaw.STL" />
      </geometry>
    </collision> -->
  </link>
  <joint
    name="r_hip_yaw"
    type="revolute">
    <origin
      xyz="0.08225 -0.001 -0.01"
      rpy="0 0 0" />
    <parent
      link="Link_hip_r_roll" />
    <child
      link="Link_hip_r_yaw" />
    <axis
      xyz="0 0 1" />
    <limit
      lower="-0.69813"
      upper="0.69813"
      effort="160"
      velocity="19.63" />
  </joint>
  <link
    name="Link_hip_r_pitch">
    <inertial>
      <origin
        xyz="0.0010856 -0.05497 -0.14535"
        rpy="0 0 0" />
      <mass
        value="5.2378" />
      <inertia
        ixx="0.043457"
        ixy="0.0002478"
        ixz="-0.0007626"
        iyy="0.037801"
        iyz="-0.0007431"
        izz="0.015183" />
    </inertial>
    <visual>
      <origin
        xyz="0 0 0"
        rpy="0 0 0" />
      <geometry>
        <mesh
          filename="package://openloong_description/meshes/Link_hip_r_pitch.STL" />
      </geometry>
      <material
        name="">
        <color
          rgba="0.69804 0.69804 0.69804 1" />
      </material>
    </visual>
    <collision>
      <origin
        xyz="0 0 0"
        rpy="0 0 0" />
      <geometry>
        <mesh
          filename="package://openloong_description/meshes/Link_hip_r_pitch.STL" />
      </geometry>
    </collision>
  </link>
  <joint
    name="r_hip_pitch"
    type="revolute">
    <origin
      xyz="0 0.03675 -0.1055"
      rpy="0 -0.4 0" />
    <parent
      link="Link_hip_r_yaw" />
    <child
      link="Link_hip_r_pitch" />
    <axis
      xyz="0 -1 0" />
    <limit
      lower="-0.78540"
      upper="1.83260"
      effort="396"
      velocity="19.16" />
  </joint>
  <link
    name="Link_knee_r_pitch">
    <inertial>
      <origin
        xyz="-0.0096425 2.9338E-06 -0.13601"
        rpy="0 0 0" />
      <mass
        value="2.9775" />
      <inertia
        ixx="0.02386"
        ixy="6.76E-05"
        ixz="-0.0004656"
        iyy="0.024184"
        iyz="-0.0005481"
        izz="0.0023083" />
    </inertial>
    <visual>
      <origin
        xyz="0 0 0"
        rpy="0 0 0" />
      <geometry>
        <mesh
          filename="package://openloong_description/meshes/Link_knee_r_pitch.STL" />
      </geometry>
      <material
        name="">
        <color
          rgba="0.66667 0.69804 0.76863 1" />
      </material>
    </visual>
    <!-- <collision>
      <origin
        xyz="0 0 0"
        rpy="0 0 0" />
      <geometry>
        <mesh
          filename="package://openloong_description/meshes/Link_knee_r_pitch.STL" />
      </geometry>
    </collision> -->
    <collision>
      <origin xyz="0 0 -0.2" rpy="0 0 0" />
      <geometry>
        <cylinder radius="0.05" length="0.2"/>
      </geometry>
    </collision>
  </link>
  <joint
    name="r_knee_pitch"
    type="revolute">
    <origin
      xyz="0 -0.01125 -0.4"
      rpy="0 0.8 0" />
    <parent
      link="Link_hip_r_pitch" />
    <child
      link="Link_knee_r_pitch" />
    <axis
      xyz="0 -1 0" />
    <limit
      lower="-2.35619"
      upper="0.08727"
      effort="396"
      velocity="19.16" />
  </joint>
  <link
    name="Link_r_ankle_pitch">
    <inertial>
      <origin
        xyz="-6.1835E-12 -1.2655E-07 -2.4682E-08"
        rpy="0 0 0" />
      <mass
        value="0.10145" />
      <inertia
        ixx="2.7175E-05"
        ixy="1.0023E-14"
        ixz="-8.1752E-13"
        iyy="6.1118E-06"
        iyz="2.6285E-11"
        izz="2.6565E-05" />
    </inertial>
    <visual>
      <origin
        xyz="0 0 0"
        rpy="0 0 0" />
      <geometry>
        <mesh
          filename="package://openloong_description/meshes/Link_r_ankle_pitch.STL" />
      </geometry>
      <material
        name="">
        <color
          rgba="0.52941 0.54902 0.54902 1" />
      </material>
    </visual>
    <!-- <collision>
      <origin
        xyz="0 0 0"
        rpy="0 0 0" />
      <geometry>
        <mesh
          filename="package://openloong_description/meshes/Link_r_ankle_pitch.STL" />
      </geometry>
    </collision> -->
  </link>
  <joint
    name="r_ankle_pitch"
    type="revolute">
    <origin
      xyz="0 0 -0.387"
      rpy="0 -0.4 0" />
    <parent
      link="Link_knee_r_pitch" />
    <child
      link="Link_r_ankle_pitch" />
    <axis
      xyz="0 -1 0" />
    <limit
      lower="-0.43633"
      upper="0.61087"
      effort="58.5"
      velocity="48.8" />
  </joint>
  <link
    name="Link_r_ankle_roll">
    <inertial>
      <origin
        xyz="0.041078 -8.9152E-08 -0.043909"
        rpy="0 0 0" />
      <mass
        value="0.75229" />
      <inertia
        ixx="0.0004393"
        ixy="0"
        ixz="-0.000269"
        iyy="0.0036465"
        iyz="0"
        izz="0.0036369" />
    </inertial>
    <visual>
      <origin
        xyz="0 0 0"
        rpy="0 0 0" />
      <geometry>
        <mesh
          filename="package://openloong_description/meshes/Link_r_ankle_roll.STL" />
      </geometry>
      <material
        name="">
        <color
          rgba="0.89804 0.91765 0.92941 1" />
      </material>
    </visual>
    <collision>
      <origin
        xyz="0 0 0"
        rpy="0 0 0" />
      <geometry>
        <mesh
          filename="package://openloong_description/meshes/Link_r_ankle_roll.STL" />
      </geometry>
    </collision>
  </link>
  <joint
    name="r_ankle_roll"
    type="revolute">
    <origin
      xyz="0 0 0"
      rpy="0 0 0" />
    <parent
      link="Link_r_ankle_pitch" />
    <child
      link="Link_r_ankle_roll" />
    <axis
      xyz="1 0 0" />
    <limit
      lower="-0.43633"
      upper="0.43633"
      effort="58.5"
      velocity="48.8" />
  </joint>
  <link
    name="Link_hip_l_roll">
    <inertial>
      <origin
        xyz="0.075725 -0.00093843 0.016591"
        rpy="0 0 0" />
      <mass
        value="2.4334" />
      <inertia
        ixx="0.0034464"
        ixy="9E-07"
        ixz="0.0001904"
        iyy="0.0042569"
        iyz="-6.6E-06"
        izz="0.0039063" />
    </inertial>
    <visual>
      <origin
        xyz="0 0 0"
        rpy="0 0 0" />
      <geometry>
        <mesh
          filename="package://openloong_description/meshes/Link_hip_l_roll.STL" />
      </geometry>
      <material
        name="">
        <color
          rgba="0.89804 0.91765 0.92941 1" />
      </material>
    </visual>
    <!-- <collision>
      <origin
        xyz="0 0 0"
        rpy="0 0 0" />
      <geometry>
        <mesh
          filename="package://openloong_description/meshes/Link_hip_l_roll.STL" />
      </geometry>
    </collision> -->
  </link>
  <joint
    name="l_hip_roll"
    type="revolute">
    <origin
      xyz="-0.0875 0.12 -0.069"
      rpy="0 0 0" />
    <parent
      link="Link_waist_yaw" />
    <child
      link="Link_hip_l_roll" />
    <axis
      xyz="1 0 0" />
    <limit
      lower="-0.17453"
      upper="0.43633"
      effort="320"
      velocity="20.94" />
  </joint>
  <link
    name="Link_hip_l_yaw">
    <inertial>
      <origin
        xyz="-3.1716E-08 0.0071358 -0.10063"
        rpy="0 0 0" />
      <mass
        value="3.4304" />
      <inertia
        ixx="0.0077365"
        ixy="0"
        ixz="0"
        iyy="0.0080807"
        iyz="-0.0001167"
        izz="0.0066409" />
    </inertial>
    <visual>
      <origin
        xyz="0 0 0"
        rpy="0 0 0" />
      <geometry>
        <mesh
          filename="package://openloong_description/meshes/Link_hip_l_yaw.STL" />
      </geometry>
      <material
        name="">
        <color
          rgba="0.89804 0.91765 0.92941 1" />
      </material>
    </visual>
    <!-- <collision>
      <origin
        xyz="0 0 0"
        rpy="0 0 0" />
      <geometry>
        <mesh
          filename="package://openloong_description/meshes/Link_hip_l_yaw.STL" />
      </geometry>
    </collision> -->
  </link>
  <joint
    name="l_hip_yaw"
    type="revolute">
    <origin
      xyz="0.08225 -0.001 -0.01"
      rpy="0 0 0" />
    <parent
      link="Link_hip_l_roll" />
    <child
      link="Link_hip_l_yaw" />
    <axis
      xyz="0 0 1" />
    <limit
      lower="-0.69813"
      upper="0.69813"
      effort="160"
      velocity="19.63" />
  </joint>
  <link
    name="Link_hip_l_pitch">
    <inertial>
      <origin
        xyz="0.0010856 0.05497 -0.14535"
        rpy="0 0 0" />
      <mass
        value="5.2378" />
      <inertia
        ixx="0.043457"
        ixy="-0.0002479"
        ixz="-0.0007626"
        iyy="0.037801"
        iyz="0.0007431"
        izz="0.015183" />
    </inertial>
    <visual>
      <origin
        xyz="0 0 0"
        rpy="0 0 0" />
      <geometry>
        <mesh
          filename="package://openloong_description/meshes/Link_hip_l_pitch.STL" />
      </geometry>
      <material
        name="">
        <color
          rgba="0.69804 0.69804 0.69804 1" />
      </material>
    </visual>
    <collision>
      <origin
        xyz="0 0 0"
        rpy="0 0 0" />
      <geometry>
        <mesh
          filename="package://openloong_description/meshes/Link_hip_l_pitch.STL" />
      </geometry>
    </collision>
  </link>
  <joint
    name="l_hip_pitch"
    type="revolute">
    <origin
      xyz="0 -0.03675 -0.1055"
      rpy="0 -0.4 0" />
    <parent
      link="Link_hip_l_yaw" />
    <child
      link="Link_hip_l_pitch" />
    <axis
      xyz="0 -1 0" />
    <limit
      lower="-0.78540"
      upper="1.83260"
      effort="396"
      velocity="19.16" />
  </joint>
  <link
    name="Link_knee_l_pitch">
    <inertial>
      <origin
        xyz="-0.0096425 -2.8684E-06 -0.13601"
        rpy="0 0 0" />
      <mass
        value="2.9775" />
      <inertia
        ixx="0.023859"
        ixy="-6.76E-05"
        ixz="-0.0004656"
        iyy="0.024183"
        iyz="0.000548"
        izz="0.0023083" />
    </inertial>
    <visual>
      <origin
        xyz="0 0 0"
        rpy="0 0 0" />
      <geometry>
        <mesh
          filename="package://openloong_description/meshes/Link_knee_l_pitch.STL" />
      </geometry>
      <material
        name="">
        <color
          rgba="0.66667 0.69804 0.76863 1" />
      </material>
    </visual>
    <!-- <collision>
      <origin
        xyz="0 0 0"
        rpy="0 0 0" />
      <geometry>
        <mesh
          filename="package://openloong_description/meshes/Link_knee_l_pitch.STL" />
      </geometry>
    </collision> -->
    <collision>
      <origin xyz="0 0 -0.2" rpy="0 0 0" />
      <geometry>
        <cylinder radius="0.05" length="0.2"/>
      </geometry>
    </collision>
  </link>
  <joint
    name="l_knee_pitch"
    type="revolute">
    <origin
      xyz="0 0.01125 -0.4"
      rpy="0 0.8 0" />
    <parent
      link="Link_hip_l_pitch" />
    <child
      link="Link_knee_l_pitch" />
    <axis
      xyz="0 -1 0" />
    <limit
      lower="-2.35619"
      upper="0.08727"
      effort="396"
      velocity="19.16" />
  </joint>
  <link
    name="Link_l_ankle_pitch">
    <inertial>
      <origin
        xyz="-6.1835E-12 1.2655E-07 6.7022E-08"
        rpy="0 0 0" />
      <mass
        value="0.10145" />
      <inertia
        ixx="2.7175E-05"
        ixy="-1.0023E-14"
        ixz="-8.1752E-13"
        iyy="6.1118E-06"
        iyz="-2.6285E-11"
        izz="2.6565E-05" />
    </inertial>
    <visual>
      <origin
        xyz="0 0 0"
        rpy="0 0 0" />
      <geometry>
        <mesh
          filename="package://openloong_description/meshes/Link_l_ankle_pitch.STL" />
      </geometry>
      <material
        name="">
        <color
          rgba="0.52941 0.54902 0.54902 1" />
      </material>
    </visual>
    <!-- <collision>
      <origin
        xyz="0 0 0"
        rpy="0 0 0" />
      <geometry>
        <mesh
          filename="package://openloong_description/meshes/Link_l_ankle_pitch.STL" />
      </geometry>
    </collision> -->
  </link>
  <joint
    name="l_ankle_pitch"
    type="revolute">
    <origin
      xyz="0 0 -0.387"
      rpy="0 -0.4 0" />
    <parent
      link="Link_knee_l_pitch" />
    <child
      link="Link_l_ankle_pitch" />
    <axis
      xyz="0 -1 0" />
    <limit
      lower="-0.43644"
      upper="0.61087"
      effort="58.5"
      velocity="48.8" />
  </joint>
  <link
    name="Link_l_ankle_roll">
    <inertial>
      <origin
        xyz="0.041077 -2.9318E-08 -0.043909"
        rpy="0 0 0" />
      <mass
        value="0.7522882" />
      <inertia
        ixx="0.0004393"
        ixy="0"
        ixz="-0.000269"
        iyy="0.0036465"
        iyz="0"
        izz="0.0036369" />
    </inertial>
    <visual>
      <origin
        xyz="0 0 0"
        rpy="0 0 0" />
      <geometry>
        <mesh
          filename="package://openloong_description/meshes/Link_l_ankle_roll.STL" />
      </geometry>
      <material
        name="">
        <color
          rgba="0.89804 0.91765 0.92941 1" />
      </material>
    </visual>
    <collision>
      <origin
        xyz="0 0 0"
        rpy="0 0 0" />
      <geometry>
        <mesh
          filename="package://openloong_description/meshes/Link_l_ankle_roll.STL" />
      </geometry>
    </collision>
  </link>
  <joint
    name="l_ankle_roll"
    type="revolute">
    <origin
      xyz="0 0 0"
      rpy="0 0 0" />
    <parent
      link="Link_l_ankle_pitch" />
    <child
      link="Link_l_ankle_roll" />
    <axis
      xyz="1 0 0" />
    <limit
      lower="-0.43633"
      upper="0.43633"
      effort="58.5"
      velocity="48.8" />
  </joint>

  <!-- ############################################################ -->

  <link name="imu_link">
    <visual>
      <geometry>
        <box size="0.05 0.05 0.02"/>
      </geometry>
      <material name="">
        <color rgba="0.75294 0.75294 0.75294 1"/>
      </material>
    </visual>
  </link>
  <joint name="z_joint_imu" type="fixed">
    <origin xyz="-0.0648 0 -0.1015" rpy="0 0 0"/>
    <parent link="base_link"/>
    <child link="imu_link"/>
  </joint>

  <!-- ############################################################ -->

  <transmission name="l_hip_roll_tran">
    <type>transmission_interface/SimpleTransmission</type>
    <joint name="l_hip_roll">
      <hardwareInterface>hardware_interface/EffortJointInterface</hardwareInterface>
    </joint>
    <actuator name="l_hip_roll_motor">
      <hardwareInterface>hardware_interface/EffortJointInterface</hardwareInterface>
      <mechanicalReduction>&quot;1&quot;</mechanicalReduction>
    </actuator>
  </transmission>
  <transmission name="l_hip_yaw_tran">
    <type>transmission_interface/SimpleTransmission</type>
    <joint name="l_hip_yaw">
      <hardwareInterface>hardware_interface/EffortJointInterface</hardwareInterface>
    </joint>
    <actuator name="l_hip_yaw_motor">
      <hardwareInterface>hardware_interface/EffortJointInterface</hardwareInterface>
      <mechanicalReduction>&quot;1&quot;</mechanicalReduction>
    </actuator>
  </transmission>
  <transmission name="l_hip_pitch_tran">
    <type>transmission_interface/SimpleTransmission</type>
    <joint name="l_hip_pitch">
      <hardwareInterface>hardware_interface/EffortJointInterface</hardwareInterface>
    </joint>
    <actuator name="l_hip_pitch_motor">
      <hardwareInterface>hardware_interface/EffortJointInterface</hardwareInterface>
      <mechanicalReduction>&quot;1&quot;</mechanicalReduction>
    </actuator>
  </transmission>
  <transmission name="l_knee_pitch_tran">
    <type>transmission_interface/SimpleTransmission</type>
    <joint name="l_knee_pitch">
      <hardwareInterface>hardware_interface/EffortJointInterface</hardwareInterface>
    </joint>
    <actuator name="l_knee_pitch_motor">
      <hardwareInterface>hardware_interface/EffortJointInterface</hardwareInterface>
      <mechanicalReduction>&quot;1&quot;</mechanicalReduction>
    </actuator>
  </transmission>
  <transmission name="l_ankle_pitch_tran">
    <type>transmission_interface/SimpleTransmission</type>
    <joint name="l_ankle_pitch">
      <hardwareInterface>hardware_interface/EffortJointInterface</hardwareInterface>
    </joint>
    <actuator name="l_ankle_pitch_motor">
      <hardwareInterface>hardware_interface/EffortJointInterface</hardwareInterface>
      <mechanicalReduction>&quot;1&quot;</mechanicalReduction>
    </actuator>
  </transmission>
  <transmission name="l_ankle_roll_tran">
    <type>transmission_interface/SimpleTransmission</type>
    <joint name="l_ankle_roll">
      <hardwareInterface>hardware_interface/EffortJointInterface</hardwareInterface>
    </joint>
    <actuator name="l_ankle_roll_motor">
      <hardwareInterface>hardware_interface/EffortJointInterface</hardwareInterface>
      <mechanicalReduction>&quot;1&quot;</mechanicalReduction>
    </actuator>
  </transmission>

  <transmission name="r_hip_roll_tran">
    <type>transmission_interface/SimpleTransmission</type>
    <joint name="r_hip_roll">
      <hardwareInterface>hardware_interface/EffortJointInterface</hardwareInterface>
    </joint>
    <actuator name="r_hip_roll_motor">
      <hardwareInterface>hardware_interface/EffortJointInterface</hardwareInterface>
      <mechanicalReduction>&quot;1&quot;</mechanicalReduction>
    </actuator>
  </transmission>
  <transmission name="r_hip_yaw_tran">
    <type>transmission_interface/SimpleTransmission</type>
    <joint name="r_hip_yaw">
      <hardwareInterface>hardware_interface/EffortJointInterface</hardwareInterface>
    </joint>
    <actuator name="r_hip_yaw_motor">
      <hardwareInterface>hardware_interface/EffortJointInterface</hardwareInterface>
      <mechanicalReduction>&quot;1&quot;</mechanicalReduction>
    </actuator>
  </transmission>
  <transmission name="r_hip_pitch_tran">
    <type>transmission_interface/SimpleTransmission</type>
    <joint name="r_hip_pitch">
      <hardwareInterface>hardware_interface/EffortJointInterface</hardwareInterface>
    </joint>
    <actuator name="r_hip_pitch_motor">
      <hardwareInterface>hardware_interface/EffortJointInterface</hardwareInterface>
      <mechanicalReduction>&quot;1&quot;</mechanicalReduction>
    </actuator>
  </transmission>
  <transmission name="r_knee_pitch_tran">
    <type>transmission_interface/SimpleTransmission</type>
    <joint name="r_knee_pitch">
      <hardwareInterface>hardware_interface/EffortJointInterface</hardwareInterface>
    </joint>
    <actuator name="r_knee_pitch_motor">
      <hardwareInterface>hardware_interface/EffortJointInterface</hardwareInterface>
      <mechanicalReduction>&quot;1&quot;</mechanicalReduction>
    </actuator>
  </transmission>
  <transmission name="r_ankle_pitch_tran">
    <type>transmission_interface/SimpleTransmission</type>
    <joint name="r_ankle_pitch">
      <hardwareInterface>hardware_interface/EffortJointInterface</hardwareInterface>
    </joint>
    <actuator name="r_ankle_pitch_motor">
      <hardwareInterface>hardware_interface/EffortJointInterface</hardwareInterface>
      <mechanicalReduction>&quot;1&quot;</mechanicalReduction>
    </actuator>
  </transmission>
  <transmission name="r_ankle_roll_tran">
    <type>transmission_interface/SimpleTransmission</type>
    <joint name="r_ankle_roll">
      <hardwareInterface>hardware_interface/EffortJointInterface</hardwareInterface>
    </joint>
    <actuator name="r_ankle_roll_motor">
      <hardwareInterface>hardware_interface/EffortJointInterface</hardwareInterface>
      <mechanicalReduction>&quot;1&quot;</mechanicalReduction>
    </actuator>
  </transmission>

</robot>
