<?xml version="1.0" ?>
<robot name="cyberdog_description" xmlns:xacro="http://www.ros.org/wiki/xacro">
  <material name="black">
    <color rgba="0.0 0.0 0.0 1.0"/>
  </material>
  <material name="blue">
    <color rgba="0.0 0.0 0.8 1.0"/>
  </material>
  <material name="green">
    <color rgba="0.0 0.8 0.0 1.0"/>
  </material>
  <material name="grey">
    <color rgba="0.2 0.2 0.2 1.0"/>
  </material>
  <material name="silver">
    <color rgba="0.913725490196 0.913725490196 0.847058823529 1.0"/>
  </material>
  <material name="orange">
    <color rgba="0.12 0.15 0.2 1.0"/>
  </material>
  <material name="brown">
    <color rgba="0.870588235294 0.811764705882 0.764705882353 1.0"/>
  </material>
  <material name="red">
    <color rgba="0.8 0.0 0.0 1.0"/>
  </material>
  <material name="white">
    <color rgba="1.0 1.0 1.0 1.0"/>
  </material>

  <link name="base">
    <visual>
      <origin rpy="0 0 0" xyz="0 0 0"/>
      <geometry>
        <box size="0.001 0.001 0.001"/>
      </geometry>
    </visual>
  </link>
  <joint name="floating_base" type="fixed">
    <origin rpy="0 0 0" xyz="0 0 0"/>
    <parent link="base"/>
    <child link="trunk"/>
  </joint>
  <link name="trunk">
    <visual>
      <origin rpy="0 0 0" xyz="0 0 0"/>
      <geometry>
        <box size="0.36 0.23 0.15"/>
      </geometry>
      <material name="silver"/>
    </visual>
    <collision>
      <origin rpy="0 0 0" xyz="0 0 0"/>
      <geometry>
        <box size="0.36 0.23 0.15"/>
      </geometry>
    </collision>
    <inertial>
      <origin rpy="0 0 0" xyz="0.018785003 0.003291012 -0.000925646"/>
      <mass value="6.248410872"/>
      <inertia ixx="0.032143039" ixy="-0.000268204" ixz="-0.00241341" iyy="0.13578316" iyz="8.0244e-05" izz="0.14828095"/>
    </inertial>
  </link>
  <joint name="imu_joint" type="fixed">
    <parent link="trunk"/>
    <child link="imu_link"/>
    <origin rpy="0 0 0" xyz="0 0 0"/>
  </joint>
  <link name="imu_link">
  </link>

  <joint name="FR_hip_joint" type="revolute">
    <origin rpy="0 0 0" xyz="0.23035 -0.05 0"/>
    <parent link="trunk"/>
    <child link="FR_hip"/>
    <axis xyz="1 0 0"/>
    <dynamics damping="0" friction="0"/>
    <limit effort="24" lower="-0.76096355387" upper="0.76096355387" velocity="31"/>
  </joint>
  <link name="FR_hip">
    <visual>
      <origin rpy="1.5707963267948966 0 0" xyz="0 0 0"/>
      <geometry>
        <cylinder length="0.052" radius="0.047"/>
      </geometry>
      <material name="silver"/>
    </visual>
    <collision>
      <origin rpy="1.5707963267948966 0 0" xyz="0 0 0"/>
      <geometry>
        <cylinder length="0.052" radius="0.047"/>
      </geometry>
    </collision>
    <inertial>
      <origin rpy="0 0 0" xyz="-0.001597914 -0.001680938 2.253e-06"/>
      <mass value="0.537806728"/>
      <inertia ixx="0.000403612" ixy="9.337e-06" ixz="5.36e-07" iyy="0.000600779" iyz="6.3e-08" izz="0.000417249"/>
    </inertial>
  </link>
  <joint name="FR_hip_rotor_fix" type="fixed">
    <origin rpy="0 0 0" xyz="-0.0832504 0 0"/>
    <parent link="FR_hip"/>
    <child link="FR_hip_rotor"/>
  </joint>
  <!-- this link is only for abad rotor inertial -->
  <link name="FR_hip_rotor">
    <inertial>
      <origin rpy="0 0 0" xyz="0 0 0"/>
      <mass value="0.076506382"/>
      <inertia ixx="4.5843e-05" ixy="0" ixz="0" iyy="4.5871e-05" iyz="0" izz="8.9031e-05"/>
    </inertial>
  </link>
  <joint name="FR_hip_fixed" type="fixed">
    <origin rpy="0 0 0" xyz="0 -0.053076000000000005 0"/>
    <parent link="FR_hip"/>
    <child link="FR_thigh_shoulder"/>
  </joint>
  <link name="FR_thigh_shoulder">
    <visual>
      <origin rpy="1.5707963267948966 0 0" xyz="0 0 0"/>
      <geometry>
        <cylinder length="0.052" radius="0.047"/>
      </geometry>
      <material name="silver"/>
    </visual>
    <collision>
      <origin rpy="1.5707963267948966 0 0" xyz="0 0 0"/>
      <geometry>
        <cylinder length="0.052" radius="0.047"/>
      </geometry>
    </collision>
  </link>
  <joint name="FR_thigh_joint" type="revolute">
    <origin rpy="0 0 0" xyz="0 -0.105076 0"/>
    <parent link="FR_hip"/>
    <child link="FR_thigh"/>
    <axis xyz="0 1 0"/>
    <dynamics damping="0" friction="0"/>
    <limit effort="24" lower="-1.88495559215" upper="3.76991118431" velocity="31"/>
  </joint>
  <link name="FR_thigh">
    <visual>
      <origin rpy="0 1.5707963267948966 0" xyz="0 0 -0.1"/>
      <geometry>
        <box size="0.2 0.035 0.05"/>
      </geometry>
      <material name="silver"/>
    </visual>
    <collision>
      <origin rpy="0 1.5707963267948966 0" xyz="0 0 -0.1"/>
      <geometry>
        <box size="0.2 0.035 0.05"/>
      </geometry>
    </collision>
    <inertial>
      <origin rpy="0 0 0" xyz="-0.003205778 0.027811623 -0.027767048"/>
      <mass value="0.950266218"/>
      <inertia ixx="0.004811898" ixy="-9.3647e-05" ixz="-0.000208709" iyy="0.004752366" iyz="-0.000813258" izz="0.001079691"/>
    </inertial>
  </link>
  <joint name="FR_thigh_rotor_fix" type="fixed">
    <origin rpy="0 0 0" xyz="0 0.107226 0"/>
    <parent link="FR_thigh"/>
    <child link="FR_thigh_rotor"/>
  </joint>
  <!-- this link is only for hip rotor inertial -->
  <link name="FR_thigh_rotor">
    <inertial>
      <origin rpy="0 0 0" xyz="0 0 0"/>
      <mass value="0.076506382"/>
      <inertia ixx="4.5843e-05" ixy="0" ixz="0" iyy="4.5871e-05" iyz="0" izz="8.9031e-05"/>
    </inertial>
  </link>
  <joint name="FR_calf_rotor_fix" type="fixed">
    <origin rpy="0 0 0" xyz="0 0.0426259 0"/>
    <parent link="FR_thigh"/>
    <child link="FR_calf_rotor"/>
  </joint>
  <!-- this link is only for knee rotor inertial -->
  <link name="FR_calf_rotor">
    <inertial>
      <origin rpy="0 0 0" xyz="0 0 0"/>
      <mass value="0.076506382"/>
      <inertia ixx="4.5843e-05" ixy="0" ixz="0" iyy="4.5871e-05" iyz="0" izz="8.9031e-05"/>
    </inertial>
  </link>
  <joint name="FR_calf_joint" type="revolute">
    <origin rpy="0 0 0" xyz="0 0 -0.2"/>
    <parent link="FR_thigh"/>
    <child link="FR_calf"/>
    <axis xyz="0 1 0"/>
    <dynamics damping="0" friction="0"/>
    <limit effort="24" lower="-2.49582083035" upper="-0.717155789644" velocity="31"/>
  </joint>
  <link name="FR_calf">
    <visual>
      <origin rpy="0 3.141592653589793 0" xyz="0 0 -0.1045"/>
      <geometry>
        <box size="0.016 0.016 0.209"/>
      </geometry>
      <material name="silver"/>
    </visual>
    <visual name="FR_calf_rubber">
      <origin rpy="0 3.141592653589793 0" xyz="-0.0125 0 -0.007"/>
      <geometry>
        <sphere radius="0.016"/>
      </geometry>
    </visual>
    <collision>
      <origin rpy="0 3.141592653589793 0" xyz="0 0 -0.1045"/>
      <geometry>
        <box size="0.016 0.016 0.209"/>
      </geometry>
    </collision>
    <collision name="FR_calf_rubber">
      <origin rpy="0 3.141592653589793 0" xyz="-0.0125 0 -0.007"/>
      <geometry>
        <sphere radius="0.016"/>
      </geometry>
    </collision>
    <inertial>
      <origin rpy="0 0 0" xyz="0.007372358 0.000122423 -0.10769301"/>
      <mass value="0.1135916"/>
      <inertia ixx="0.000667971" ixy="-1e-09" ixz="5.356e-06" iyy="0.000674399" iyz="-1.5e-08" izz="1.4181e-05"/>
    </inertial>
  </link>
  <joint name="FR_foot_fixed" type="fixed" dont_collapse="true">
    <origin rpy="0 0 0" xyz="0 0 -0.19999999999999998"/>
    <parent link="FR_calf"/>
    <child link="FR_foot"/>
  </joint>
  <link name="FR_foot">
    <visual>
      <origin rpy="0 0 0" xyz="0 0 0"/>
      <geometry>
        <sphere radius="0.018"/>
      </geometry>
      <material name="silver"/>
    </visual>
    <collision>
      <origin rpy="0 0 0" xyz="0 0 0"/>
      <geometry>
        <sphere radius="0.018"/>
      </geometry>
    </collision>
  </link>

  <joint name="FL_hip_joint" type="revolute">
    <origin rpy="0 0 0" xyz="0.23035 0.05 0"/>
    <parent link="trunk"/>
    <child link="FL_hip"/>
    <axis xyz="1 0 0"/>
    <dynamics damping="0" friction="0"/>
    <limit effort="24" lower="-0.76096355387" upper="0.76096355387" velocity="31"/>
  </joint>
  <link name="FL_hip">
    <visual>
      <origin rpy="1.5707963267948966 0 0" xyz="0 0 0"/>
      <geometry>
        <cylinder length="0.052" radius="0.047"/>
      </geometry>
      <material name="silver"/>
    </visual>
    <collision>
      <origin rpy="1.5707963267948966 0 0" xyz="0 0 0"/>
      <geometry>
        <cylinder length="0.052" radius="0.047"/>
      </geometry>
    </collision>
    <inertial>
      <origin rpy="0 0 0" xyz="-0.001597914 0.001680938 2.253e-06"/>
      <mass value="0.537806728"/>
      <inertia ixx="0.000403612" ixy="-9.337e-06" ixz="5.36e-07" iyy="0.000600779" iyz="-6.3e-08" izz="0.000417249"/>
    </inertial>
  </link>
  <joint name="FL_hip_rotor_fix" type="fixed">
    <origin rpy="0 0 0" xyz="-0.0832504 0 0"/>
    <parent link="FL_hip"/>
    <child link="FL_hip_rotor"/>
  </joint>
  <!-- this link is only for abad rotor inertial -->
  <link name="FL_hip_rotor">
    <inertial>
      <origin rpy="0 0 0" xyz="0 0 0"/>
      <mass value="0.076506382"/>
      <inertia ixx="4.5843e-05" ixy="0" ixz="0" iyy="4.5871e-05" iyz="0" izz="8.9031e-05"/>
    </inertial>
  </link>
  <joint name="FL_hip_fixed" type="fixed">
    <origin rpy="0 0 0" xyz="0 0.053076000000000005 0"/>
    <parent link="FL_hip"/>
    <child link="FL_thigh_shoulder"/>
  </joint>
  <link name="FL_thigh_shoulder">
    <visual>
      <origin rpy="1.5707963267948966 0 0" xyz="0 0 0"/>
      <geometry>
        <cylinder length="0.052" radius="0.047"/>
      </geometry>
      <material name="silver"/>
    </visual>
    <collision>
      <origin rpy="1.5707963267948966 0 0" xyz="0 0 0"/>
      <geometry>
        <cylinder length="0.052" radius="0.047"/>
      </geometry>
    </collision>
  </link>
  <joint name="FL_thigh_joint" type="revolute">
    <origin rpy="0 0 0" xyz="0 0.105076 0"/>
    <parent link="FL_hip"/>
    <child link="FL_thigh"/>
    <axis xyz="0 1 0"/>
    <dynamics damping="0" friction="0"/>
    <limit effort="24" lower="-1.88495559215" upper="3.76991118431" velocity="31"/>
  </joint>
  <link name="FL_thigh">
    <visual>
      <origin rpy="0 1.5707963267948966 0" xyz="0 0 -0.1"/>
      <geometry>
        <box size="0.2 0.035 0.05"/>
      </geometry>
      <material name="silver"/>
    </visual>
    <collision>
      <origin rpy="0 1.5707963267948966 0" xyz="0 0 -0.1"/>
      <geometry>
        <box size="0.2 0.035 0.05"/>
      </geometry>
    </collision>
    <inertial>
      <origin rpy="0 0 0" xyz="-0.003205778 -0.027811623 -0.027767048"/>
      <mass value="0.950266218"/>
      <inertia ixx="0.004811898" ixy="9.3647e-05" ixz="-0.000208709" iyy="0.004752366" iyz="0.000813258" izz="0.001079691"/>
    </inertial>
  </link>
  <joint name="FL_thigh_rotor_fix" type="fixed">
    <origin rpy="0 0 0" xyz="0 -0.107226 0"/>
    <parent link="FL_thigh"/>
    <child link="FL_thigh_rotor"/>
  </joint>
  <!-- this link is only for hip rotor inertial -->
  <link name="FL_thigh_rotor">
    <inertial>
      <origin rpy="0 0 0" xyz="0 0 0"/>
      <mass value="0.076506382"/>
      <inertia ixx="4.5843e-05" ixy="0" ixz="0" iyy="4.5871e-05" iyz="0" izz="8.9031e-05"/>
    </inertial>
  </link>
  <joint name="FL_calf_rotor_fix" type="fixed">
    <origin rpy="0 0 0" xyz="0 -0.0426259 0"/>
    <parent link="FL_thigh"/>
    <child link="FL_calf_rotor"/>
  </joint>
  <!-- this link is only for knee rotor inertial -->
  <link name="FL_calf_rotor">
    <inertial>
      <origin rpy="0 0 0" xyz="0 0 0"/>
      <mass value="0.076506382"/>
      <inertia ixx="4.5843e-05" ixy="0" ixz="0" iyy="4.5871e-05" iyz="0" izz="8.9031e-05"/>
    </inertial>
  </link>
  <joint name="FL_calf_joint" type="revolute">
    <origin rpy="0 0 0" xyz="0 0 -0.2"/>
    <parent link="FL_thigh"/>
    <child link="FL_calf"/>
    <axis xyz="0 1 0"/>
    <dynamics damping="0" friction="0"/>
    <limit effort="24" lower="-2.49582083035" upper="-0.717155789644" velocity="31"/>
  </joint>
  <link name="FL_calf">
    <visual>
      <origin rpy="0 3.141592653589793 0" xyz="0 0 -0.1045"/>
      <geometry>
        <box size="0.016 0.016 0.209"/>
      </geometry>
      <material name="silver"/>
    </visual>
    <visual name="FL_calf_rubber">
      <origin rpy="0 3.141592653589793 0" xyz="-0.0125 0 -0.007"/>
      <geometry>
        <sphere radius="0.016"/>
      </geometry>
    </visual>
    <collision>
      <origin rpy="0 3.141592653589793 0" xyz="0 0 -0.1045"/>
      <geometry>
        <box size="0.016 0.016 0.209"/>
      </geometry>
    </collision>
    <collision name="FL_calf_rubber">
      <origin rpy="0 3.141592653589793 0" xyz="-0.0125 0 -0.007"/>
      <geometry>
        <sphere radius="0.016"/>
      </geometry>
    </collision>
    <inertial>
      <origin rpy="0 0 0" xyz="0.007372358 0.000122423 -0.10769301"/>
      <mass value="0.1135916"/>
      <inertia ixx="0.000667971" ixy="-1e-09" ixz="5.356e-06" iyy="0.000674399" iyz="-1.5e-08" izz="1.4181e-05"/>
    </inertial>
  </link>
  <joint name="FL_foot_fixed" type="fixed" dont_collapse="true">
    <origin rpy="0 0 0" xyz="0 0 -0.19999999999999998"/>
    <parent link="FL_calf"/>
    <child link="FL_foot"/>
  </joint>
  <link name="FL_foot">
    <visual>
      <origin rpy="0 0 0" xyz="0 0 0"/>
      <geometry>
        <sphere radius="0.018"/>
      </geometry>
      <material name="silver"/>
    </visual>
    <collision>
      <origin rpy="0 0 0" xyz="0 0 0"/>
      <geometry>
        <sphere radius="0.018"/>
      </geometry>
    </collision>
  </link>

  <joint name="RR_hip_joint" type="revolute">
    <origin rpy="0 0 0" xyz="-0.23035 -0.05 0"/>
    <parent link="trunk"/>
    <child link="RR_hip"/>
    <axis xyz="1 0 0"/>
    <dynamics damping="0" friction="0"/>
    <limit effort="24" lower="-0.76096355387" upper="0.76096355387" velocity="31"/>
  </joint>
  <link name="RR_hip">
    <visual>
      <origin rpy="1.5707963267948966 0 0" xyz="0 0 0"/>
      <geometry>
        <cylinder length="0.052" radius="0.047"/>
      </geometry>
      <material name="silver"/>
    </visual>
    <collision>
      <origin rpy="1.5707963267948966 0 0" xyz="0 0 0"/>
      <geometry>
        <cylinder length="0.052" radius="0.047"/>
      </geometry>
    </collision>
    <inertial>
      <origin rpy="0 0 0" xyz="0.001597914 -0.001680938 2.253e-06"/>
      <mass value="0.537806728"/>
      <inertia ixx="0.000403612" ixy="-9.337e-06" ixz="-5.36e-07" iyy="0.000600779" iyz="6.3e-08" izz="0.000417249"/>
    </inertial>
  </link>
  <joint name="RR_hip_rotor_fix" type="fixed">
    <origin rpy="0 0 0" xyz="0.0832504 0 0"/>
    <parent link="RR_hip"/>
    <child link="RR_hip_rotor"/>
  </joint>
  <!-- this link is only for abad rotor inertial -->
  <link name="RR_hip_rotor">
    <inertial>
      <origin rpy="0 0 0" xyz="0 0 0"/>
      <mass value="0.076506382"/>
      <inertia ixx="4.5843e-05" ixy="0" ixz="0" iyy="4.5871e-05" iyz="0" izz="8.9031e-05"/>
    </inertial>
  </link>
  <joint name="RR_hip_fixed" type="fixed">
    <origin rpy="0 0 0" xyz="0 -0.053076000000000005 0"/>
    <parent link="RR_hip"/>
    <child link="RR_thigh_shoulder"/>
  </joint>
  <link name="RR_thigh_shoulder">
    <visual>
      <origin rpy="1.5707963267948966 0 0" xyz="0 0 0"/>
      <geometry>
        <cylinder length="0.052" radius="0.047"/>
      </geometry>
      <material name="silver"/>
    </visual>
    <collision>
      <origin rpy="1.5707963267948966 0 0" xyz="0 0 0"/>
      <geometry>
        <cylinder length="0.052" radius="0.047"/>
      </geometry>
    </collision>
  </link>
  <joint name="RR_thigh_joint" type="revolute">
    <origin rpy="0 0 0" xyz="0 -0.105076 0"/>
    <parent link="RR_hip"/>
    <child link="RR_thigh"/>
    <axis xyz="0 1 0"/>
    <dynamics damping="0" friction="0"/>
    <limit effort="24" lower="-1.88495559215" upper="3.76991118431" velocity="31"/>
  </joint>
  <link name="RR_thigh">
    <visual>
      <origin rpy="0 1.5707963267948966 0" xyz="0 0 -0.1"/>
      <geometry>
        <box size="0.2 0.035 0.05"/>
      </geometry>
      <material name="silver"/>
    </visual>
    <collision>
      <origin rpy="0 1.5707963267948966 0" xyz="0 0 -0.1"/>
      <geometry>
        <box size="0.2 0.035 0.05"/>
      </geometry>
    </collision>
    <inertial>
      <origin rpy="0 0 0" xyz="-0.003205778 0.027811623 -0.027767048"/>
      <mass value="0.950266218"/>
      <inertia ixx="0.004811898" ixy="-9.3647e-05" ixz="-0.000208709" iyy="0.004752366" iyz="-0.000813258" izz="0.001079691"/>
    </inertial>
  </link>
  <joint name="RR_thigh_rotor_fix" type="fixed">
    <origin rpy="0 0 0" xyz="0 0.107226 0"/>
    <parent link="RR_thigh"/>
    <child link="RR_thigh_rotor"/>
  </joint>
  <!-- this link is only for hip rotor inertial -->
  <link name="RR_thigh_rotor">
    <inertial>
      <origin rpy="0 0 0" xyz="0 0 0"/>
      <mass value="0.076506382"/>
      <inertia ixx="4.5843e-05" ixy="0" ixz="0" iyy="4.5871e-05" iyz="0" izz="8.9031e-05"/>
    </inertial>
  </link>
  <joint name="RR_calf_rotor_fix" type="fixed">
    <origin rpy="0 0 0" xyz="0 0.0426259 0"/>
    <parent link="RR_thigh"/>
    <child link="RR_calf_rotor"/>
  </joint>
  <!-- this link is only for knee rotor inertial -->
  <link name="RR_calf_rotor">
    <inertial>
      <origin rpy="0 0 0" xyz="0 0 0"/>
      <mass value="0.076506382"/>
      <inertia ixx="4.5843e-05" ixy="0" ixz="0" iyy="4.5871e-05" iyz="0" izz="8.9031e-05"/>
    </inertial>
  </link>
  <joint name="RR_calf_joint" type="revolute">
    <origin rpy="0 0 0" xyz="0 0 -0.2"/>
    <parent link="RR_thigh"/>
    <child link="RR_calf"/>
    <axis xyz="0 1 0"/>
    <dynamics damping="0" friction="0"/>
    <limit effort="24" lower="-2.49582083035" upper="-0.717155789644" velocity="31"/>
  </joint>
  <link name="RR_calf">
    <visual>
      <origin rpy="0 3.141592653589793 0" xyz="0 0 -0.1045"/>
      <geometry>
        <box size="0.016 0.016 0.209"/>
      </geometry>
      <material name="silver"/>
    </visual>
    <visual name="RR_calf_rubber">
      <origin rpy="0 3.141592653589793 0" xyz="-0.0125 0 -0.007"/>
      <geometry>
        <sphere radius="0.016"/>
      </geometry>
    </visual>
    <collision>
      <origin rpy="0 3.141592653589793 0" xyz="0 0 -0.1045"/>
      <geometry>
        <box size="0.016 0.016 0.209"/>
      </geometry>
    </collision>
    <collision name="RR_calf_rubber">
      <origin rpy="0 3.141592653589793 0" xyz="-0.0125 0 -0.007"/>
      <geometry>
        <sphere radius="0.016"/>
      </geometry>
    </collision>
    <inertial>
      <origin rpy="0 0 0" xyz="0.007372358 0.000122423 -0.10769301"/>
      <mass value="0.1135916"/>
      <inertia ixx="0.000667971" ixy="-1e-09" ixz="5.356e-06" iyy="0.000674399" iyz="-1.5e-08" izz="1.4181e-05"/>
    </inertial>
  </link>
  <joint name="RR_foot_fixed" type="fixed" dont_collapse="true">
    <origin rpy="0 0 0" xyz="0 0 -0.19999999999999998"/>
    <parent link="RR_calf"/>
    <child link="RR_foot"/>
  </joint>
  <link name="RR_foot">
    <visual>
      <origin rpy="0 0 0" xyz="0 0 0"/>
      <geometry>
        <sphere radius="0.018"/>
      </geometry>
      <material name="silver"/>
    </visual>
    <collision>
      <origin rpy="0 0 0" xyz="0 0 0"/>
      <geometry>
        <sphere radius="0.018"/>
      </geometry>
    </collision>
  </link>
  <!-- <xacro:leg_transmission name="${name}" /> -->
  <joint name="RL_hip_joint" type="revolute">
    <origin rpy="0 0 0" xyz="-0.23035 0.05 0"/>
    <parent link="trunk"/>
    <child link="RL_hip"/>
    <axis xyz="1 0 0"/>
    <dynamics damping="0" friction="0"/>
    <limit effort="24" lower="-0.76096355387" upper="0.76096355387" velocity="31"/>
  </joint>
  <link name="RL_hip">
    <visual>
      <origin rpy="1.5707963267948966 0 0" xyz="0 0 0"/>
      <geometry>
        <cylinder length="0.052" radius="0.047"/>
      </geometry>
      <material name="silver"/>
    </visual>
    <collision>
      <origin rpy="1.5707963267948966 0 0" xyz="0 0 0"/>
      <geometry>
        <cylinder length="0.052" radius="0.047"/>
      </geometry>
    </collision>
    <inertial>
      <origin rpy="0 0 0" xyz="0.001597914 0.001680938 2.253e-06"/>
      <mass value="0.537806728"/>
      <inertia ixx="0.000403612" ixy="9.337e-06" ixz="-5.36e-07" iyy="0.000600779" iyz="-6.3e-08" izz="0.000417249"/>
    </inertial>
  </link>
  <joint name="RL_hip_rotor_fix" type="fixed">
    <origin rpy="0 0 0" xyz="0.0832504 0 0"/>
    <parent link="RL_hip"/>
    <child link="RL_hip_rotor"/>
  </joint>
  <!-- this link is only for abad rotor inertial -->
  <link name="RL_hip_rotor">
    <inertial>
      <origin rpy="0 0 0" xyz="0 0 0"/>
      <mass value="0.076506382"/>
      <inertia ixx="4.5843e-05" ixy="0" ixz="0" iyy="4.5871e-05" iyz="0" izz="8.9031e-05"/>
    </inertial>
  </link>
  <joint name="RL_hip_fixed" type="fixed">
    <origin rpy="0 0 0" xyz="0 0.053076000000000005 0"/>
    <parent link="RL_hip"/>
    <child link="RL_thigh_shoulder"/>
  </joint>
  <link name="RL_thigh_shoulder">
    <visual>
      <origin rpy="1.5707963267948966 0 0" xyz="0 0 0"/>
      <geometry>
        <cylinder length="0.052" radius="0.047"/>
      </geometry>
      <material name="silver"/>
    </visual>
    <collision>
      <origin rpy="1.5707963267948966 0 0" xyz="0 0 0"/>
      <geometry>
        <cylinder length="0.052" radius="0.047"/>
      </geometry>
    </collision>
  </link>
  <joint name="RL_thigh_joint" type="revolute">
    <origin rpy="0 0 0" xyz="0 0.105076 0"/>
    <parent link="RL_hip"/>
    <child link="RL_thigh"/>
    <axis xyz="0 1 0"/>
    <dynamics damping="0" friction="0"/>
    <limit effort="24" lower="-1.88495559215" upper="3.76991118431" velocity="31"/>
  </joint>
  <link name="RL_thigh">
    <visual>
      <origin rpy="0 1.5707963267948966 0" xyz="0 0 -0.1"/>
      <geometry>
        <box size="0.2 0.035 0.05"/>
      </geometry>
      <material name="silver"/>
    </visual>
    <collision>
      <origin rpy="0 1.5707963267948966 0" xyz="0 0 -0.1"/>
      <geometry>
        <box size="0.2 0.035 0.05"/>
      </geometry>
    </collision>
    <inertial>
      <origin rpy="0 0 0" xyz="-0.003205778 -0.027811623 -0.027767048"/>
      <mass value="0.950266218"/>
      <inertia ixx="0.004811898" ixy="9.3647e-05" ixz="-0.000208709" iyy="0.004752366" iyz="0.000813258" izz="0.001079691"/>
    </inertial>
  </link>
  <joint name="RL_thigh_rotor_fix" type="fixed">
    <origin rpy="0 0 0" xyz="0 -0.107226 0"/>
    <parent link="RL_thigh"/>
    <child link="RL_thigh_rotor"/>
  </joint>
  <!-- this link is only for hip rotor inertial -->
  <link name="RL_thigh_rotor">
    <inertial>
      <origin rpy="0 0 0" xyz="0 0 0"/>
      <mass value="0.076506382"/>
      <inertia ixx="4.5843e-05" ixy="0" ixz="0" iyy="4.5871e-05" iyz="0" izz="8.9031e-05"/>
    </inertial>
  </link>
  <joint name="RL_calf_rotor_fix" type="fixed">
    <origin rpy="0 0 0" xyz="0 -0.0426259 0"/>
    <parent link="RL_thigh"/>
    <child link="RL_calf_rotor"/>
  </joint>
  <!-- this link is only for knee rotor inertial -->
  <link name="RL_calf_rotor">
    <inertial>
      <origin rpy="0 0 0" xyz="0 0 0"/>
      <mass value="0.076506382"/>
      <inertia ixx="4.5843e-05" ixy="0" ixz="0" iyy="4.5871e-05" iyz="0" izz="8.9031e-05"/>
    </inertial>
  </link>
  <joint name="RL_calf_joint" type="revolute">
    <origin rpy="0 0 0" xyz="0 0 -0.2"/>
    <parent link="RL_thigh"/>
    <child link="RL_calf"/>
    <axis xyz="0 1 0"/>
    <dynamics damping="0" friction="0"/>
    <limit effort="24" lower="-2.49582083035" upper="-0.717155789644" velocity="31"/>
  </joint>
  <link name="RL_calf">
    <visual>
      <origin rpy="0 3.141592653589793 0" xyz="0 0 -0.1045"/>
      <geometry>
        <box size="0.016 0.016 0.209"/>
      </geometry>
      <material name="silver"/>
    </visual>
    <visual name="RL_calf_rubber">
      <origin rpy="0 3.141592653589793 0" xyz="-0.0125 0 -0.007"/>
      <geometry>
        <sphere radius="0.016"/>
      </geometry>
    </visual>
    <collision>
      <origin rpy="0 3.141592653589793 0" xyz="0 0 -0.1045"/>
      <geometry>
        <box size="0.016 0.016 0.209"/>
      </geometry>
    </collision>
    <collision name="RL_calf_rubber">
      <origin rpy="0 3.141592653589793 0" xyz="-0.0125 0 -0.007"/>
      <geometry>
        <sphere radius="0.016"/>
      </geometry>
    </collision>
    <inertial>
      <origin rpy="0 0 0" xyz="0.007372358 0.000122423 -0.10769301"/>
      <mass value="0.1135916"/>
      <inertia ixx="0.000667971" ixy="-1e-09" ixz="5.356e-06" iyy="0.000674399" iyz="-1.5e-08" izz="1.4181e-05"/>
    </inertial>
  </link>
  <joint name="RL_foot_fixed" type="fixed" dont_collapse="true">
    <origin rpy="0 0 0" xyz="0 0 -0.19999999999999998"/>
    <parent link="RL_calf"/>
    <child link="RL_foot"/>
  </joint>
  <link name="RL_foot">
    <visual>
      <origin rpy="0 0 0" xyz="0 0 0"/>
      <geometry>
        <sphere radius="0.018"/>
      </geometry>
      <material name="silver"/>
    </visual>
    <collision>
      <origin rpy="0 0 0" xyz="0 0 0"/>
      <geometry>
        <sphere radius="0.018"/>
      </geometry>
    </collision>
  </link>
</robot>
